Workbook

Sheet 총괄(10월)
A1: 아이엔건설환경 | E1: 새암건설㈜ | F1: 건우건설㈜
A2: 청리면 덕산지구~~~ | E2: 영동 산과고~~~ | F2: 금성면~~~ | AY2: 특수형태근로자
A3: =H5 -> 45931 | D3: 일용노무비 지급명세서 | H3: 공 제 요 율 | J3: 국민연금 | M3: 건강보험 | P3: 장기요양 | S3: 갑근세 | V3: 주민세 | X3: 갑근세기준 | Z3: 고용보험율 | AB3: ※4대보험적용대상 월8일 이상근무자 | AF3: 출력인원 증가시 : 1번행과15번행 제외하고 그사이에 행을 복사하여 삽입하면 산식은 자동으로 인식됨. | AI3: 통장갖고있어서 자유롭게 신고가능자 | AY3: 고용보험요율
J4: 0.045 | M4: 0.03545 | P4: 건* | Q4: =12.95%/2 -> 0.06475 | S4: 0.027 | V4: 갑*10% | X4: 150000 | Z4: 0.009 | AI4: 임종관, 민헌기, 박범해, 신용철, 전덕하, 최순자, 최순옥, 양희옥, 김양수, 장영석 | AY4: 0.7%→0.8%
A5: 회사명 | C5: 총괄 | F5: 기간 | H5: 45931 | O5: =H6 -> 45961 | Q5: 일간 | S5: 공사명
H6: 45961 | S6: 공종명
A7: 연번 | B7: 직 종 | C7: 성 명 | D7: 주민등록 번 호 | E7: 주 소 | F7: 출력현황 | V7: 출력 공수 | W7: 노무비 | X7: 근로소득세액공제 | AA7: 공제합계 | AB7: 차 감 지급액 | AC7: 결재정보 | AE7: 출력일수
F8: 1 | G8: 2 | H8: 3 | I8: 4 | J8: 5 | K8: 6 | L8: 7 | M8: 8 | N8: 9 | O8: 10 | P8: 11 | Q8: 12 | R8: 13 | S8: 14 | T8: 15 | W8: 단 가 | X8: 고용보험 | Y8: 건강보험 | Z8: 국민연금 | AC8: 은행 | AD8: 예금주 | AI8: 1 | AJ8: 2 | AK8: 3 | AL8: 4 | AM8: 5 | AN8: 6 | AO8: 7 | AP8: 8 | AQ8: 9 | AR8: 10 | AS8: 11 | AT8: 12 | AU8: 13 | AV8: 14 | AW8: 15 | AY8: 우편번호
E9: 전화번호 | F9: 16 | G9: 17 | H9: 18 | I9: 19 | J9: 20 | K9: 21 | L9: 22 | M9: 23 | N9: 24 | O9: 25 | P9: 26 | Q9: 27 | R9: 28 | S9: 29 | T9: 30 | U9: 31 | W9: 총 액 | X9: 갑근세 | Y9: 주민세 | Z9: 장기요양 | AC9: 계좌번호 | AF9: 생년월일 | AG9: 만나이 | AI9: 16 | AJ9: 17 | AK9: 18 | AL9: 19 | AM9: 20 | AN9: 21 | AO9: 22 | AP9: 23 | AQ9: 24 | AR9: 25 | AS9: 26 | AT9: 27 | AU9: 28 | AV9: 29 | AW9: 30 | AX9: 31
A10: 1 | B10: =IF(ISERROR(VLOOKUP(C10,일용직명단!$A$3:$I$104,2,FALSE())),0,VLOOKUP(C10,일용직명단!$A$3:$I$104,2,FALSE())) -> 0 | C10: 임종관 | D10: =IF(ISERROR(VLOOKUP(C10,일용직명단!$A$3:$K$1246,3,FALSE())),0,VLOOKUP(C10,일용직명단!$A$3:$K$1246,3,FALSE())) -> 660123-1386716 | E10: =IF(ISERROR(VLOOKUP(C10,일용직명단!$A$3:$K$1246,4,FALSE())),0,VLOOKUP(C10,일용직명단!$A$3:$K$1246,4,FALSE())) -> 충북 영동군 양강면 국촌1길10 | O10: 1 | P10: 1 | R10: 1 | S10: 1 | T10: 1 | V10: =SUM(F10:U11) -> 7 | W10: =IF(ISERROR(VLOOKUP(C10,일용직명단!$A$3:$K$1246,8,FALSE())),0,VLOOKUP(C10,일용직명단!$A$3:$K$1246,8,FALSE())) -> 150000 | X10: =IFERROR(IF(AG10>=65,0,ROUNDDOWN(W11*$Z$4,-1)),0) -> 9450 | Y10: =IF(AE10>=8,ROUNDDOWN(W11*$M$4,-1),0) -> 0 | Z10: =IFERROR(IF(AND(COUNT(F10:U11)>=8,$AG10<60,W11<=5530000),ROUNDDOWN(ROUNDDOWN(W11,-3)*4.5%,-1),IF(AND(COUNT(F10:U11)>=8,AG10<60,W11>5530000),248850,0)),0) -> 0 | AA10: =+X10+Y10+X11+Y11+Z10+Z11 -> 9450 | AB10: =W11-AA10 -> 1040550 | AC10: =IF(ISERROR(VLOOKUP(C10,일용직명단!$A$3:$I$1226,5,FALSE())),0,VLOOKUP(C10,일용직명단!$A$3:$I$1226,5,FALSE())) -> 농협 | AD10: =IF(ISERROR(VLOOKUP(C10,일용직명단!$A$3:$I$1226,6,FALSE())),0,VLOOKUP(C10,일용직명단!$A$3:$I$1226,6,FALSE())) -> 임종관 | AE10: =COUNT(F10:U11) -> 7 | AF10: =IF(OR(MID(D10,8,1)="1",MID(D10,8,1)="2"),19&LEFT(D10,2),20&LEFT(D10,2))&"-"&MID(D10,3,2)&"-"&MID(D10,5,2) -> 1966-01-23 | AG10: =INT((TODAY()-AF10)/365.25) -> 60 | AH10: =ROUNDDOWN(SUM(AI10:AX11),-1) -> 0 | AI10: =IF($W10*F10>150000,($W10*F10-150000)*6%*45%,0) -> 0 | AJ10: =IF($W10*G10>150000,($W10*G10-150000)*6%*45%,0) -> 0 | AK10: =IF($W10*H10>150000,($W10*H10-150000)*6%*45%,0) -> 0 | AL10: =IF($W10*I10>150000,($W10*I10-150000)*6%*45%,0) -> 0 | AM10: =IF($W10*J10>150000,($W10*J10-150000)*6%*45%,0) -> 0 | AN10: =IF($W10*K10>150000,($W10*K10-150000)*6%*45%,0) -> 0 | AO10: =IF($W10*L10>150000,($W10*L10-150000)*6%*45%,0) -> 0 | AP10: =IF($W10*M10>150000,($W10*M10-150000)*6%*45%,0) -> 0 | ... AW10: =IF($W10*T10>150000,($W10*T10-150000)*6%*45%,0) -> 0 | AY10: =IF(ISERROR(VLOOKUP(C10,[26]일용직명단!$A$3:$M$1151,11,FALSE())),0,VLOOKUP(C10,[26]일용직명단!$A$3:$M$1151,11,FALSE())) -> 29155
E11: =IF(ISERROR(VLOOKUP(C10,일용직명단!$A$3:$K$1246,9,FALSE())),0,VLOOKUP(C10,일용직명단!$A$3:$K$1246,9,FALSE())) -> 010-3039-3737 | F11: 1 | G11: 1 | W11: =W10*V10 -> 1050000 | X11: =IF(AH10<1000,0,AH10) -> 0 | Y11: =ROUNDDOWN(X11*10%,-1) -> 0 | Z11: =IF(AE10>=8,ROUNDDOWN(Y10*$Q$4,-1),0) -> 0 | AC11: =IF(ISERROR(VLOOKUP(C10,일용직명단!$A$3:$I$1226,7,FALSE())),0,VLOOKUP(C10,일용직명단!$A$3:$I$1226,7,FALSE())) -> 352-1734-5415-23 | AI11: =IF($W10*F11>150000,($W10*F11-150000)*6%*45%,0) -> 0 | AJ11: =IF($W10*G11>150000,($W10*G11-150000)*6%*45%,0) -> 0 | AK11: =IF($W10*H11>150000,($W10*H11-150000)*6%*45%,0) -> 0 | AL11: =IF($W10*I11>150000,($W10*I11-150000)*6%*45%,0) -> 0 | AM11: =IF($W10*J11>150000,($W10*J11-150000)*6%*45%,0) -> 0 | AN11: =IF($W10*K11>150000,($W10*K11-150000)*6%*45%,0) -> 0 | AO11: =IF($W10*L11>150000,($W10*L11-150000)*6%*45%,0) -> 0 | AP11: =IF($W10*M11>150000,($W10*M11-150000)*6%*45%,0) -> 0 | ... AX11: =IF($W10*U11>150000,($W10*U11-150000)*6%*45%,0) -> 0
A12: =A10+1 -> 2 | B12: =IF(ISERROR(VLOOKUP(C12,일용직명단!$A$3:$I$104,2,FALSE())),0,VLOOKUP(C12,일용직명단!$A$3:$I$104,2,FALSE())) -> 0 | C12: 민헌기 | D12: =IF(ISERROR(VLOOKUP(C12,일용직명단!$A$3:$K$1246,3,FALSE())),0,VLOOKUP(C12,일용직명단!$A$3:$K$1246,3,FALSE())) -> 601219-1386711 | E12: =IF(ISERROR(VLOOKUP(C12,일용직명단!$A$3:$K$1246,4,FALSE())),0,VLOOKUP(C12,일용직명단!$A$3:$K$1246,4,FALSE())) -> 충북 영동군 양강면 내만길 173 (만계리 156-4) | O12: 1 | P12: 1 | R12: 1 | S12: 1 | T12: 1 | V12: =SUM(F12:U13) -> 7 | W12: =IF(ISERROR(VLOOKUP(C12,일용직명단!$A$3:$K$1246,8,FALSE())),0,VLOOKUP(C12,일용직명단!$A$3:$K$1246,8,FALSE())) -> 150000 | X12: =IFERROR(IF(AG12>=65,0,ROUNDDOWN(W13*$Z$4,-1)),0) -> 0 | Y12: =IF(AE12>=8,ROUNDDOWN(W13*$M$4,-1),0) -> 0 | Z12: =IFERROR(IF(AND(COUNT(F12:U13)>=8,$AG12<60,W13<=5530000),ROUNDDOWN(ROUNDDOWN(W13,-3)*4.5%,-1),IF(AND(COUNT(F12:U13)>=8,AG12<60,W13>5530000),248850,0)),0) -> 0 | AA12: =+X12+Y12+X13+Y13+Z12+Z13 -> 0 | AB12: =W13-AA12 -> 1050000 | AC12: =IF(ISERROR(VLOOKUP(C12,일용직명단!$A$3:$I$1226,5,FALSE())),0,VLOOKUP(C12,일용직명단!$A$3:$I$1226,5,FALSE())) -> 농협 | AD12: =IF(ISERROR(VLOOKUP(C12,일용직명단!$A$3:$I$1226,6,FALSE())),0,VLOOKUP(C12,일용직명단!$A$3:$I$1226,6,FALSE())) -> 민헌기 | AE12: =COUNT(F12:U13) -> 7 | AF12: =IF(OR(MID(D12,8,1)="1",MID(D12,8,1)="2"),19&LEFT(D12,2),20&LEFT(D12,2))&"-"&MID(D12,3,2)&"-"&MID(D12,5,2) -> 1960-12-19 | AG12: =INT((TODAY()-AF12)/365.25) -> 65 | AH12: =ROUNDDOWN(SUM(AI12:AX13),-1) -> 0 | AI12: =IF($W12*F12>150000,($W12*F12-150000)*6%*45%,0) -> 0 | AJ12: =IF($W12*G12>150000,($W12*G12-150000)*6%*45%,0) -> 0 | AK12: =IF($W12*H12>150000,($W12*H12-150000)*6%*45%,0) -> 0 | AL12: =IF($W12*I12>150000,($W12*I12-150000)*6%*45%,0) -> 0 | AM12: =IF($W12*J12>150000,($W12*J12-150000)*6%*45%,0) -> 0 | AN12: =IF($W12*K12>150000,($W12*K12-150000)*6%*45%,0) -> 0 | AO12: =IF($W12*L12>150000,($W12*L12-150000)*6%*45%,0) -> 0 | AP12: =IF($W12*M12>150000,($W12*M12-150000)*6%*45%,0) -> 0 | ... AW12: =IF($W12*T12>150000,($W12*T12-150000)*6%*45%,0) -> 0 | AY12: =IF(ISERROR(VLOOKUP(C12,[26]일용직명단!$A$3:$M$1151,11,FALSE())),0,VLOOKUP(C12,[26]일용직명단!$A$3:$M$1151,11,FALSE())) -> 29157
E13: =IF(ISERROR(VLOOKUP(C12,일용직명단!$A$3:$K$1246,9,FALSE())),0,VLOOKUP(C12,일용직명단!$A$3:$K$1246,9,FALSE())) -> 010-5338-5196 | F13: 1 | G13: 1 | W13: =W12*V12 -> 1050000 | X13: =IF(AH12<1000,0,AH12) -> 0 | Y13: =ROUNDDOWN(X13*10%,-1) -> 0 | Z13: =IF(AE12>=8,ROUNDDOWN(Y12*$Q$4,-1),0) -> 0 | AC13: =IF(ISERROR(VLOOKUP(C12,일용직명단!$A$3:$I$1226,7,FALSE())),0,VLOOKUP(C12,일용직명단!$A$3:$I$1226,7,FALSE())) -> 352-0293-9952-13 | AI13: =IF($W12*F13>150000,($W12*F13-150000)*6%*45%,0) -> 0 | AJ13: =IF($W12*G13>150000,($W12*G13-150000)*6%*45%,0) -> 0 | AK13: =IF($W12*H13>150000,($W12*H13-150000)*6%*45%,0) -> 0 | AL13: =IF($W12*I13>150000,($W12*I13-150000)*6%*45%,0) -> 0 | AM13: =IF($W12*J13>150000,($W12*J13-150000)*6%*45%,0) -> 0 | AN13: =IF($W12*K13>150000,($W12*K13-150000)*6%*45%,0) -> 0 | AO13: =IF($W12*L13>150000,($W12*L13-150000)*6%*45%,0) -> 0 | AP13: =IF($W12*M13>150000,($W12*M13-150000)*6%*45%,0) -> 0 | ... AX13: =IF($W12*U13>150000,($W12*U13-150000)*6%*45%,0) -> 0
A14: =A12+1 -> 3 | B14: =IF(ISERROR(VLOOKUP(C14,일용직명단!$A$3:$I$104,2,FALSE())),0,VLOOKUP(C14,일용직명단!$A$3:$I$104,2,FALSE())) -> 0 | C14: 박범해 | D14: =IF(ISERROR(VLOOKUP(C14,일용직명단!$A$3:$K$1246,3,FALSE())),0,VLOOKUP(C14,일용직명단!$A$3:$K$1246,3,FALSE())) -> 660105-1386714 | E14: =IF(ISERROR(VLOOKUP(C14,일용직명단!$A$3:$K$1246,4,FALSE())),0,VLOOKUP(C14,일용직명단!$A$3:$K$1246,4,FALSE())) -> 충북 영동군 양강면 남전2안길 4-17 (남전리 272) | O14: 1 | P14: 1 | R14: 1 | S14: 1 | T14: 1 | V14: =SUM(F14:U15) -> 7 | W14: =IF(ISERROR(VLOOKUP(C14,일용직명단!$A$3:$K$1246,8,FALSE())),0,VLOOKUP(C14,일용직명단!$A$3:$K$1246,8,FALSE())) -> 150000 | X14: =IFERROR(IF(AG14>=65,0,ROUNDDOWN(W15*$Z$4,-1)),0) -> 9450 | Y14: =IF(AE14>=8,ROUNDDOWN(W15*$M$4,-1),0) -> 0 | Z14: =IFERROR(IF(AND(COUNT(F14:U15)>=8,$AG14<60,W15<=5530000),ROUNDDOWN(ROUNDDOWN(W15,-3)*4.5%,-1),IF(AND(COUNT(F14:U15)>=8,AG14<60,W15>5530000),248850,0)),0) -> 0 | AA14: =+X14+Y14+X15+Y15+Z14+Z15 -> 9450 | AB14: =W15-AA14 -> 1040550 | AC14: =IF(ISERROR(VLOOKUP(C14,일용직명단!$A$3:$I$1226,5,FALSE())),0,VLOOKUP(C14,일용직명단!$A$3:$I$1226,5,FALSE())) -> 농협 | AD14: =IF(ISERROR(VLOOKUP(C14,일용직명단!$A$3:$I$1226,6,FALSE())),0,VLOOKUP(C14,일용직명단!$A$3:$I$1226,6,FALSE())) -> 박범해 | AE14: =COUNT(F14:U15) -> 7 | AF14: =IF(OR(MID(D14,8,1)="1",MID(D14,8,1)="2"),19&LEFT(D14,2),20&LEFT(D14,2))&"-"&MID(D14,3,2)&"-"&MID(D14,5,2) -> 1966-01-05 | AG14: =INT((TODAY()-AF14)/365.25) -> 60 | AH14: =ROUNDDOWN(SUM(AI14:AX15),-1) -> 0 | AI14: =IF($W14*F14>150000,($W14*F14-150000)*6%*45%,0) -> 0 | AJ14: =IF($W14*G14>150000,($W14*G14-150000)*6%*45%,0) -> 0 | AK14: =IF($W14*H14>150000,($W14*H14-150000)*6%*45%,0) -> 0 | AL14: =IF($W14*I14>150000,($W14*I14-150000)*6%*45%,0) -> 0 | AM14: =IF($W14*J14>150000,($W14*J14-150000)*6%*45%,0) -> 0 | AN14: =IF($W14*K14>150000,($W14*K14-150000)*6%*45%,0) -> 0 | AO14: =IF($W14*L14>150000,($W14*L14-150000)*6%*45%,0) -> 0 | AP14: =IF($W14*M14>150000,($W14*M14-150000)*6%*45%,0) -> 0 | ... AW14: =IF($W14*T14>150000,($W14*T14-150000)*6%*45%,0) -> 0 | AY14: =IF(ISERROR(VLOOKUP(C14,[26]일용직명단!$A$3:$M$1151,11,FALSE())),0,VLOOKUP(C14,[26]일용직명단!$A$3:$M$1151,11,FALSE())) -> 29155
E15: =IF(ISERROR(VLOOKUP(C14,일용직명단!$A$3:$K$1246,9,FALSE())),0,VLOOKUP(C14,일용직명단!$A$3:$K$1246,9,FALSE())) -> 010-6356-5898 | F15: 1 | G15: 1 | W15: =W14*V14 -> 1050000 | X15: =IF(AH14<1000,0,AH14) -> 0 | Y15: =ROUNDDOWN(X15*10%,-1) -> 0 | Z15: =IF(AE14>=8,ROUNDDOWN(Y14*$Q$4,-1),0) -> 0 | AC15: =IF(ISERROR(VLOOKUP(C14,일용직명단!$A$3:$I$1226,7,FALSE())),0,VLOOKUP(C14,일용직명단!$A$3:$I$1226,7,FALSE())) -> 356-1071-0591-83 | AI15: =IF($W14*F15>150000,($W14*F15-150000)*6%*45%,0) -> 0 | AJ15: =IF($W14*G15>150000,($W14*G15-150000)*6%*45%,0) -> 0 | AK15: =IF($W14*H15>150000,($W14*H15-150000)*6%*45%,0) -> 0 | AL15: =IF($W14*I15>150000,($W14*I15-150000)*6%*45%,0) -> 0 | AM15: =IF($W14*J15>150000,($W14*J15-150000)*6%*45%,0) -> 0 | AN15: =IF($W14*K15>150000,($W14*K15-150000)*6%*45%,0) -> 0 | AO15: =IF($W14*L15>150000,($W14*L15-150000)*6%*45%,0) -> 0 | AP15: =IF($W14*M15>150000,($W14*M15-150000)*6%*45%,0) -> 0 | ... AX15: =IF($W14*U15>150000,($W14*U15-150000)*6%*45%,0) -> 0
A16: =A14+1 -> 4 | B16: =IF(ISERROR(VLOOKUP(C16,일용직명단!$A$3:$I$104,2,FALSE())),0,VLOOKUP(C16,일용직명단!$A$3:$I$104,2,FALSE())) -> 0 | C16: 신용철 | D16: =IF(ISERROR(VLOOKUP(C16,일용직명단!$A$3:$K$1246,3,FALSE())),0,VLOOKUP(C16,일용직명단!$A$3:$K$1246,3,FALSE())) -> 651220-1228344 | E16: =IF(ISERROR(VLOOKUP(C16,일용직명단!$A$3:$K$1246,4,FALSE())),0,VLOOKUP(C16,일용직명단!$A$3:$K$1246,4,FALSE())) -> 충북 영동군 황간면 신흥1길 8 | O16: 1 | P16: 1 | R16: 1 | S16: 1 | T16: 1 | V16: =SUM(F16:U17) -> 7 | W16: =IF(ISERROR(VLOOKUP(C16,일용직명단!$A$3:$K$1246,8,FALSE())),0,VLOOKUP(C16,일용직명단!$A$3:$K$1246,8,FALSE())) -> 150000 | X16: =IFERROR(IF(AG16>=65,0,ROUNDDOWN(W17*$Z$4,-1)),0) -> 9450 | Y16: =IF(AE16>=8,ROUNDDOWN(W17*$M$4,-1),0) -> 0 | Z16: =IFERROR(IF(AND(COUNT(F16:U17)>=8,$AG16<60,W17<=5530000),ROUNDDOWN(ROUNDDOWN(W17,-3)*4.5%,-1),IF(AND(COUNT(F16:U17)>=8,AG16<60,W17>5530000),248850,0)),0) -> 0 | AA16: =+X16+Y16+X17+Y17+Z16+Z17 -> 9450 | AB16: =W17-AA16 -> 1040550 | AC16: =IF(ISERROR(VLOOKUP(C16,일용직명단!$A$3:$I$1226,5,FALSE())),0,VLOOKUP(C16,일용직명단!$A$3:$I$1226,5,FALSE())) -> 농협 | AD16: =IF(ISERROR(VLOOKUP(C16,일용직명단!$A$3:$I$1226,6,FALSE())),0,VLOOKUP(C16,일용직명단!$A$3:$I$1226,6,FALSE())) -> 신용철 | AE16: =COUNT(F16:U17) -> 7 | AF16: =IF(OR(MID(D16,8,1)="1",MID(D16,8,1)="2"),19&LEFT(D16,2),20&LEFT(D16,2))&"-"&MID(D16,3,2)&"-"&MID(D16,5,2) -> 1965-12-20 | AG16: =INT((TODAY()-AF16)/365.25) -> 60 | AH16: =ROUNDDOWN(SUM(AI16:AX17),-1) -> 0 | AI16: =IF($W16*F16>150000,($W16*F16-150000)*6%*45%,0) -> 0 | AJ16: =IF($W16*G16>150000,($W16*G16-150000)*6%*45%,0) -> 0 | AK16: =IF($W16*H16>150000,($W16*H16-150000)*6%*45%,0) -> 0 | AL16: =IF($W16*I16>150000,($W16*I16-150000)*6%*45%,0) -> 0 | AM16: =IF($W16*J16>150000,($W16*J16-150000)*6%*45%,0) -> 0 | AN16: =IF($W16*K16>150000,($W16*K16-150000)*6%*45%,0) -> 0 | AO16: =IF($W16*L16>150000,($W16*L16-150000)*6%*45%,0) -> 0 | AP16: =IF($W16*M16>150000,($W16*M16-150000)*6%*45%,0) -> 0 | ... AW16: =IF($W16*T16>150000,($W16*T16-150000)*6%*45%,0) -> 0 | AY16: =IF(ISERROR(VLOOKUP(C16,[26]일용직명단!$A$3:$M$1151,11,FALSE())),0,VLOOKUP(C16,[26]일용직명단!$A$3:$M$1151,11,FALSE())) -> 29116
E17: =IF(ISERROR(VLOOKUP(C16,일용직명단!$A$3:$K$1246,9,FALSE())),0,VLOOKUP(C16,일용직명단!$A$3:$K$1246,9,FALSE())) -> 010-3900-0965 | F17: 1 | G17: 1 | W17: =W16*V16 -> 1050000 | X17: =IF(AH16<1000,0,AH16) -> 0 | Y17: =ROUNDDOWN(X17*10%,-1) -> 0 | Z17: =IF(AE16>=8,ROUNDDOWN(Y16*$Q$4,-1),0) -> 0 | AC17: =IF(ISERROR(VLOOKUP(C16,일용직명단!$A$3:$I$1226,7,FALSE())),0,VLOOKUP(C16,일용직명단!$A$3:$I$1226,7,FALSE())) -> 356-1329-6202-53 | AI17: =IF($W16*F17>150000,($W16*F17-150000)*6%*45%,0) -> 0 | AJ17: =IF($W16*G17>150000,($W16*G17-150000)*6%*45%,0) -> 0 | AK17: =IF($W16*H17>150000,($W16*H17-150000)*6%*45%,0) -> 0 | AL17: =IF($W16*I17>150000,($W16*I17-150000)*6%*45%,0) -> 0 | AM17: =IF($W16*J17>150000,($W16*J17-150000)*6%*45%,0) -> 0 | AN17: =IF($W16*K17>150000,($W16*K17-150000)*6%*45%,0) -> 0 | AO17: =IF($W16*L17>150000,($W16*L17-150000)*6%*45%,0) -> 0 | AP17: =IF($W16*M17>150000,($W16*M17-150000)*6%*45%,0) -> 0 | ... AX17: =IF($W16*U17>150000,($W16*U17-150000)*6%*45%,0) -> 0
A18: =A16+1 -> 5 | C18: 전덕하 | D18: =IF(ISERROR(VLOOKUP(C18,일용직명단!$A$3:$K$1246,3,FALSE())),0,VLOOKUP(C18,일용직명단!$A$3:$K$1246,3,FALSE())) -> 491107-1448813 | E18: =IF(ISERROR(VLOOKUP(C18,일용직명단!$A$3:$K$1246,4,FALSE())),0,VLOOKUP(C18,일용직명단!$A$3:$K$1246,4,FALSE())) -> 충북 영동군 양강면 국촌1길 6-6 | O18: 1 | P18: 1 | R18: 1 | S18: 1 | T18: 1 | V18: =SUM(F18:U19) -> 7 | W18: =IF(ISERROR(VLOOKUP(C18,일용직명단!$A$3:$K$1246,8,FALSE())),0,VLOOKUP(C18,일용직명단!$A$3:$K$1246,8,FALSE())) -> 150000 | X18: =IFERROR(IF(AG18>=65,0,ROUNDDOWN(W19*$Z$4,-1)),0) -> 0 | Y18: =IF(AE18>=8,ROUNDDOWN(W19*$M$4,-1),0) -> 0 | Z18: =IFERROR(IF(AND(COUNT(F18:U19)>=8,$AG18<60,W19<=5530000),ROUNDDOWN(ROUNDDOWN(W19,-3)*4.5%,-1),IF(AND(COUNT(F18:U19)>=8,AG18<60,W19>5530000),248850,0)),0) -> 0 | AA18: =+X18+Y18+X19+Y19+Z18+Z19 -> 0 | AB18: =W19-AA18 -> 1050000 | AC18: =IF(ISERROR(VLOOKUP(C18,일용직명단!$A$3:$I$1226,5,FALSE())),0,VLOOKUP(C18,일용직명단!$A$3:$I$1226,5,FALSE())) -> 농협 | AD18: =IF(ISERROR(VLOOKUP(C18,일용직명단!$A$3:$I$1226,6,FALSE())),0,VLOOKUP(C18,일용직명단!$A$3:$I$1226,6,FALSE())) -> 전덕하 | AE18: =COUNT(F18:U19) -> 7 | AF18: =IF(OR(MID(D18,8,1)="1",MID(D18,8,1)="2"),19&LEFT(D18,2),20&LEFT(D18,2))&"-"&MID(D18,3,2)&"-"&MID(D18,5,2) -> 1949-11-07 | AG18: =INT((TODAY()-AF18)/365.25) -> 76 | AH18: =ROUNDDOWN(SUM(AI18:AX19),-1) -> 0 | AI18: =IF($W18*F18>150000,($W18*F18-150000)*6%*45%,0) -> 0 | AJ18: =IF($W18*G18>150000,($W18*G18-150000)*6%*45%,0) -> 0 | AK18: =IF($W18*H18>150000,($W18*H18-150000)*6%*45%,0) -> 0 | AL18: =IF($W18*I18>150000,($W18*I18-150000)*6%*45%,0) -> 0 | AM18: =IF($W18*J18>150000,($W18*J18-150000)*6%*45%,0) -> 0 | AN18: =IF($W18*K18>150000,($W18*K18-150000)*6%*45%,0) -> 0 | AO18: =IF($W18*L18>150000,($W18*L18-150000)*6%*45%,0) -> 0 | AP18: =IF($W18*M18>150000,($W18*M18-150000)*6%*45%,0) -> 0 | ... AW18: =IF($W18*T18>150000,($W18*T18-150000)*6%*45%,0) -> 0 | AY18: =IF(ISERROR(VLOOKUP(C18,[26]일용직명단!$A$3:$M$1151,11,FALSE())),0,VLOOKUP(C18,[26]일용직명단!$A$3:$M$1151,11,FALSE())) -> 29155
E19: =IF(ISERROR(VLOOKUP(C18,일용직명단!$A$3:$K$1246,9,FALSE())),0,VLOOKUP(C18,일용직명단!$A$3:$K$1246,9,FALSE())) -> 0 | F19: 1 | G19: 1 | W19: =W18*V18 -> 1050000 | X19: =IF(AH18<1000,0,AH18) -> 0 | Y19: =ROUNDDOWN(X19*10%,-1) -> 0 | Z19: =IF(AE18>=8,ROUNDDOWN(Y18*$Q$4,-1),0) -> 0 | AC19: =IF(ISERROR(VLOOKUP(C18,일용직명단!$A$3:$I$1226,7,FALSE())),0,VLOOKUP(C18,일용직명단!$A$3:$I$1226,7,FALSE())) -> 356-0791-8136-43 | AI19: =IF($W18*F19>150000,($W18*F19-150000)*6%*45%,0) -> 0 | AJ19: =IF($W18*G19>150000,($W18*G19-150000)*6%*45%,0) -> 0 | AK19: =IF($W18*H19>150000,($W18*H19-150000)*6%*45%,0) -> 0 | AL19: =IF($W18*I19>150000,($W18*I19-150000)*6%*45%,0) -> 0 | AM19: =IF($W18*J19>150000,($W18*J19-150000)*6%*45%,0) -> 0 | AN19: =IF($W18*K19>150000,($W18*K19-150000)*6%*45%,0) -> 0 | AO19: =IF($W18*L19>150000,($W18*L19-150000)*6%*45%,0) -> 0 | AP19: =IF($W18*M19>150000,($W18*M19-150000)*6%*45%,0) -> 0 | ... AX19: =IF($W18*U19>150000,($W18*U19-150000)*6%*45%,0) -> 0
A20: =A18+1 -> 6 | B20: =IF(ISERROR(VLOOKUP(C20,일용직명단!$A$3:$I$104,2,FALSE())),0,VLOOKUP(C20,일용직명단!$A$3:$I$104,2,FALSE())) -> 0 | C20: 최순자 | D20: =IF(ISERROR(VLOOKUP(C20,일용직명단!$A$3:$K$1246,3,FALSE())),0,VLOOKUP(C20,일용직명단!$A$3:$K$1246,3,FALSE())) -> 610604-2382923 | E20: =IF(ISERROR(VLOOKUP(C20,일용직명단!$A$3:$K$1246,4,FALSE())),0,VLOOKUP(C20,일용직명단!$A$3:$K$1246,4,FALSE())) -> 대전광역시 동구 충정로 136, 1102동 2006호 (가양동, 대주파크빌) | O20: 1 | P20: 1 | R20: 1 | S20: 1 | T20: 1 | V20: =SUM(F20:U21) -> 7 | W20: =IF(ISERROR(VLOOKUP(C20,일용직명단!$A$3:$K$1246,8,FALSE())),0,VLOOKUP(C20,일용직명단!$A$3:$K$1246,8,FALSE())) -> 150000 | X20: =IFERROR(IF(AG20>=65,0,ROUNDDOWN(W21*$Z$4,-1)),0) -> 9450 | Y20: =IF(AE20>=8,ROUNDDOWN(W21*$M$4,-1),0) -> 0 | Z20: =IFERROR(IF(AND(COUNT(F20:U21)>=8,$AG20<60,W21<=5530000),ROUNDDOWN(ROUNDDOWN(W21,-3)*4.5%,-1),IF(AND(COUNT(F20:U21)>=8,AG20<60,W21>5530000),248850,0)),0) -> 0 | AA20: =+X20+Y20+X21+Y21+Z20+Z21 -> 9450 | AB20: =W21-AA20 -> 1040550 | AC20: =IF(ISERROR(VLOOKUP(C20,일용직명단!$A$3:$I$1226,5,FALSE())),0,VLOOKUP(C20,일용직명단!$A$3:$I$1226,5,FALSE())) -> 농협 | AD20: =IF(ISERROR(VLOOKUP(C20,일용직명단!$A$3:$I$1226,6,FALSE())),0,VLOOKUP(C20,일용직명단!$A$3:$I$1226,6,FALSE())) -> 최순자 | AE20: =COUNT(F20:U21) -> 7 | AF20: =IF(OR(MID(D20,8,1)="1",MID(D20,8,1)="2"),19&LEFT(D20,2),20&LEFT(D20,2))&"-"&MID(D20,3,2)&"-"&MID(D20,5,2) -> 1961-06-04 | AG20: =INT((TODAY()-AF20)/365.25) -> 64 | AH20: =ROUNDDOWN(SUM(AI20:AX21),-1) -> 0 | AI20: =IF($W20*F20>150000,($W20*F20-150000)*6%*45%,0) -> 0 | AJ20: =IF($W20*G20>150000,($W20*G20-150000)*6%*45%,0) -> 0 | AK20: =IF($W20*H20>150000,($W20*H20-150000)*6%*45%,0) -> 0 | AL20: =IF($W20*I20>150000,($W20*I20-150000)*6%*45%,0) -> 0 | AM20: =IF($W20*J20>150000,($W20*J20-150000)*6%*45%,0) -> 0 | AN20: =IF($W20*K20>150000,($W20*K20-150000)*6%*45%,0) -> 0 | AO20: =IF($W20*L20>150000,($W20*L20-150000)*6%*45%,0) -> 0 | AP20: =IF($W20*M20>150000,($W20*M20-150000)*6%*45%,0) -> 0 | ... AW20: =IF($W20*T20>150000,($W20*T20-150000)*6%*45%,0) -> 0 | AY20: =IF(ISERROR(VLOOKUP(C20,[26]일용직명단!$A$3:$M$1151,11,FALSE())),0,VLOOKUP(C20,[26]일용직명단!$A$3:$M$1151,11,FALSE())) -> 34509
E21: =IF(ISERROR(VLOOKUP(C20,일용직명단!$A$3:$K$1246,9,FALSE())),0,VLOOKUP(C20,일용직명단!$A$3:$K$1246,9,FALSE())) -> 010-5093-9072 | F21: 1 | G21: 1 | W21: =W20*V20 -> 1050000 | X21: =IF(AH20<1000,0,AH20) -> 0 | Y21: =ROUNDDOWN(X21*10%,-1) -> 0 | Z21: =IF(AE20>=8,ROUNDDOWN(Y20*$Q$4,-1),0) -> 0 | AC21: =IF(ISERROR(VLOOKUP(C20,일용직명단!$A$3:$I$1226,7,FALSE())),0,VLOOKUP(C20,일용직명단!$A$3:$I$1226,7,FALSE())) -> 356-1585-3805-03 | AI21: =IF($W20*F21>150000,($W20*F21-150000)*6%*45%,0) -> 0 | AJ21: =IF($W20*G21>150000,($W20*G21-150000)*6%*45%,0) -> 0 | AK21: =IF($W20*H21>150000,($W20*H21-150000)*6%*45%,0) -> 0 | AL21: =IF($W20*I21>150000,($W20*I21-150000)*6%*45%,0) -> 0 | AM21: =IF($W20*J21>150000,($W20*J21-150000)*6%*45%,0) -> 0 | AN21: =IF($W20*K21>150000,($W20*K21-150000)*6%*45%,0) -> 0 | AO21: =IF($W20*L21>150000,($W20*L21-150000)*6%*45%,0) -> 0 | AP21: =IF($W20*M21>150000,($W20*M21-150000)*6%*45%,0) -> 0 | ... AX21: =IF($W20*U21>150000,($W20*U21-150000)*6%*45%,0) -> 0
A22: =A20+1 -> 7 | C22: 최순옥 | D22: =IF(ISERROR(VLOOKUP(C22,일용직명단!$A$3:$K$1246,3,FALSE())),0,VLOOKUP(C22,일용직명단!$A$3:$K$1246,3,FALSE())) -> 661110-2382929 | E22: =IF(ISERROR(VLOOKUP(C22,일용직명단!$A$3:$K$1246,4,FALSE())),0,VLOOKUP(C22,일용직명단!$A$3:$K$1246,4,FALSE())) -> 대전광역시 동구 성동로7번길 58-11, 1동 107호 (자양동, 임광아파트) | O22: 1 | P22: 1 | R22: 1 | S22: 1 | T22: 1 | V22: =SUM(F22:U23) -> 7 | W22: =IF(ISERROR(VLOOKUP(C22,일용직명단!$A$3:$K$1246,8,FALSE())),0,VLOOKUP(C22,일용직명단!$A$3:$K$1246,8,FALSE())) -> 150000 | X22: =IFERROR(IF(AG22>=65,0,ROUNDDOWN(W23*$Z$4,-1)),0) -> 9450 | Y22: =IF(AE22>=8,ROUNDDOWN(W23*$M$4,-1),0) -> 0 | Z22: =IFERROR(IF(AND(COUNT(F22:U23)>=8,$AG22<60,W23<=5530000),ROUNDDOWN(ROUNDDOWN(W23,-3)*4.5%,-1),IF(AND(COUNT(F22:U23)>=8,AG22<60,W23>5530000),248850,0)),0) -> 0 | AA22: =+X22+Y22+X23+Y23+Z22+Z23 -> 9450 | AB22: =W23-AA22 -> 1040550 | AC22: =IF(ISERROR(VLOOKUP(C22,일용직명단!$A$3:$I$1226,5,FALSE())),0,VLOOKUP(C22,일용직명단!$A$3:$I$1226,5,FALSE())) -> 농협 | AD22: =IF(ISERROR(VLOOKUP(C22,일용직명단!$A$3:$I$1226,6,FALSE())),0,VLOOKUP(C22,일용직명단!$A$3:$I$1226,6,FALSE())) -> 최순옥 | AE22: =COUNT(F22:U23) -> 7 | AF22: =IF(OR(MID(D22,8,1)="1",MID(D22,8,1)="2"),19&LEFT(D22,2),20&LEFT(D22,2))&"-"&MID(D22,3,2)&"-"&MID(D22,5,2) -> 1966-11-10 | AG22: =INT((TODAY()-AF22)/365.25) -> 59 | AH22: =ROUNDDOWN(SUM(AI22:AX23),-1) -> 0 | AI22: =IF($W22*F22>150000,($W22*F22-150000)*6%*45%,0) -> 0 | AJ22: =IF($W22*G22>150000,($W22*G22-150000)*6%*45%,0) -> 0 | AK22: =IF($W22*H22>150000,($W22*H22-150000)*6%*45%,0) -> 0 | AL22: =IF($W22*I22>150000,($W22*I22-150000)*6%*45%,0) -> 0 | AM22: =IF($W22*J22>150000,($W22*J22-150000)*6%*45%,0) -> 0 | AN22: =IF($W22*K22>150000,($W22*K22-150000)*6%*45%,0) -> 0 | AO22: =IF($W22*L22>150000,($W22*L22-150000)*6%*45%,0) -> 0 | AP22: =IF($W22*M22>150000,($W22*M22-150000)*6%*45%,0) -> 0 | ... AW22: =IF($W22*T22>150000,($W22*T22-150000)*6%*45%,0) -> 0 | AY22: =IF(ISERROR(VLOOKUP(C22,[27]일용직명단!$A$3:$M$1151,11,FALSE())),0,VLOOKUP(C22,[27]일용직명단!$A$3:$M$1151,11,FALSE())) -> 34513
E23: =IF(ISERROR(VLOOKUP(C22,일용직명단!$A$3:$K$1246,9,FALSE())),0,VLOOKUP(C22,일용직명단!$A$3:$K$1246,9,FALSE())) -> 010-8770-7249 | F23: 1 | G23: 1 | W23: =W22*V22 -> 1050000 | X23: =IF(AH22<1000,0,AH22) -> 0 | Y23: =ROUNDDOWN(X23*10%,-1) -> 0 | Z23: =IF(AE22>=8,ROUNDDOWN(Y22*$Q$4,-1),0) -> 0 | AC23: =IF(ISERROR(VLOOKUP(C22,일용직명단!$A$3:$I$1226,7,FALSE())),0,VLOOKUP(C22,일용직명단!$A$3:$I$1226,7,FALSE())) -> 352-2099-8874-83 | AI23: =IF($W22*F23>150000,($W22*F23-150000)*6%*45%,0) -> 0 | AJ23: =IF($W22*G23>150000,($W22*G23-150000)*6%*45%,0) -> 0 | AK23: =IF($W22*H23>150000,($W22*H23-150000)*6%*45%,0) -> 0 | AL23: =IF($W22*I23>150000,($W22*I23-150000)*6%*45%,0) -> 0 | AM23: =IF($W22*J23>150000,($W22*J23-150000)*6%*45%,0) -> 0 | AN23: =IF($W22*K23>150000,($W22*K23-150000)*6%*45%,0) -> 0 | AO23: =IF($W22*L23>150000,($W22*L23-150000)*6%*45%,0) -> 0 | AP23: =IF($W22*M23>150000,($W22*M23-150000)*6%*45%,0) -> 0 | ... AX23: =IF($W22*U23>150000,($W22*U23-150000)*6%*45%,0) -> 0
A24: =A22+1 -> 8 | B24: =IF(ISERROR(VLOOKUP(C24,일용직명단!$A$3:$I$104,2,FALSE())),0,VLOOKUP(C24,일용직명단!$A$3:$I$104,2,FALSE())) -> 0 | C24: 양희옥 | D24: =IF(ISERROR(VLOOKUP(C24,일용직명단!$A$3:$K$1246,3,FALSE())),0,VLOOKUP(C24,일용직명단!$A$3:$K$1246,3,FALSE())) -> 640320-2386922 | E24: =IF(ISERROR(VLOOKUP(C24,일용직명단!$A$3:$K$1246,4,FALSE())),0,VLOOKUP(C24,일용직명단!$A$3:$K$1246,4,FALSE())) -> 충북 영동군 양강면 양정리116-6 | O24: 1 | P24: 1 | R24: 1 | S24: 1 | T24: 1 | V24: =SUM(F24:U25) -> 7 | W24: =IF(ISERROR(VLOOKUP(C24,일용직명단!$A$3:$K$1246,8,FALSE())),0,VLOOKUP(C24,일용직명단!$A$3:$K$1246,8,FALSE())) -> 150000 | X24: =IFERROR(IF(AG24>=65,0,ROUNDDOWN(W25*$Z$4,-1)),0) -> 9450 | Y24: =IF(AE24>=8,ROUNDDOWN(W25*$M$4,-1),0) -> 0 | Z24: =IFERROR(IF(AND(COUNT(F24:U25)>=8,$AG24<60,W25<=5530000),ROUNDDOWN(ROUNDDOWN(W25,-3)*4.5%,-1),IF(AND(COUNT(F24:U25)>=8,AG24<60,W25>5530000),248850,0)),0) -> 0 | AA24: =+X24+Y24+X25+Y25+Z24+Z25 -> 9450 | AB24: =W25-AA24 -> 1040550 | AC24: =IF(ISERROR(VLOOKUP(C24,일용직명단!$A$3:$I$1226,5,FALSE())),0,VLOOKUP(C24,일용직명단!$A$3:$I$1226,5,FALSE())) -> 농협 | AD24: =IF(ISERROR(VLOOKUP(C24,일용직명단!$A$3:$I$1226,6,FALSE())),0,VLOOKUP(C24,일용직명단!$A$3:$I$1226,6,FALSE())) -> 양희옥 | AE24: =COUNT(F24:U25) -> 7 | AF24: =IF(OR(MID(D24,8,1)="1",MID(D24,8,1)="2"),19&LEFT(D24,2),20&LEFT(D24,2))&"-"&MID(D24,3,2)&"-"&MID(D24,5,2) -> 1964-03-20 | AG24: =INT((TODAY()-AF24)/365.25) -> 62 | AH24: =ROUNDDOWN(SUM(AI24:AX25),-1) -> 0 | AI24: =IF($W24*F24>150000,($W24*F24-150000)*6%*45%,0) -> 0 | AJ24: =IF($W24*G24>150000,($W24*G24-150000)*6%*45%,0) -> 0 | AK24: =IF($W24*H24>150000,($W24*H24-150000)*6%*45%,0) -> 0 | AL24: =IF($W24*I24>150000,($W24*I24-150000)*6%*45%,0) -> 0 | AM24: =IF($W24*J24>150000,($W24*J24-150000)*6%*45%,0) -> 0 | AN24: =IF($W24*K24>150000,($W24*K24-150000)*6%*45%,0) -> 0 | AO24: =IF($W24*L24>150000,($W24*L24-150000)*6%*45%,0) -> 0 | AP24: =IF($W24*M24>150000,($W24*M24-150000)*6%*45%,0) -> 0 | ... AW24: =IF($W24*T24>150000,($W24*T24-150000)*6%*45%,0) -> 0 | AY24: =IF(ISERROR(VLOOKUP(C24,[26]일용직명단!$A$3:$M$1151,11,FALSE())),0,VLOOKUP(C24,[26]일용직명단!$A$3:$M$1151,11,FALSE())) -> 29156
E25: =IF(ISERROR(VLOOKUP(C24,일용직명단!$A$3:$K$1246,9,FALSE())),0,VLOOKUP(C24,일용직명단!$A$3:$K$1246,9,FALSE())) -> 010-8982-1150 | F25: 1 | G25: 1 | W25: =W24*V24 -> 1050000 | X25: =IF(AH24<1000,0,AH24) -> 0 | Y25: =ROUNDDOWN(X25*10%,-1) -> 0 | Z25: =IF(AE24>=8,ROUNDDOWN(Y24*$Q$4,-1),0) -> 0 | AC25: =IF(ISERROR(VLOOKUP(C24,일용직명단!$A$3:$I$1226,7,FALSE())),0,VLOOKUP(C24,일용직명단!$A$3:$I$1226,7,FALSE())) -> 407023-56-010784 | AI25: =IF($W24*F25>150000,($W24*F25-150000)*6%*45%,0) -> 0 | AJ25: =IF($W24*G25>150000,($W24*G25-150000)*6%*45%,0) -> 0 | AK25: =IF($W24*H25>150000,($W24*H25-150000)*6%*45%,0) -> 0 | AL25: =IF($W24*I25>150000,($W24*I25-150000)*6%*45%,0) -> 0 | AM25: =IF($W24*J25>150000,($W24*J25-150000)*6%*45%,0) -> 0 | AN25: =IF($W24*K25>150000,($W24*K25-150000)*6%*45%,0) -> 0 | AO25: =IF($W24*L25>150000,($W24*L25-150000)*6%*45%,0) -> 0 | AP25: =IF($W24*M25>150000,($W24*M25-150000)*6%*45%,0) -> 0 | ... AX25: =IF($W24*U25>150000,($W24*U25-150000)*6%*45%,0) -> 0
A26: =A24+1 -> 9 | C26: 김양수 | D26: =IF(ISERROR(VLOOKUP(C26,일용직명단!$A$3:$K$1246,3,FALSE())),0,VLOOKUP(C26,일용직명단!$A$3:$K$1246,3,FALSE())) -> 610205-2400329 | E26: =IF(ISERROR(VLOOKUP(C26,일용직명단!$A$3:$K$1246,4,FALSE())),0,VLOOKUP(C26,일용직명단!$A$3:$K$1246,4,FALSE())) -> 충북 영동군 영동읍 회동로 156-20 | O26: 1 | P26: 1 | R26: 1 | S26: 1 | T26: 1 | V26: =SUM(F26:U27) -> 7 | W26: =IF(ISERROR(VLOOKUP(C26,일용직명단!$A$3:$K$1246,8,FALSE())),0,VLOOKUP(C26,일용직명단!$A$3:$K$1246,8,FALSE())) -> 150000 | X26: =IFERROR(IF(AG26>=65,0,ROUNDDOWN(W27*$Z$4,-1)),0) -> 0 | Y26: =IF(AE26>=8,ROUNDDOWN(W27*$M$4,-1),0) -> 0 | Z26: =IFERROR(IF(AND(COUNT(F26:U27)>=8,$AG26<60,W27<=5530000),ROUNDDOWN(ROUNDDOWN(W27,-3)*4.5%,-1),IF(AND(COUNT(F26:U27)>=8,AG26<60,W27>5530000),248850,0)),0) -> 0 | AA26: =+X26+Y26+X27+Y27+Z26+Z27 -> 0 | AB26: =W27-AA26 -> 1050000 | AC26: =IF(ISERROR(VLOOKUP(C26,일용직명단!$A$3:$I$1226,5,FALSE())),0,VLOOKUP(C26,일용직명단!$A$3:$I$1226,5,FALSE())) -> 농협 | AD26: =IF(ISERROR(VLOOKUP(C26,일용직명단!$A$3:$I$1226,6,FALSE())),0,VLOOKUP(C26,일용직명단!$A$3:$I$1226,6,FALSE())) -> 김양수 | AE26: =COUNT(F26:U27) -> 7 | AF26: =IF(OR(MID(D26,8,1)="1",MID(D26,8,1)="2"),19&LEFT(D26,2),20&LEFT(D26,2))&"-"&MID(D26,3,2)&"-"&MID(D26,5,2) -> 1961-02-05 | AG26: =INT((TODAY()-AF26)/365.25) -> 65 | AH26: =ROUNDDOWN(SUM(AI26:AX27),-1) -> 0 | AI26: =IF($W26*F26>150000,($W26*F26-150000)*6%*45%,0) -> 0 | AJ26: =IF($W26*G26>150000,($W26*G26-150000)*6%*45%,0) -> 0 | AK26: =IF($W26*H26>150000,($W26*H26-150000)*6%*45%,0) -> 0 | AL26: =IF($W26*I26>150000,($W26*I26-150000)*6%*45%,0) -> 0 | AM26: =IF($W26*J26>150000,($W26*J26-150000)*6%*45%,0) -> 0 | AN26: =IF($W26*K26>150000,($W26*K26-150000)*6%*45%,0) -> 0 | AO26: =IF($W26*L26>150000,($W26*L26-150000)*6%*45%,0) -> 0 | AP26: =IF($W26*M26>150000,($W26*M26-150000)*6%*45%,0) -> 0 | ... AW26: =IF($W26*T26>150000,($W26*T26-150000)*6%*45%,0) -> 0 | AY26: =IF(ISERROR(VLOOKUP(C26,[26]일용직명단!$A$3:$M$1151,11,FALSE())),0,VLOOKUP(C26,[26]일용직명단!$A$3:$M$1151,11,FALSE())) -> 29141
E27: =IF(ISERROR(VLOOKUP(C26,일용직명단!$A$3:$K$1246,9,FALSE())),0,VLOOKUP(C26,일용직명단!$A$3:$K$1246,9,FALSE())) -> 010-4034-9739 | F27: 1 | G27: 1 | W27: =W26*V26 -> 1050000 | X27: =IF(AH26<1000,0,AH26) -> 0 | Y27: =ROUNDDOWN(X27*10%,-1) -> 0 | Z27: =IF(AE26>=8,ROUNDDOWN(Y26*$Q$4,-1),0) -> 0 | AC27: =IF(ISERROR(VLOOKUP(C26,일용직명단!$A$3:$I$1226,7,FALSE())),0,VLOOKUP(C26,일용직명단!$A$3:$I$1226,7,FALSE())) -> 356-1603-8569-73 | AI27: =IF($W26*F27>150000,($W26*F27-150000)*6%*45%,0) -> 0 | AJ27: =IF($W26*G27>150000,($W26*G27-150000)*6%*45%,0) -> 0 | AK27: =IF($W26*H27>150000,($W26*H27-150000)*6%*45%,0) -> 0 | AL27: =IF($W26*I27>150000,($W26*I27-150000)*6%*45%,0) -> 0 | AM27: =IF($W26*J27>150000,($W26*J27-150000)*6%*45%,0) -> 0 | AN27: =IF($W26*K27>150000,($W26*K27-150000)*6%*45%,0) -> 0 | AO27: =IF($W26*L27>150000,($W26*L27-150000)*6%*45%,0) -> 0 | AP27: =IF($W26*M27>150000,($W26*M27-150000)*6%*45%,0) -> 0 | ... AX27: =IF($W26*U27>150000,($W26*U27-150000)*6%*45%,0) -> 0
A28: =A26+1 -> 10 | C28: 장영석 | D28: =IF(ISERROR(VLOOKUP(C28,일용직명단!$A$3:$K$1246,3,FALSE())),0,VLOOKUP(C28,일용직명단!$A$3:$K$1246,3,FALSE())) -> 611022-1386119 | E28: =IF(ISERROR(VLOOKUP(C28,일용직명단!$A$3:$K$1246,4,FALSE())),0,VLOOKUP(C28,일용직명단!$A$3:$K$1246,4,FALSE())) -> 충북 영동군 영동읍 영동황간로 27, 801호(금강타운) | O28: 1 | P28: 1 | R28: 1 | S28: 1 | T28: 1 | V28: =SUM(F28:U29) -> 7 | W28: =IF(ISERROR(VLOOKUP(C28,일용직명단!$A$3:$K$1246,8,FALSE())),0,VLOOKUP(C28,일용직명단!$A$3:$K$1246,8,FALSE())) -> 150000 | X28: =IFERROR(IF(AG28>=65,0,ROUNDDOWN(W29*$Z$4,-1)),0) -> 9450 | Y28: =IF(AE28>=8,ROUNDDOWN(W29*$M$4,-1),0) -> 0 | Z28: =IFERROR(IF(AND(COUNT(F28:U29)>=8,$AG28<60,W29<=5530000),ROUNDDOWN(ROUNDDOWN(W29,-3)*4.5%,-1),IF(AND(COUNT(F28:U29)>=8,AG28<60,W29>5530000),248850,0)),0) -> 0 | AA28: =+X28+Y28+X29+Y29+Z28+Z29 -> 9450 | AB28: =W29-AA28 -> 1040550 | AC28: =IF(ISERROR(VLOOKUP(C28,일용직명단!$A$3:$I$1226,5,FALSE())),0,VLOOKUP(C28,일용직명단!$A$3:$I$1226,5,FALSE())) -> 농협 | AD28: =IF(ISERROR(VLOOKUP(C28,일용직명단!$A$3:$I$1226,6,FALSE())),0,VLOOKUP(C28,일용직명단!$A$3:$I$1226,6,FALSE())) -> 장영석 | AE28: =COUNT(F28:U29) -> 7 | AF28: =IF(OR(MID(D28,8,1)="1",MID(D28,8,1)="2"),19&LEFT(D28,2),20&LEFT(D28,2))&"-"&MID(D28,3,2)&"-"&MID(D28,5,2) -> 1961-10-22 | AG28: =INT((TODAY()-AF28)/365.25) -> 64 | AH28: =ROUNDDOWN(SUM(AI28:AX29),-1) -> 0 | AI28: =IF($W28*F28>150000,($W28*F28-150000)*6%*45%,0) -> 0 | AJ28: =IF($W28*G28>150000,($W28*G28-150000)*6%*45%,0) -> 0 | AK28: =IF($W28*H28>150000,($W28*H28-150000)*6%*45%,0) -> 0 | AL28: =IF($W28*I28>150000,($W28*I28-150000)*6%*45%,0) -> 0 | AM28: =IF($W28*J28>150000,($W28*J28-150000)*6%*45%,0) -> 0 | AN28: =IF($W28*K28>150000,($W28*K28-150000)*6%*45%,0) -> 0 | AO28: =IF($W28*L28>150000,($W28*L28-150000)*6%*45%,0) -> 0 | AP28: =IF($W28*M28>150000,($W28*M28-150000)*6%*45%,0) -> 0 | ... AW28: =IF($W28*T28>150000,($W28*T28-150000)*6%*45%,0) -> 0 | AY28: =IF(ISERROR(VLOOKUP(C28,[26]일용직명단!$A$3:$M$1151,11,FALSE())),0,VLOOKUP(C28,[26]일용직명단!$A$3:$M$1151,11,FALSE())) -> 0
E29: =IF(ISERROR(VLOOKUP(C28,일용직명단!$A$3:$K$1246,9,FALSE())),0,VLOOKUP(C28,일용직명단!$A$3:$K$1246,9,FALSE())) -> 010-4021-4009 | F29: 1 | G29: 1 | W29: =W28*V28 -> 1050000 | X29: =IF(AH28<1000,0,AH28) -> 0 | Y29: =ROUNDDOWN(X29*10%,-1) -> 0 | Z29: =IF(AE28>=8,ROUNDDOWN(Y28*$Q$4,-1),0) -> 0 | AC29: =IF(ISERROR(VLOOKUP(C28,일용직명단!$A$3:$I$1226,7,FALSE())),0,VLOOKUP(C28,일용직명단!$A$3:$I$1226,7,FALSE())) -> 356-1027-4314-93 | AI29: =IF($W28*F29>150000,($W28*F29-150000)*6%*45%,0) -> 0 | AJ29: =IF($W28*G29>150000,($W28*G29-150000)*6%*45%,0) -> 0 | AK29: =IF($W28*H29>150000,($W28*H29-150000)*6%*45%,0) -> 0 | AL29: =IF($W28*I29>150000,($W28*I29-150000)*6%*45%,0) -> 0 | AM29: =IF($W28*J29>150000,($W28*J29-150000)*6%*45%,0) -> 0 | AN29: =IF($W28*K29>150000,($W28*K29-150000)*6%*45%,0) -> 0 | AO29: =IF($W28*L29>150000,($W28*L29-150000)*6%*45%,0) -> 0 | AP29: =IF($W28*M29>150000,($W28*M29-150000)*6%*45%,0) -> 0 | ... AX29: =IF($W28*U29>150000,($W28*U29-150000)*6%*45%,0) -> 0
A30: =A28+1 -> 11 | B30: =IF(ISERROR(VLOOKUP(C30,일용직명단!$A$3:$I$104,2,FALSE())),0,VLOOKUP(C30,일용직명단!$A$3:$I$104,2,FALSE())) -> 0 | C30: 박봉열 | D30: =IF(ISERROR(VLOOKUP(C30,일용직명단!$A$3:$K$1246,3,FALSE())),0,VLOOKUP(C30,일용직명단!$A$3:$K$1246,3,FALSE())) -> 630605-1182813 | E30: =IF(ISERROR(VLOOKUP(C30,일용직명단!$A$3:$K$1246,4,FALSE())),0,VLOOKUP(C30,일용직명단!$A$3:$K$1246,4,FALSE())) -> 인천광역시 남동구 인주대로 857, 102동 105호(만수동,삼환아파트) | O30: 1 | P30: 1 | R30: 1 | S30: 1 | T30: 1 | V30: =SUM(F30:U31) -> 7 | W30: =IF(ISERROR(VLOOKUP(C30,일용직명단!$A$3:$K$1246,8,FALSE())),0,VLOOKUP(C30,일용직명단!$A$3:$K$1246,8,FALSE())) -> 150000 | X30: =IFERROR(IF(AG30>=65,0,ROUNDDOWN(W31*$Z$4,-1)),0) -> 9450 | Y30: =IF(AE30>=8,ROUNDDOWN(W31*$M$4,-1),0) -> 0 | Z30: =IFERROR(IF(AND(COUNT(F30:U31)>=8,$AG30<60,W31<=5530000),ROUNDDOWN(ROUNDDOWN(W31,-3)*4.5%,-1),IF(AND(COUNT(F30:U31)>=8,AG30<60,W31>5530000),248850,0)),0) -> 0 | AA30: =+X30+Y30+X31+Y31+Z30+Z31 -> 9450 | AB30: =W31-AA30 -> 1040550 | AC30: =IF(ISERROR(VLOOKUP(C30,일용직명단!$A$3:$I$1226,5,FALSE())),0,VLOOKUP(C30,일용직명단!$A$3:$I$1226,5,FALSE())) -> 새마을 | AD30: =IF(ISERROR(VLOOKUP(C30,일용직명단!$A$3:$I$1226,6,FALSE())),0,VLOOKUP(C30,일용직명단!$A$3:$I$1226,6,FALSE())) -> 박봉열 | AE30: =COUNT(F30:U31) -> 7 | AF30: =IF(OR(MID(D30,8,1)="1",MID(D30,8,1)="2"),19&LEFT(D30,2),20&LEFT(D30,2))&"-"&MID(D30,3,2)&"-"&MID(D30,5,2) -> 1963-06-05 | AG30: =INT((TODAY()-AF30)/365.25) -> 62 | AH30: =ROUNDDOWN(SUM(AI30:AX31),-1) -> 0 | AI30: =IF($W30*F30>150000,($W30*F30-150000)*6%*45%,0) -> 0 | AJ30: =IF($W30*G30>150000,($W30*G30-150000)*6%*45%,0) -> 0 | AK30: =IF($W30*H30>150000,($W30*H30-150000)*6%*45%,0) -> 0 | AL30: =IF($W30*I30>150000,($W30*I30-150000)*6%*45%,0) -> 0 | AM30: =IF($W30*J30>150000,($W30*J30-150000)*6%*45%,0) -> 0 | AN30: =IF($W30*K30>150000,($W30*K30-150000)*6%*45%,0) -> 0 | AO30: =IF($W30*L30>150000,($W30*L30-150000)*6%*45%,0) -> 0 | AP30: =IF($W30*M30>150000,($W30*M30-150000)*6%*45%,0) -> 0 | ... AW30: =IF($W30*T30>150000,($W30*T30-150000)*6%*45%,0) -> 0 | AY30: =IF(ISERROR(VLOOKUP(C30,[26]일용직명단!$A$3:$M$1151,11,FALSE())),0,VLOOKUP(C30,[26]일용직명단!$A$3:$M$1151,11,FALSE())) -> 0
E31: =IF(ISERROR(VLOOKUP(C30,일용직명단!$A$3:$K$1246,9,FALSE())),0,VLOOKUP(C30,일용직명단!$A$3:$K$1246,9,FALSE())) -> 0 | F31: 1 | G31: 1 | W31: =W30*V30 -> 1050000 | X31: =IF(AH30<1000,0,AH30) -> 0 | Y31: =ROUNDDOWN(X31*10%,-1) -> 0 | Z31: =IF(AE30>=8,ROUNDDOWN(Y30*$Q$4,-1),0) -> 0 | AC31: =IF(ISERROR(VLOOKUP(C30,일용직명단!$A$3:$I$1226,7,FALSE())),0,VLOOKUP(C30,일용직명단!$A$3:$I$1226,7,FALSE())) -> 2306-09-0087630-4 | AI31: =IF($W30*F31>150000,($W30*F31-150000)*6%*45%,0) -> 0 | AJ31: =IF($W30*G31>150000,($W30*G31-150000)*6%*45%,0) -> 0 | AK31: =IF($W30*H31>150000,($W30*H31-150000)*6%*45%,0) -> 0 | AL31: =IF($W30*I31>150000,($W30*I31-150000)*6%*45%,0) -> 0 | AM31: =IF($W30*J31>150000,($W30*J31-150000)*6%*45%,0) -> 0 | AN31: =IF($W30*K31>150000,($W30*K31-150000)*6%*45%,0) -> 0 | AO31: =IF($W30*L31>150000,($W30*L31-150000)*6%*45%,0) -> 0 | AP31: =IF($W30*M31>150000,($W30*M31-150000)*6%*45%,0) -> 0 | ... AX31: =IF($W30*U31>150000,($W30*U31-150000)*6%*45%,0) -> 0
A32: =A30+1 -> 12 | B32: =IF(ISERROR(VLOOKUP(C32,일용직명단!$A$3:$I$104,2,FALSE())),0,VLOOKUP(C32,일용직명단!$A$3:$I$104,2,FALSE())) -> 0 | C32: 장신진 | D32: =IF(ISERROR(VLOOKUP(C32,일용직명단!$A$3:$K$1246,3,FALSE())),0,VLOOKUP(C32,일용직명단!$A$3:$K$1246,3,FALSE())) -> 620908-1386710 | E32: =IF(ISERROR(VLOOKUP(C32,일용직명단!$A$3:$K$1246,4,FALSE())),0,VLOOKUP(C32,일용직명단!$A$3:$K$1246,4,FALSE())) -> 충북 영동군 영동읍 동정로 39-27, 현대아파트 101동 1501호 | O32: 1 | P32: 1 | R32: 1 | S32: 1 | T32: 1 | V32: =SUM(F32:U33) -> 7 | W32: =IF(ISERROR(VLOOKUP(C32,일용직명단!$A$3:$K$1246,8,FALSE())),0,VLOOKUP(C32,일용직명단!$A$3:$K$1246,8,FALSE())) -> 150000 | X32: =IFERROR(IF(AG32>=65,0,ROUNDDOWN(W33*$Z$4,-1)),0) -> 9450 | Y32: =IF(AE32>=8,ROUNDDOWN(W33*$M$4,-1),0) -> 0 | Z32: =IFERROR(IF(AND(COUNT(F32:U33)>=8,$AG32<60,W33<=5530000),ROUNDDOWN(ROUNDDOWN(W33,-3)*4.5%,-1),IF(AND(COUNT(F32:U33)>=8,AG32<60,W33>5530000),248850,0)),0) -> 0 | AA32: =+X32+Y32+X33+Y33+Z32+Z33 -> 9450 | AB32: =W33-AA32 -> 1040550 | AC32: =IF(ISERROR(VLOOKUP(C32,일용직명단!$A$3:$I$1226,5,FALSE())),0,VLOOKUP(C32,일용직명단!$A$3:$I$1226,5,FALSE())) -> 농협 | AD32: =IF(ISERROR(VLOOKUP(C32,일용직명단!$A$3:$I$1226,6,FALSE())),0,VLOOKUP(C32,일용직명단!$A$3:$I$1226,6,FALSE())) -> 장신진 | AE32: =COUNT(F32:U33) -> 7 | AF32: =IF(OR(MID(D32,8,1)="1",MID(D32,8,1)="2"),19&LEFT(D32,2),20&LEFT(D32,2))&"-"&MID(D32,3,2)&"-"&MID(D32,5,2) -> 1962-09-08 | AG32: =INT((TODAY()-AF32)/365.25) -> 63 | AH32: =ROUNDDOWN(SUM(AI32:AX33),-1) -> 0 | AI32: =IF($W32*F32>150000,($W32*F32-150000)*6%*45%,0) -> 0 | AJ32: =IF($W32*G32>150000,($W32*G32-150000)*6%*45%,0) -> 0 | AK32: =IF($W32*H32>150000,($W32*H32-150000)*6%*45%,0) -> 0 | AL32: =IF($W32*I32>150000,($W32*I32-150000)*6%*45%,0) -> 0 | AM32: =IF($W32*J32>150000,($W32*J32-150000)*6%*45%,0) -> 0 | AN32: =IF($W32*K32>150000,($W32*K32-150000)*6%*45%,0) -> 0 | AO32: =IF($W32*L32>150000,($W32*L32-150000)*6%*45%,0) -> 0 | AP32: =IF($W32*M32>150000,($W32*M32-150000)*6%*45%,0) -> 0 | ... AW32: =IF($W32*T32>150000,($W32*T32-150000)*6%*45%,0) -> 0 | AY32: =IF(ISERROR(VLOOKUP(C32,[26]일용직명단!$A$3:$M$1151,11,FALSE())),0,VLOOKUP(C32,[26]일용직명단!$A$3:$M$1151,11,FALSE())) -> 29140
E33: =IF(ISERROR(VLOOKUP(C32,일용직명단!$A$3:$K$1246,9,FALSE())),0,VLOOKUP(C32,일용직명단!$A$3:$K$1246,9,FALSE())) -> 010-8450-8819 | F33: 1 | G33: 1 | W33: =W32*V32 -> 1050000 | X33: =IF(AH32<1000,0,AH32) -> 0 | Y33: =ROUNDDOWN(X33*10%,-1) -> 0 | Z33: =IF(AE32>=8,ROUNDDOWN(Y32*$Q$4,-1),0) -> 0 | AC33: =IF(ISERROR(VLOOKUP(C32,일용직명단!$A$3:$I$1226,7,FALSE())),0,VLOOKUP(C32,일용직명단!$A$3:$I$1226,7,FALSE())) -> 356-1353-2371-93 | AI33: =IF($W32*F33>150000,($W32*F33-150000)*6%*45%,0) -> 0 | AJ33: =IF($W32*G33>150000,($W32*G33-150000)*6%*45%,0) -> 0 | AK33: =IF($W32*H33>150000,($W32*H33-150000)*6%*45%,0) -> 0 | AL33: =IF($W32*I33>150000,($W32*I33-150000)*6%*45%,0) -> 0 | AM33: =IF($W32*J33>150000,($W32*J33-150000)*6%*45%,0) -> 0 | AN33: =IF($W32*K33>150000,($W32*K33-150000)*6%*45%,0) -> 0 | AO33: =IF($W32*L33>150000,($W32*L33-150000)*6%*45%,0) -> 0 | AP33: =IF($W32*M33>150000,($W32*M33-150000)*6%*45%,0) -> 0 | ... AX33: =IF($W32*U33>150000,($W32*U33-150000)*6%*45%,0) -> 0
A34: =A32+1 -> 13 | B34: =IF(ISERROR(VLOOKUP(C34,일용직명단!$A$3:$I$104,2,FALSE())),0,VLOOKUP(C34,일용직명단!$A$3:$I$104,2,FALSE())) -> 0 | C34: 민백규 | D34: =IF(ISERROR(VLOOKUP(C34,일용직명단!$A$3:$K$1246,3,FALSE())),0,VLOOKUP(C34,일용직명단!$A$3:$K$1246,3,FALSE())) -> 600810-1386721 | E34: =IF(ISERROR(VLOOKUP(C34,일용직명단!$A$3:$K$1246,4,FALSE())),0,VLOOKUP(C34,일용직명단!$A$3:$K$1246,4,FALSE())) -> 충북 영동군 양강면 내만길 178-2 | O34: 1 | P34: 1 | R34: 1 | S34: 1 | T34: 1 | V34: =SUM(F34:U35) -> 7 | W34: =IF(ISERROR(VLOOKUP(C34,일용직명단!$A$3:$K$1246,8,FALSE())),0,VLOOKUP(C34,일용직명단!$A$3:$K$1246,8,FALSE())) -> 150000 | X34: =IFERROR(IF(AG34>=65,0,ROUNDDOWN(W35*$Z$4,-1)),0) -> 0 | Y34: =IF(AE34>=8,ROUNDDOWN(W35*$M$4,-1),0) -> 0 | Z34: =IFERROR(IF(AND(COUNT(F34:U35)>=8,$AG34<60,W35<=5530000),ROUNDDOWN(ROUNDDOWN(W35,-3)*4.5%,-1),IF(AND(COUNT(F34:U35)>=8,AG34<60,W35>5530000),248850,0)),0) -> 0 | AA34: =+X34+Y34+X35+Y35+Z34+Z35 -> 0 | AB34: =W35-AA34 -> 1050000 | AC34: =IF(ISERROR(VLOOKUP(C34,일용직명단!$A$3:$I$1226,5,FALSE())),0,VLOOKUP(C34,일용직명단!$A$3:$I$1226,5,FALSE())) -> 농협 | AD34: =IF(ISERROR(VLOOKUP(C34,일용직명단!$A$3:$I$1226,6,FALSE())),0,VLOOKUP(C34,일용직명단!$A$3:$I$1226,6,FALSE())) -> 민백규 | AE34: =COUNT(F34:U35) -> 7 | AF34: =IF(OR(MID(D34,8,1)="1",MID(D34,8,1)="2"),19&LEFT(D34,2),20&LEFT(D34,2))&"-"&MID(D34,3,2)&"-"&MID(D34,5,2) -> 1960-08-10 | AG34: =INT((TODAY()-AF34)/365.25) -> 65 | AH34: =ROUNDDOWN(SUM(AI34:AX35),-1) -> 0 | AI34: =IF($W34*F34>150000,($W34*F34-150000)*6%*45%,0) -> 0 | AJ34: =IF($W34*G34>150000,($W34*G34-150000)*6%*45%,0) -> 0 | AK34: =IF($W34*H34>150000,($W34*H34-150000)*6%*45%,0) -> 0 | AL34: =IF($W34*I34>150000,($W34*I34-150000)*6%*45%,0) -> 0 | AM34: =IF($W34*J34>150000,($W34*J34-150000)*6%*45%,0) -> 0 | AN34: =IF($W34*K34>150000,($W34*K34-150000)*6%*45%,0) -> 0 | AO34: =IF($W34*L34>150000,($W34*L34-150000)*6%*45%,0) -> 0 | AP34: =IF($W34*M34>150000,($W34*M34-150000)*6%*45%,0) -> 0 | ... AW34: =IF($W34*T34>150000,($W34*T34-150000)*6%*45%,0) -> 0 | AY34: =IF(ISERROR(VLOOKUP(C34,[26]일용직명단!$A$3:$M$1151,11,FALSE())),0,VLOOKUP(C34,[26]일용직명단!$A$3:$M$1151,11,FALSE())) -> 29157
E35: =IF(ISERROR(VLOOKUP(C34,일용직명단!$A$3:$K$1246,9,FALSE())),0,VLOOKUP(C34,일용직명단!$A$3:$K$1246,9,FALSE())) -> 010-7107-2693 | F35: 1 | G35: 1 | W35: =W34*V34 -> 1050000 | X35: =IF(AH34<1000,0,AH34) -> 0 | Y35: =ROUNDDOWN(X35*10%,-1) -> 0 | Z35: =IF(AE34>=8,ROUNDDOWN(Y34*$Q$4,-1),0) -> 0 | AC35: =IF(ISERROR(VLOOKUP(C34,일용직명단!$A$3:$I$1226,7,FALSE())),0,VLOOKUP(C34,일용직명단!$A$3:$I$1226,7,FALSE())) -> 453060-52-207611 | AI35: =IF($W34*F35>150000,($W34*F35-150000)*6%*45%,0) -> 0 | AJ35: =IF($W34*G35>150000,($W34*G35-150000)*6%*45%,0) -> 0 | AK35: =IF($W34*H35>150000,($W34*H35-150000)*6%*45%,0) -> 0 | AL35: =IF($W34*I35>150000,($W34*I35-150000)*6%*45%,0) -> 0 | AM35: =IF($W34*J35>150000,($W34*J35-150000)*6%*45%,0) -> 0 | AN35: =IF($W34*K35>150000,($W34*K35-150000)*6%*45%,0) -> 0 | AO35: =IF($W34*L35>150000,($W34*L35-150000)*6%*45%,0) -> 0 | AP35: =IF($W34*M35>150000,($W34*M35-150000)*6%*45%,0) -> 0 | ... AX35: =IF($W34*U35>150000,($W34*U35-150000)*6%*45%,0) -> 0
A36: =A34+1 -> 14 | C36: 김판수 | D36: =IF(ISERROR(VLOOKUP(C36,일용직명단!$A$3:$K$1246,3,FALSE())),0,VLOOKUP(C36,일용직명단!$A$3:$K$1246,3,FALSE())) -> 720402-1798516 | E36: =IF(ISERROR(VLOOKUP(C36,일용직명단!$A$3:$K$1246,4,FALSE())),0,VLOOKUP(C36,일용직명단!$A$3:$K$1246,4,FALSE())) -> 경북 칠곡군 북삼읍 인강9길 10, 101동 1212호(로얄아파트) | O36: 1 | P36: 1 | R36: 1 | S36: 1 | T36: 1 | V36: =SUM(F36:U37) -> 7 | W36: =IF(ISERROR(VLOOKUP(C36,일용직명단!$A$3:$K$1246,8,FALSE())),0,VLOOKUP(C36,일용직명단!$A$3:$K$1246,8,FALSE())) -> 150000 | X36: =IFERROR(IF(AG36>=65,0,ROUNDDOWN(W37*$Z$4,-1)),0) -> 9450 | Y36: =IF(AE36>=8,ROUNDDOWN(W37*$M$4,-1),0) -> 0 | Z36: =IFERROR(IF(AND(COUNT(F36:U37)>=8,$AG36<60,W37<=5530000),ROUNDDOWN(ROUNDDOWN(W37,-3)*4.5%,-1),IF(AND(COUNT(F36:U37)>=8,AG36<60,W37>5530000),248850,0)),0) -> 0 | AA36: =+X36+Y36+X37+Y37+Z36+Z37 -> 9450 | AB36: =W37-AA36 -> 1040550 | AC36: =IF(ISERROR(VLOOKUP(C36,일용직명단!$A$3:$I$1226,5,FALSE())),0,VLOOKUP(C36,일용직명단!$A$3:$I$1226,5,FALSE())) -> 농협 | AD36: =IF(ISERROR(VLOOKUP(C36,일용직명단!$A$3:$I$1226,6,FALSE())),0,VLOOKUP(C36,일용직명단!$A$3:$I$1226,6,FALSE())) -> 김판수 | AE36: =COUNT(F36:U37) -> 7 | AF36: =IF(OR(MID(D36,8,1)="1",MID(D36,8,1)="2"),19&LEFT(D36,2),20&LEFT(D36,2))&"-"&MID(D36,3,2)&"-"&MID(D36,5,2) -> 1972-04-02 | AG36: =INT((TODAY()-AF36)/365.25) -> 54 | AH36: =ROUNDDOWN(SUM(AI36:AX37),-1) -> 0 | AI36: =IF($W36*F36>150000,($W36*F36-150000)*6%*45%,0) -> 0 | AJ36: =IF($W36*G36>150000,($W36*G36-150000)*6%*45%,0) -> 0 | AK36: =IF($W36*H36>150000,($W36*H36-150000)*6%*45%,0) -> 0 | AL36: =IF($W36*I36>150000,($W36*I36-150000)*6%*45%,0) -> 0 | AM36: =IF($W36*J36>150000,($W36*J36-150000)*6%*45%,0) -> 0 | AN36: =IF($W36*K36>150000,($W36*K36-150000)*6%*45%,0) -> 0 | AO36: =IF($W36*L36>150000,($W36*L36-150000)*6%*45%,0) -> 0 | AP36: =IF($W36*M36>150000,($W36*M36-150000)*6%*45%,0) -> 0 | ... AW36: =IF($W36*T36>150000,($W36*T36-150000)*6%*45%,0) -> 0 | AY36: =IF(ISERROR(VLOOKUP(C36,[26]일용직명단!$A$3:$M$1151,11,FALSE())),0,VLOOKUP(C36,[26]일용직명단!$A$3:$M$1151,11,FALSE())) -> 0
E37: =IF(ISERROR(VLOOKUP(C36,일용직명단!$A$3:$K$1246,9,FALSE())),0,VLOOKUP(C36,일용직명단!$A$3:$K$1246,9,FALSE())) -> 010-7520-7708 | F37: 1 | G37: 1 | W37: =W36*V36 -> 1050000 | X37: =IF(AH36<1000,0,AH36) -> 0 | Y37: =ROUNDDOWN(X37*10%,-1) -> 0 | Z37: =IF(AE36>=8,ROUNDDOWN(Y36*$Q$4,-1),0) -> 0 | AC37: =IF(ISERROR(VLOOKUP(C36,일용직명단!$A$3:$I$1226,7,FALSE())),0,VLOOKUP(C36,일용직명단!$A$3:$I$1226,7,FALSE())) -> 735089-56-010696 | AI37: =IF($W36*F37>150000,($W36*F37-150000)*6%*45%,0) -> 0 | AJ37: =IF($W36*G37>150000,($W36*G37-150000)*6%*45%,0) -> 0 | AK37: =IF($W36*H37>150000,($W36*H37-150000)*6%*45%,0) -> 0 | AL37: =IF($W36*I37>150000,($W36*I37-150000)*6%*45%,0) -> 0 | AM37: =IF($W36*J37>150000,($W36*J37-150000)*6%*45%,0) -> 0 | AN37: =IF($W36*K37>150000,($W36*K37-150000)*6%*45%,0) -> 0 | AO37: =IF($W36*L37>150000,($W36*L37-150000)*6%*45%,0) -> 0 | AP37: =IF($W36*M37>150000,($W36*M37-150000)*6%*45%,0) -> 0 | ... AX37: =IF($W36*U37>150000,($W36*U37-150000)*6%*45%,0) -> 0
A38: =A36+1 -> 15 | B38: =IF(ISERROR(VLOOKUP(C38,일용직명단!$A$3:$I$104,2,FALSE())),0,VLOOKUP(C38,일용직명단!$A$3:$I$104,2,FALSE())) -> 0 | C38: 김환배 | D38: =IF(ISERROR(VLOOKUP(C38,일용직명단!$A$3:$K$1246,3,FALSE())),0,VLOOKUP(C38,일용직명단!$A$3:$K$1246,3,FALSE())) -> 530810-1057646 | E38: =IF(ISERROR(VLOOKUP(C38,일용직명단!$A$3:$K$1246,4,FALSE())),0,VLOOKUP(C38,일용직명단!$A$3:$K$1246,4,FALSE())) -> 충북 영동군 양강면 남전2안길 4-20 | O38: 1 | P38: 1 | R38: 1 | S38: 1 | T38: 1 | V38: =SUM(F38:U39) -> 7 | W38: =IF(ISERROR(VLOOKUP(C38,일용직명단!$A$3:$K$1246,8,FALSE())),0,VLOOKUP(C38,일용직명단!$A$3:$K$1246,8,FALSE())) -> 150000 | X38: =IFERROR(IF(AG38>=65,0,ROUNDDOWN(W39*$Z$4,-1)),0) -> 0 | Y38: =IF(AE38>=8,ROUNDDOWN(W39*$M$4,-1),0) -> 0 | Z38: =IFERROR(IF(AND(COUNT(F38:U39)>=8,$AG38<60,W39<=5530000),ROUNDDOWN(ROUNDDOWN(W39,-3)*4.5%,-1),IF(AND(COUNT(F38:U39)>=8,AG38<60,W39>5530000),248850,0)),0) -> 0 | AA38: =+X38+Y38+X39+Y39+Z38+Z39 -> 0 | AB38: =W39-AA38 -> 1050000 | AC38: =IF(ISERROR(VLOOKUP(C38,일용직명단!$A$3:$I$1226,5,FALSE())),0,VLOOKUP(C38,일용직명단!$A$3:$I$1226,5,FALSE())) -> 농협 | AD38: =IF(ISERROR(VLOOKUP(C38,일용직명단!$A$3:$I$1226,6,FALSE())),0,VLOOKUP(C38,일용직명단!$A$3:$I$1226,6,FALSE())) -> 김환배 | AE38: =COUNT(F38:U39) -> 7 | AF38: =IF(OR(MID(D38,8,1)="1",MID(D38,8,1)="2"),19&LEFT(D38,2),20&LEFT(D38,2))&"-"&MID(D38,3,2)&"-"&MID(D38,5,2) -> 1953-08-10 | AG38: =INT((TODAY()-AF38)/365.25) -> 72 | AH38: =ROUNDDOWN(SUM(AI38:AX39),-1) -> 0 | AI38: =IF($W38*F38>150000,($W38*F38-150000)*6%*45%,0) -> 0 | AJ38: =IF($W38*G38>150000,($W38*G38-150000)*6%*45%,0) -> 0 | AK38: =IF($W38*H38>150000,($W38*H38-150000)*6%*45%,0) -> 0 | AL38: =IF($W38*I38>150000,($W38*I38-150000)*6%*45%,0) -> 0 | AM38: =IF($W38*J38>150000,($W38*J38-150000)*6%*45%,0) -> 0 | AN38: =IF($W38*K38>150000,($W38*K38-150000)*6%*45%,0) -> 0 | AO38: =IF($W38*L38>150000,($W38*L38-150000)*6%*45%,0) -> 0 | AP38: =IF($W38*M38>150000,($W38*M38-150000)*6%*45%,0) -> 0 | ... AW38: =IF($W38*T38>150000,($W38*T38-150000)*6%*45%,0) -> 0 | AY38: =IF(ISERROR(VLOOKUP(C38,[26]일용직명단!$A$3:$M$1151,11,FALSE())),0,VLOOKUP(C38,[26]일용직명단!$A$3:$M$1151,11,FALSE())) -> 29155
E39: =IF(ISERROR(VLOOKUP(C38,일용직명단!$A$3:$K$1246,9,FALSE())),0,VLOOKUP(C38,일용직명단!$A$3:$K$1246,9,FALSE())) -> 010-5326-2934 | F39: 1 | G39: 1 | W39: =W38*V38 -> 1050000 | X39: =IF(AH38<1000,0,AH38) -> 0 | Y39: =ROUNDDOWN(X39*10%,-1) -> 0 | Z39: =IF(AE38>=8,ROUNDDOWN(Y38*$Q$4,-1),0) -> 0 | AC39: =IF(ISERROR(VLOOKUP(C38,일용직명단!$A$3:$I$1226,7,FALSE())),0,VLOOKUP(C38,일용직명단!$A$3:$I$1226,7,FALSE())) -> 352-0532-0302-03 | AI39: =IF($W38*F39>150000,($W38*F39-150000)*6%*45%,0) -> 0 | AJ39: =IF($W38*G39>150000,($W38*G39-150000)*6%*45%,0) -> 0 | AK39: =IF($W38*H39>150000,($W38*H39-150000)*6%*45%,0) -> 0 | AL39: =IF($W38*I39>150000,($W38*I39-150000)*6%*45%,0) -> 0 | AM39: =IF($W38*J39>150000,($W38*J39-150000)*6%*45%,0) -> 0 | AN39: =IF($W38*K39>150000,($W38*K39-150000)*6%*45%,0) -> 0 | AO39: =IF($W38*L39>150000,($W38*L39-150000)*6%*45%,0) -> 0 | AP39: =IF($W38*M39>150000,($W38*M39-150000)*6%*45%,0) -> 0 | ... AX39: =IF($W38*U39>150000,($W38*U39-150000)*6%*45%,0) -> 0
A40: =A38+1 -> 16 | C40: 정상천 | D40: =IF(ISERROR(VLOOKUP(C40,일용직명단!$A$3:$K$1246,3,FALSE())),0,VLOOKUP(C40,일용직명단!$A$3:$K$1246,3,FALSE())) -> 700705-1384813 | E40: =IF(ISERROR(VLOOKUP(C40,일용직명단!$A$3:$K$1246,4,FALSE())),0,VLOOKUP(C40,일용직명단!$A$3:$K$1246,4,FALSE())) -> 충북 청주시 상당구 중고개로248번길 52-1 | V40: =SUM(F40:U41) -> 10 | W40: =IF(ISERROR(VLOOKUP(C40,일용직명단!$A$3:$K$1246,8,FALSE())),0,VLOOKUP(C40,일용직명단!$A$3:$K$1246,8,FALSE())) -> 150000 | X40: =IFERROR(IF(AG40>=65,0,ROUNDDOWN(W41*$Z$4,-1)),0) -> 13500 | Y40: =IF(AE40>=8,ROUNDDOWN(W41*$M$4,-1),0) -> 53170 | Z40: =IFERROR(IF(AND(COUNT(F40:U41)>=8,$AG40<60,W41<=5530000),ROUNDDOWN(ROUNDDOWN(W41,-3)*4.5%,-1),IF(AND(COUNT(F40:U41)>=8,AG40<60,W41>5530000),248850,0)),0) -> 67500 | AA40: =+X40+Y40+X41+Y41+Z40+Z41 -> 137610 | AB40: =W41-AA40 -> 1362390 | AC40: =IF(ISERROR(VLOOKUP(C40,일용직명단!$A$3:$I$1226,5,FALSE())),0,VLOOKUP(C40,일용직명단!$A$3:$I$1226,5,FALSE())) -> 농협 | AD40: =IF(ISERROR(VLOOKUP(C40,일용직명단!$A$3:$I$1226,6,FALSE())),0,VLOOKUP(C40,일용직명단!$A$3:$I$1226,6,FALSE())) -> 정상천 | AE40: =COUNT(F40:U41) -> 10 | AF40: =IF(OR(MID(D40,8,1)="1",MID(D40,8,1)="2"),19&LEFT(D40,2),20&LEFT(D40,2))&"-"&MID(D40,3,2)&"-"&MID(D40,5,2) -> 1970-07-05 | AG40: =INT((TODAY()-AF40)/365.25) -> 55 | AH40: =ROUNDDOWN(SUM(AI40:AX41),-1) -> 0 | AI40: =IF($W40*F40>150000,($W40*F40-150000)*6%*45%,0) -> 0 | AJ40: =IF($W40*G40>150000,($W40*G40-150000)*6%*45%,0) -> 0 | AK40: =IF($W40*H40>150000,($W40*H40-150000)*6%*45%,0) -> 0 | AL40: =IF($W40*I40>150000,($W40*I40-150000)*6%*45%,0) -> 0 | AM40: =IF($W40*J40>150000,($W40*J40-150000)*6%*45%,0) -> 0 | AN40: =IF($W40*K40>150000,($W40*K40-150000)*6%*45%,0) -> 0 | AO40: =IF($W40*L40>150000,($W40*L40-150000)*6%*45%,0) -> 0 | AP40: =IF($W40*M40>150000,($W40*M40-150000)*6%*45%,0) -> 0 | ... AW40: =IF($W40*T40>150000,($W40*T40-150000)*6%*45%,0) -> 0 | AY40: =IF(ISERROR(VLOOKUP(C40,[26]일용직명단!$A$3:$M$1151,11,FALSE())),0,VLOOKUP(C40,[26]일용직명단!$A$3:$M$1151,11,FALSE())) -> 0
...

Sheet 총괄(11월)
A1: 건우건설 | E1: 건우건설㈜ | F1: 새암건설㈜ | K1: 건우건설 | P1: 아이엔 | V1: 아이엔 | Z1: 새암건설 | AC1: 건우
A2: 영동유색깔 | E2: 제천금성면 | F2: 산과고 | K2: 수자원 | P2: 청리면 | V2: 작점리(이종성) | Z2: 제천늘봄 | AC2: 소죽천 | AY2: 특수형태근로자
A3: =H5 -> 45962 | D3: 일용노무비 지급명세서 | H3: 공 제 요 율 | J3: 국민연금 | M3: 건강보험 | P3: 장기요양 | S3: 갑근세 | V3: 주민세 | X3: 갑근세기준 | Z3: 고용보험율 | AB3: ※4대보험적용대상 월8일 이상근무자 | AF3: 출력인원 증가시 : 1번행과15번행 제외하고 그사이에 행을 복사하여 삽입하면 산식은 자동으로 인식됨. | AI3: 통장갖고있어서 자유롭게 신고가능자 | AY3: 고용보험요율
J4: 0.045 | M4: 0.03545 | P4: 건* | Q4: =12.95%/2 -> 0.06475 | S4: 0.027 | V4: 갑*10% | X4: 150000 | Z4: 0.009 | AI4: 임종관, 민헌기, 박범해, 신용철, 전덕하, 최순자, 최순옥, 양희옥, 김양수, 장영석 | AY4: 0.7%→0.8%
A5: 회사명 | C5: 총괄 | F5: 기간 | H5: 45962 | O5: =H6 -> 45991 | Q5: 일간 | S5: 공사명
H6: 45991 | S6: 공종명
A7: 연번 | B7: 직 종 | C7: 성 명 | D7: 주민등록 번 호 | E7: 주 소 | F7: 출력현황 | V7: 출력 공수 | W7: 노무비 | X7: 근로소득세액공제 | AA7: 공제합계 | AB7: 차 감 지급액 | AC7: 결재정보 | AE7: 출력일수
F8: 1 | G8: 2 | H8: 3 | I8: 4 | J8: 5 | K8: 6 | L8: 7 | M8: 8 | N8: 9 | O8: 10 | P8: 11 | Q8: 12 | R8: 13 | S8: 14 | T8: 15 | W8: 단 가 | X8: 고용보험 | Y8: 건강보험 | Z8: 국민연금 | AC8: 은행 | AD8: 예금주 | AI8: 1 | AJ8: 2 | AK8: 3 | AL8: 4 | AM8: 5 | AN8: 6 | AO8: 7 | AP8: 8 | AQ8: 9 | AR8: 10 | AS8: 11 | AT8: 12 | AU8: 13 | AV8: 14 | AW8: 15 | AY8: 우편번호
E9: 전화번호 | F9: 16 | G9: 17 | H9: 18 | I9: 19 | J9: 20 | K9: 21 | L9: 22 | M9: 23 | N9: 24 | O9: 25 | P9: 26 | Q9: 27 | R9: 28 | S9: 29 | T9: 30 | W9: 총 액 | X9: 갑근세 | Y9: 주민세 | Z9: 장기요양 | AC9: 계좌번호 | AF9: 생년월일 | AG9: 만나이 | AI9: 16 | AJ9: 17 | AK9: 18 | AL9: 19 | AM9: 20 | AN9: 21 | AO9: 22 | AP9: 23 | AQ9: 24 | AR9: 25 | AS9: 26 | AT9: 27 | AU9: 28 | AV9: 29 | AW9: 30 | AX9: 31
A10: 1 | B10: =IF(ISERROR(VLOOKUP(C10,일용직명단!$A$3:$I$104,2,FALSE())),0,VLOOKUP(C10,일용직명단!$A$3:$I$104,2,FALSE())) -> 0 | C10: 임종관 | D10: =IF(ISERROR(VLOOKUP(C10,일용직명단!$A$3:$K$1246,3,FALSE())),0,VLOOKUP(C10,일용직명단!$A$3:$K$1246,3,FALSE())) -> 660123-1386716 | E10: =IF(ISERROR(VLOOKUP(C10,일용직명단!$A$3:$K$1246,4,FALSE())),0,VLOOKUP(C10,일용직명단!$A$3:$K$1246,4,FALSE())) -> 충북 영동군 양강면 국촌1길10 | H10: 1 | I10: 1 | J10: 1 | K10: 1 | L10: 1 | M10: 1 | O10: 1 | P10: 1 | Q10: 1 | R10: 1 | S10: 1 | T10: 1 | V10: =SUM(F10:U11) -> 12 | W10: =IF(ISERROR(VLOOKUP(C10,일용직명단!$A$3:$K$1246,8,FALSE())),0,VLOOKUP(C10,일용직명단!$A$3:$K$1246,8,FALSE())) -> 150000 | X10: =IFERROR(IF(AG10>=65,0,ROUNDDOWN(W11*$Z$4,-1)),0) -> 16200 | Y10: =IF(AE10>=8,ROUNDDOWN(W11*$M$4,-1),0) -> 63810 | Z10: =IFERROR(IF(AND(COUNT(F10:U11)>=8,$AG10<60,W11<=5530000),ROUNDDOWN(ROUNDDOWN(W11,-3)*4.5%,-1),IF(AND(COUNT(F10:U11)>=8,AG10<60,W11>5530000),248850,0)),0) -> 0 | AA10: =+X10+Y10+X11+Y11+Z10+Z11 -> 84140 | AB10: =W11-AA10 -> 1715860 | AC10: =IF(ISERROR(VLOOKUP(C10,일용직명단!$A$3:$I$1226,5,FALSE())),0,VLOOKUP(C10,일용직명단!$A$3:$I$1226,5,FALSE())) -> 농협 | AD10: =IF(ISERROR(VLOOKUP(C10,일용직명단!$A$3:$I$1226,6,FALSE())),0,VLOOKUP(C10,일용직명단!$A$3:$I$1226,6,FALSE())) -> 임종관 | AE10: =COUNT(F10:U11) -> 12 | AF10: =IF(OR(MID(D10,8,1)="1",MID(D10,8,1)="2"),19&LEFT(D10,2),20&LEFT(D10,2))&"-"&MID(D10,3,2)&"-"&MID(D10,5,2) -> 1966-01-23 | AG10: =INT((TODAY()-AF10)/365.25) -> 60 | AH10: =ROUNDDOWN(SUM(AI10:AX11),-1) -> 0 | AI10: =IF($W10*F10>150000,($W10*F10-150000)*6%*45%,0) -> 0 | AJ10: =IF($W10*G10>150000,($W10*G10-150000)*6%*45%,0) -> 0 | AK10: =IF($W10*H10>150000,($W10*H10-150000)*6%*45%,0) -> 0 | AL10: =IF($W10*I10>150000,($W10*I10-150000)*6%*45%,0) -> 0 | AM10: =IF($W10*J10>150000,($W10*J10-150000)*6%*45%,0) -> 0 | AN10: =IF($W10*K10>150000,($W10*K10-150000)*6%*45%,0) -> 0 | AO10: =IF($W10*L10>150000,($W10*L10-150000)*6%*45%,0) -> 0 | AP10: =IF($W10*M10>150000,($W10*M10-150000)*6%*45%,0) -> 0 | ... AW10: =IF($W10*T10>150000,($W10*T10-150000)*6%*45%,0) -> 0 | AY10: =IF(ISERROR(VLOOKUP(C10,[26]일용직명단!$A$3:$M$1151,11,FALSE())),0,VLOOKUP(C10,[26]일용직명단!$A$3:$M$1151,11,FALSE())) -> 29155
E11: =IF(ISERROR(VLOOKUP(C10,일용직명단!$A$3:$K$1246,9,FALSE())),0,VLOOKUP(C10,일용직명단!$A$3:$K$1246,9,FALSE())) -> 010-3039-3737 | W11: =W10*V10 -> 1800000 | X11: =IF(AH10<1000,0,AH10) -> 0 | Y11: =ROUNDDOWN(X11*10%,-1) -> 0 | Z11: =IF(AE10>=8,ROUNDDOWN(Y10*$Q$4,-1),0) -> 4130 | AC11: =IF(ISERROR(VLOOKUP(C10,일용직명단!$A$3:$I$1226,7,FALSE())),0,VLOOKUP(C10,일용직명단!$A$3:$I$1226,7,FALSE())) -> 352-1734-5415-23 | AI11: =IF($W10*F11>150000,($W10*F11-150000)*6%*45%,0) -> 0 | AJ11: =IF($W10*G11>150000,($W10*G11-150000)*6%*45%,0) -> 0 | AK11: =IF($W10*H11>150000,($W10*H11-150000)*6%*45%,0) -> 0 | AL11: =IF($W10*I11>150000,($W10*I11-150000)*6%*45%,0) -> 0 | AM11: =IF($W10*J11>150000,($W10*J11-150000)*6%*45%,0) -> 0 | AN11: =IF($W10*K11>150000,($W10*K11-150000)*6%*45%,0) -> 0 | AO11: =IF($W10*L11>150000,($W10*L11-150000)*6%*45%,0) -> 0 | AP11: =IF($W10*M11>150000,($W10*M11-150000)*6%*45%,0) -> 0 | ... AX11: =IF($W10*U11>150000,($W10*U11-150000)*6%*45%,0) -> 0
A12: =A10+1 -> 2 | B12: =IF(ISERROR(VLOOKUP(C12,일용직명단!$A$3:$I$104,2,FALSE())),0,VLOOKUP(C12,일용직명단!$A$3:$I$104,2,FALSE())) -> 0 | C12: 장신진 | D12: =IF(ISERROR(VLOOKUP(C12,일용직명단!$A$3:$K$1246,3,FALSE())),0,VLOOKUP(C12,일용직명단!$A$3:$K$1246,3,FALSE())) -> 620908-1386710 | E12: =IF(ISERROR(VLOOKUP(C12,일용직명단!$A$3:$K$1246,4,FALSE())),0,VLOOKUP(C12,일용직명단!$A$3:$K$1246,4,FALSE())) -> 충북 영동군 영동읍 동정로 39-27, 현대아파트 101동 1501호 | H12: 1 | I12: 1 | J12: 1 | K12: 1 | L12: 1 | M12: 1 | O12: 1 | P12: 1 | Q12: 1 | R12: 1 | S12: 1 | T12: 1 | V12: =SUM(F12:U13) -> 12 | W12: =IF(ISERROR(VLOOKUP(C12,일용직명단!$A$3:$K$1246,8,FALSE())),0,VLOOKUP(C12,일용직명단!$A$3:$K$1246,8,FALSE())) -> 150000 | X12: =IFERROR(IF(AG12>=65,0,ROUNDDOWN(W13*$Z$4,-1)),0) -> 16200 | Y12: =IF(AE12>=8,ROUNDDOWN(W13*$M$4,-1),0) -> 63810 | Z12: =IFERROR(IF(AND(COUNT(F12:U13)>=8,$AG12<60,W13<=5530000),ROUNDDOWN(ROUNDDOWN(W13,-3)*4.5%,-1),IF(AND(COUNT(F12:U13)>=8,AG12<60,W13>5530000),248850,0)),0) -> 0 | AA12: =+X12+Y12+X13+Y13+Z12+Z13 -> 84140 | AB12: =W13-AA12 -> 1715860 | AC12: =IF(ISERROR(VLOOKUP(C12,일용직명단!$A$3:$I$1226,5,FALSE())),0,VLOOKUP(C12,일용직명단!$A$3:$I$1226,5,FALSE())) -> 농협 | AD12: =IF(ISERROR(VLOOKUP(C12,일용직명단!$A$3:$I$1226,6,FALSE())),0,VLOOKUP(C12,일용직명단!$A$3:$I$1226,6,FALSE())) -> 장신진 | AE12: =COUNT(F12:U13) -> 12 | AF12: =IF(OR(MID(D12,8,1)="1",MID(D12,8,1)="2"),19&LEFT(D12,2),20&LEFT(D12,2))&"-"&MID(D12,3,2)&"-"&MID(D12,5,2) -> 1962-09-08 | AG12: =INT((TODAY()-AF12)/365.25) -> 63 | AH12: =ROUNDDOWN(SUM(AI12:AX13),-1) -> 0 | AI12: =IF($W12*F12>150000,($W12*F12-150000)*6%*45%,0) -> 0 | AJ12: =IF($W12*G12>150000,($W12*G12-150000)*6%*45%,0) -> 0 | AK12: =IF($W12*H12>150000,($W12*H12-150000)*6%*45%,0) -> 0 | AL12: =IF($W12*I12>150000,($W12*I12-150000)*6%*45%,0) -> 0 | AM12: =IF($W12*J12>150000,($W12*J12-150000)*6%*45%,0) -> 0 | AN12: =IF($W12*K12>150000,($W12*K12-150000)*6%*45%,0) -> 0 | AO12: =IF($W12*L12>150000,($W12*L12-150000)*6%*45%,0) -> 0 | AP12: =IF($W12*M12>150000,($W12*M12-150000)*6%*45%,0) -> 0 | ... AW12: =IF($W12*T12>150000,($W12*T12-150000)*6%*45%,0) -> 0 | AY12: =IF(ISERROR(VLOOKUP(C12,[26]일용직명단!$A$3:$M$1151,11,FALSE())),0,VLOOKUP(C12,[26]일용직명단!$A$3:$M$1151,11,FALSE())) -> 29140
E13: =IF(ISERROR(VLOOKUP(C12,일용직명단!$A$3:$K$1246,9,FALSE())),0,VLOOKUP(C12,일용직명단!$A$3:$K$1246,9,FALSE())) -> 010-8450-8819 | W13: =W12*V12 -> 1800000 | X13: =IF(AH12<1000,0,AH12) -> 0 | Y13: =ROUNDDOWN(X13*10%,-1) -> 0 | Z13: =IF(AE12>=8,ROUNDDOWN(Y12*$Q$4,-1),0) -> 4130 | AC13: =IF(ISERROR(VLOOKUP(C12,일용직명단!$A$3:$I$1226,7,FALSE())),0,VLOOKUP(C12,일용직명단!$A$3:$I$1226,7,FALSE())) -> 356-1353-2371-93 | AI13: =IF($W12*F13>150000,($W12*F13-150000)*6%*45%,0) -> 0 | AJ13: =IF($W12*G13>150000,($W12*G13-150000)*6%*45%,0) -> 0 | AK13: =IF($W12*H13>150000,($W12*H13-150000)*6%*45%,0) -> 0 | AL13: =IF($W12*I13>150000,($W12*I13-150000)*6%*45%,0) -> 0 | AM13: =IF($W12*J13>150000,($W12*J13-150000)*6%*45%,0) -> 0 | AN13: =IF($W12*K13>150000,($W12*K13-150000)*6%*45%,0) -> 0 | AO13: =IF($W12*L13>150000,($W12*L13-150000)*6%*45%,0) -> 0 | AP13: =IF($W12*M13>150000,($W12*M13-150000)*6%*45%,0) -> 0 | ... AX13: =IF($W12*U13>150000,($W12*U13-150000)*6%*45%,0) -> 0
A14: =A12+1 -> 3 | B14: =IF(ISERROR(VLOOKUP(C14,일용직명단!$A$3:$I$104,2,FALSE())),0,VLOOKUP(C14,일용직명단!$A$3:$I$104,2,FALSE())) -> 0 | C14: 박범해 | D14: =IF(ISERROR(VLOOKUP(C14,일용직명단!$A$3:$K$1246,3,FALSE())),0,VLOOKUP(C14,일용직명단!$A$3:$K$1246,3,FALSE())) -> 660105-1386714 | E14: =IF(ISERROR(VLOOKUP(C14,일용직명단!$A$3:$K$1246,4,FALSE())),0,VLOOKUP(C14,일용직명단!$A$3:$K$1246,4,FALSE())) -> 충북 영동군 양강면 남전2안길 4-17 (남전리 272) | H14: 1 | I14: 1 | J14: 1 | K14: 1 | L14: 1 | M14: 1 | O14: 1 | P14: 1 | Q14: 1 | R14: 1 | S14: 1 | T14: 1 | V14: =SUM(F14:U15) -> 12 | W14: =IF(ISERROR(VLOOKUP(C14,일용직명단!$A$3:$K$1246,8,FALSE())),0,VLOOKUP(C14,일용직명단!$A$3:$K$1246,8,FALSE())) -> 150000 | X14: =IFERROR(IF(AG14>=65,0,ROUNDDOWN(W15*$Z$4,-1)),0) -> 16200 | Y14: =IF(AE14>=8,ROUNDDOWN(W15*$M$4,-1),0) -> 63810 | Z14: =IFERROR(IF(AND(COUNT(F14:U15)>=8,$AG14<60,W15<=5530000),ROUNDDOWN(ROUNDDOWN(W15,-3)*4.5%,-1),IF(AND(COUNT(F14:U15)>=8,AG14<60,W15>5530000),248850,0)),0) -> 0 | AA14: =+X14+Y14+X15+Y15+Z14+Z15 -> 84140 | AB14: =W15-AA14 -> 1715860 | AC14: =IF(ISERROR(VLOOKUP(C14,일용직명단!$A$3:$I$1226,5,FALSE())),0,VLOOKUP(C14,일용직명단!$A$3:$I$1226,5,FALSE())) -> 농협 | AD14: =IF(ISERROR(VLOOKUP(C14,일용직명단!$A$3:$I$1226,6,FALSE())),0,VLOOKUP(C14,일용직명단!$A$3:$I$1226,6,FALSE())) -> 박범해 | AE14: =COUNT(F14:U15) -> 12 | AF14: =IF(OR(MID(D14,8,1)="1",MID(D14,8,1)="2"),19&LEFT(D14,2),20&LEFT(D14,2))&"-"&MID(D14,3,2)&"-"&MID(D14,5,2) -> 1966-01-05 | AG14: =INT((TODAY()-AF14)/365.25) -> 60 | AH14: =ROUNDDOWN(SUM(AI14:AX15),-1) -> 0 | AI14: =IF($W14*F14>150000,($W14*F14-150000)*6%*45%,0) -> 0 | AJ14: =IF($W14*G14>150000,($W14*G14-150000)*6%*45%,0) -> 0 | AK14: =IF($W14*H14>150000,($W14*H14-150000)*6%*45%,0) -> 0 | AL14: =IF($W14*I14>150000,($W14*I14-150000)*6%*45%,0) -> 0 | AM14: =IF($W14*J14>150000,($W14*J14-150000)*6%*45%,0) -> 0 | AN14: =IF($W14*K14>150000,($W14*K14-150000)*6%*45%,0) -> 0 | AO14: =IF($W14*L14>150000,($W14*L14-150000)*6%*45%,0) -> 0 | AP14: =IF($W14*M14>150000,($W14*M14-150000)*6%*45%,0) -> 0 | ... AW14: =IF($W14*T14>150000,($W14*T14-150000)*6%*45%,0) -> 0 | AY14: =IF(ISERROR(VLOOKUP(C14,[26]일용직명단!$A$3:$M$1151,11,FALSE())),0,VLOOKUP(C14,[26]일용직명단!$A$3:$M$1151,11,FALSE())) -> 29155
E15: =IF(ISERROR(VLOOKUP(C14,일용직명단!$A$3:$K$1246,9,FALSE())),0,VLOOKUP(C14,일용직명단!$A$3:$K$1246,9,FALSE())) -> 010-6356-5898 | W15: =W14*V14 -> 1800000 | X15: =IF(AH14<1000,0,AH14) -> 0 | Y15: =ROUNDDOWN(X15*10%,-1) -> 0 | Z15: =IF(AE14>=8,ROUNDDOWN(Y14*$Q$4,-1),0) -> 4130 | AC15: =IF(ISERROR(VLOOKUP(C14,일용직명단!$A$3:$I$1226,7,FALSE())),0,VLOOKUP(C14,일용직명단!$A$3:$I$1226,7,FALSE())) -> 356-1071-0591-83 | AI15: =IF($W14*F15>150000,($W14*F15-150000)*6%*45%,0) -> 0 | AJ15: =IF($W14*G15>150000,($W14*G15-150000)*6%*45%,0) -> 0 | AK15: =IF($W14*H15>150000,($W14*H15-150000)*6%*45%,0) -> 0 | AL15: =IF($W14*I15>150000,($W14*I15-150000)*6%*45%,0) -> 0 | AM15: =IF($W14*J15>150000,($W14*J15-150000)*6%*45%,0) -> 0 | AN15: =IF($W14*K15>150000,($W14*K15-150000)*6%*45%,0) -> 0 | AO15: =IF($W14*L15>150000,($W14*L15-150000)*6%*45%,0) -> 0 | AP15: =IF($W14*M15>150000,($W14*M15-150000)*6%*45%,0) -> 0 | ... AX15: =IF($W14*U15>150000,($W14*U15-150000)*6%*45%,0) -> 0
