Workbook
Name 간이세액표: [1]간이세액표!$A$4:$M$650
Name 건강보험율: '[1]4대보험요율표'!$E$16
Name 고용보험율: '[1]4대보험요율표'!$D$26
Name 국민연금: '[1]4대보험요율표'!$D$6
Name 요양보험율: '[1]4대보험요율표'!$D$17
Name 월액최고: '[1]4대보험요율표'!$H$5
Name 월액최저: '[1]4대보험요율표'!$I$5
Name 최고연금: '[1]4대보험요율표'!$H$6
Name 최저연금: '[1]4대보험요율표'!$I$6

Sheet 직원명부
A1: 번호 | B1: 성명 | C1: 직책 | D1: 주민등록번호 | E1: 주소 충청북도 영동군 영동읍 영동황간로 30-1 | F1: 연락번호 | G1: e-mail 주소 | H1: 예금주 | I1: 은행명 | J1: 계 좌 번 호 | K1: 입사일 | L1: 퇴사일 | M1: 급여액
A2: 1 | B2: 안경이 | C2: 대표 | D2: 650228- 2226831 | E2: 충청북도 영동군 양강면 국촌1길 6-6 | F2: 010-4436-0963 | K2: 40683 | M2: 2100000
A3: =A2+1 -> 2 | B3: 김성헌 | C3: 부장 | D3: 650616-1386114 | E3: 충청북도 영동군 영동읍 영산로7길 2, 가동 303호(양지연립) | F3: 010-9428-5663 | K3: 44964 | M3: 2100000
A4: =A3+1 -> 3 | B4: 최종식 | C4: 부장 | D4: 650319-1392610 | E4: 충청북도 청주시 상당구 중고개로142번길 17, (씨티프라디움 206-1305) | F4: 010-5498-6461 | K4: 45108 | M4: 2100000
A5: =A4+1 -> 4 | B5: 김태현 | C5: 과장 | D5: 921222-1386111 | E5: 충청북도 영동군 영동읍 영산로 25 | F5: 010-5031-8281 | K5: 45184 | M5: 2100000
A6: =A5+1 -> 5 | B6: 박인식 | D6: 570228- 1387118 | E6: 경기도 안산시 상록구 사2동 1396번지 401호 | F6: 010-3718-8935 | K6: 43070 | M6: 2100000
A7: =A6+1 -> 6 | B7: 이은애 | C7: 부장 | D7: 680409-2387111 | E7: 충청북도 영동군 영동읍 회동로 162 | F7: 010-5108-2005 | K7: 45170 | M7: 2100000
A8: =A7+1 -> 7 | B8: 이일복 | D8: 610101-1386227 | E8: 충청북도 영동군 용산면 율리4길 18-1 | K8: 45246 | M8: 2100000
A9: 8 | B9: 유지안 | C9: 부장 | D9: 760101-1384121 | K9: 2023.08.01 | L9: 2024.02.29 | M9: 2100000
A10: 9 | B10: 조태현 | C10: 과장 | D10: 660520-1386119 | K10: 2024.02.01 | M10: 2100000
A11: 10 | B11: 홍혜경 | C11: 대리 | D11: 790915-2813026 | K11: 2024.02.01 | M11: 2100000
A12: 11 | B12: 박봉환 | C12: 고장 | D12: 600713-1182814 | K12: 2024.02.01 | M12: 2100000

Sheet 1월
B3: 건우건설주식회사 | L3: 2024년 ( 01 )월 급여대장
B5: 지급일자 : 2024년 01월 31일
B7: NO | C7: 성명 | D7: 직책 | E7: 지 급 내 역(과세) | N7: 지급내역(비과세) | P7: 지급액 | Q7: 공 제 내 역 | W7: 공제계 | X7: 지급총액 | Z7: 부양가족수 본인포함 | AA7: 20세이하 자녀수 | AC7: 비과세 합계액
E8: 기본급 | F8: 월차수당 | G8: 직책수당 | H8: 야근수당 | I8: 근속수당 | J8: 현장수당 | K8: 기술수당 | L8: 년차수당 | M8: 상여금 | N8: 식비 | O8: 차량유지비 | Q8: 소득세 | R8: 지방 소득세 | S8: 국민연금 | T8: 건강보험 | U8: 장기요양보험 | V8: 고용보험
B9: 1 | C9: =[1]직원인적급여카드!B2 -> 안경이 | D9: =[1]직원인적급여카드!C2 -> 대표 | E9: 2100000 | N9: 200000 | O9: 200000 | P9: =SUM(E9:O9) -> 2500000 | Q9: =IFERROR(IF(P9-AC9<=10000000,VLOOKUP((P9-AC9)/1000,간이세액표,IF(11<Z9+AA9,13,2+Z9+AA9),TRUE),IF(P9-AC9>14000000,VLOOKUP((P9-AC9)/1000,간이세액표,IF(11<Z9+AA9,13,2+Z9+AA9),TRUE)+1372000+ROUNDDOWN(((P9-AC9-14000000)*98%)*38%,-1),VLOOKUP((P9-AC9)/1000,간이세액표,IF(11<Z9+AA9,13,2+Z9+AA9),TRUE)+ROUNDDOWN(((P9-AC9-10000000)*98%)*35%,-1))),) -> 25950 | R9: =ROUNDDOWN(Q9*10%,-1) -> 2590 | S9: =IFERROR(IF(AND(P9-AC9>=월액최저,P9-AC9<=월액최고),ROUNDDOWN((P9-AC9)*국민연금,-1),IF(P9-AC9>=월액최고,최고연금,IF(AND(P9-AC9<=월액최저,P9-AC9>=1),최저연금,))),) -> 99000 | T9: =IFERROR(ROUNDDOWN((P9-AC9)*3.43%,-1),) -> 75460 | U9: =ROUNDDOWN(T9*11.52%,-1) -> 8690 | V9: =IFERROR(IF(D9<>"대표이사",ROUNDDOWN((P9-AC9)*고용보험율,-1),0),) -> 17600 | W9: =SUM(Q9:V9) -> 229290 | X9: =P9-W9 -> 2270710 | Z9: 1 | AC9: =IF(N9>=100000,100000,N9)+IF(O9>=200000,200000,O9) -> 300000
B10: 2 | C10: =[1]직원인적급여카드!B3 -> 김성헌 | D10: =[1]직원인적급여카드!C3 -> 부장 | E10: =[1]직원인적급여카드!M3 -> 2100000 | N10: 200000 | O10: 200000 | P10: =SUM(E10:O10) -> 2500000 | Q10: =IFERROR(IF(P10-AC10<=10000000,VLOOKUP((P10-AC10)/1000,간이세액표,IF(11<Z10+AA10,13,2+Z10+AA10),TRUE),IF(P10-AC10>14000000,VLOOKUP((P10-AC10)/1000,간이세액표,IF(11<Z10+AA10,13,2+Z10+AA10),TRUE)+1372000+ROUNDDOWN(((P10-AC10-14000000)*98%)*38%,-1),VLOOKUP((P10-AC10)/1000,간이세액표,IF(11<Z10+AA10,13,2+Z10+AA10),TRUE)+ROUNDDOWN(((P10-AC10-10000000)*98%)*35%,-1))),) -> 25950 | R10: =ROUNDDOWN(Q10*10%,-1) -> 2590 | S10: =IFERROR(IF(AND(P10-AC10>=월액최저,P10-AC10<=월액최고),ROUNDDOWN((P10-AC10)*국민연금,-1),IF(P10-AC10>=월액최고,최고연금,IF(AND(P10-AC10<=월액최저,P10-AC10>=1),최저연금,))),) -> 99000 | T10: =IFERROR(ROUNDDOWN((P10-AC10)*3.43%,-1),) -> 75460 | U10: =ROUNDDOWN(T10*11.52%,-1) -> 8690 | V10: =IFERROR(IF(D10<>"대표이사",ROUNDDOWN((P10-AC10)*고용보험율,-1),0),) -> 17600 | W10: =SUM(Q10:V10) -> 229290 | X10: =P10-W10 -> 2270710 | Z10: 1 | AC10: =IF(N10>=100000,100000,N10)+IF(O10>=200000,200000,O10) -> 300000
B11: 3 | C11: =[1]직원인적급여카드!B4 -> 최종식 | D11: =[1]직원인적급여카드!C4 -> 부장 | E11: =[1]직원인적급여카드!M4 -> 2100000 | N11: 200000 | O11: 200000 | P11: =SUM(E11:O11) -> 2500000 | Q11: =IFERROR(IF(P11-AC11<=10000000,VLOOKUP((P11-AC11)/1000,간이세액표,IF(11<Z11+AA11,13,2+Z11+AA11),TRUE),IF(P11-AC11>14000000,VLOOKUP((P11-AC11)/1000,간이세액표,IF(11<Z11+AA11,13,2+Z11+AA11),TRUE)+1372000+ROUNDDOWN(((P11-AC11-14000000)*98%)*38%,-1),VLOOKUP((P11-AC11)/1000,간이세액표,IF(11<Z11+AA11,13,2+Z11+AA11),TRUE)+ROUNDDOWN(((P11-AC11-10000000)*98%)*35%,-1))),) -> 25950 | R11: =ROUNDDOWN(Q11*10%,-1) -> 2590 | S11: =IFERROR(IF(AND(P11-AC11>=월액최저,P11-AC11<=월액최고),ROUNDDOWN((P11-AC11)*국민연금,-1),IF(P11-AC11>=월액최고,최고연금,IF(AND(P11-AC11<=월액최저,P11-AC11>=1),최저연금,))),) -> 99000 | T11: =IFERROR(ROUNDDOWN((P11-AC11)*3.43%,-1),) -> 75460 | U11: =ROUNDDOWN(T11*11.52%,-1) -> 8690 | V11: =IFERROR(IF(D11<>"대표이사",ROUNDDOWN((P11-AC11)*고용보험율,-1),0),) -> 17600 | W11: =SUM(Q11:V11) -> 229290 | X11: =P11-W11 -> 2270710 | Z11: 1 | AC11: =IF(N11>=100000,100000,N11)+IF(O11>=200000,200000,O11) -> 300000
B12: 4 | C12: =[1]직원인적급여카드!B5 -> 김태현 | D12: =[1]직원인적급여카드!C5 -> 과장 | E12: =[1]직원인적급여카드!M5 -> 2100000 | N12: 200000 | O12: 200000 | P12: =SUM(E12:O12) -> 2500000 | Q12: =IFERROR(IF(P12-AC12<=10000000,VLOOKUP((P12-AC12)/1000,간이세액표,IF(11<Z12+AA12,13,2+Z12+AA12),TRUE),IF(P12-AC12>14000000,VLOOKUP((P12-AC12)/1000,간이세액표,IF(11<Z12+AA12,13,2+Z12+AA12),TRUE)+1372000+ROUNDDOWN(((P12-AC12-14000000)*98%)*38%,-1),VLOOKUP((P12-AC12)/1000,간이세액표,IF(11<Z12+AA12,13,2+Z12+AA12),TRUE)+ROUNDDOWN(((P12-AC12-10000000)*98%)*35%,-1))),) -> 25950 | R12: =ROUNDDOWN(Q12*10%,-1) -> 2590 | S12: =IFERROR(IF(AND(P12-AC12>=월액최저,P12-AC12<=월액최고),ROUNDDOWN((P12-AC12)*국민연금,-1),IF(P12-AC12>=월액최고,최고연금,IF(AND(P12-AC12<=월액최저,P12-AC12>=1),최저연금,))),) -> 99000 | T12: =IFERROR(ROUNDDOWN((P12-AC12)*3.43%,-1),) -> 75460 | U12: =ROUNDDOWN(T12*11.52%,-1) -> 8690 | V12: =IFERROR(IF(D12<>"대표이사",ROUNDDOWN((P12-AC12)*고용보험율,-1),0),) -> 17600 | W12: =SUM(Q12:V12) -> 229290 | X12: =P12-W12 -> 2270710 | Z12: 1 | AC12: =IF(N12>=100000,100000,N12)+IF(O12>=200000,200000,O12) -> 300000
B13: 5 | C13: =[1]직원인적급여카드!B6 -> 박인식 | D13: 부장 | E13: 2100000 | N13: 200000 | O13: 200000 | P13: =SUM(E13:O13) -> 2500000 | Q13: =IFERROR(IF(P13-AC13<=10000000,VLOOKUP((P13-AC13)/1000,간이세액표,IF(11<Z13+AA13,13,2+Z13+AA13),TRUE),IF(P13-AC13>14000000,VLOOKUP((P13-AC13)/1000,간이세액표,IF(11<Z13+AA13,13,2+Z13+AA13),TRUE)+1372000+ROUNDDOWN(((P13-AC13-14000000)*98%)*38%,-1),VLOOKUP((P13-AC13)/1000,간이세액표,IF(11<Z13+AA13,13,2+Z13+AA13),TRUE)+ROUNDDOWN(((P13-AC13-10000000)*98%)*35%,-1))),) -> 25950 | R13: =ROUNDDOWN(Q13*10%,-1) -> 2590 | T13: =IFERROR(ROUNDDOWN((P13-AC13)*3.43%,-1),) -> 75460 | U13: =ROUNDDOWN(T13*11.52%,-1) -> 8690 | V13: =IFERROR(IF(D13<>"대표이사",ROUNDDOWN((P13-AC13)*고용보험율,-1),0),) -> 17600 | W13: =SUM(Q13:V13) -> 130290 | X13: =P13-W13 -> 2369710 | Z13: 1 | AC13: =IF(N13>=100000,100000,N13)+IF(O13>=200000,200000,O13) -> 300000
B14: 6 | C14: =[1]직원인적급여카드!B7 -> 이은애 | D14: =[1]직원인적급여카드!C7 -> 부장 | E14: =[1]직원인적급여카드!M7 -> 2100000 | N14: 200000 | O14: 200000 | P14: =SUM(E14:O14) -> 2500000 | Q14: =IFERROR(IF(P14-AC14<=10000000,VLOOKUP((P14-AC14)/1000,간이세액표,IF(11<Z14+AA14,13,2+Z14+AA14),TRUE),IF(P14-AC14>14000000,VLOOKUP((P14-AC14)/1000,간이세액표,IF(11<Z14+AA14,13,2+Z14+AA14),TRUE)+1372000+ROUNDDOWN(((P14-AC14-14000000)*98%)*38%,-1),VLOOKUP((P14-AC14)/1000,간이세액표,IF(11<Z14+AA14,13,2+Z14+AA14),TRUE)+ROUNDDOWN(((P14-AC14-10000000)*98%)*35%,-1))),) -> 25950 | R14: =ROUNDDOWN(Q14*10%,-1) -> 2590 | S14: =IFERROR(IF(AND(P14-AC14>=월액최저,P14-AC14<=월액최고),ROUNDDOWN((P14-AC14)*국민연금,-1),IF(P14-AC14>=월액최고,최고연금,IF(AND(P14-AC14<=월액최저,P14-AC14>=1),최저연금,))),) -> 99000 | T14: =IFERROR(ROUNDDOWN((P14-AC14)*3.43%,-1),) -> 75460 | U14: =ROUNDDOWN(T14*11.52%,-1) -> 8690 | V14: =IFERROR(IF(D14<>"대표이사",ROUNDDOWN((P14-AC14)*고용보험율,-1),0),) -> 17600 | W14: =SUM(Q14:V14) -> 229290 | X14: =P14-W14 -> 2270710 | Z14: 1 | AC14: =IF(N14>=100000,100000,N14)+IF(O14>=200000,200000,O14) -> 300000
B15: 7 | C15: =[1]직원인적급여카드!B8 -> 이일복 | D15: 과장 | E15: =[1]직원인적급여카드!M8 -> 2100000 | N15: 200000 | O15: 200000 | P15: =SUM(E15:O15) -> 2500000 | Q15: =IFERROR(IF(P15-AC15<=10000000,VLOOKUP((P15-AC15)/1000,간이세액표,IF(11<Z15+AA15,13,2+Z15+AA15),TRUE),IF(P15-AC15>14000000,VLOOKUP((P15-AC15)/1000,간이세액표,IF(11<Z15+AA15,13,2+Z15+AA15),TRUE)+1372000+ROUNDDOWN(((P15-AC15-14000000)*98%)*38%,-1),VLOOKUP((P15-AC15)/1000,간이세액표,IF(11<Z15+AA15,13,2+Z15+AA15),TRUE)+ROUNDDOWN(((P15-AC15-10000000)*98%)*35%,-1))),) -> 25950 | R15: =ROUNDDOWN(Q15*10%,-1) -> 2590 | T15: =IFERROR(ROUNDDOWN((P15-AC15)*3.43%,-1),) -> 75460 | U15: =ROUNDDOWN(T15*11.52%,-1) -> 8690 | V15: =IFERROR(IF(D15<>"대표이사",ROUNDDOWN((P15-AC15)*고용보험율,-1),0),) -> 17600 | W15: =SUM(Q15:V15) -> 130290 | X15: =P15-W15 -> 2369710 | Z15: 1 | AC15: =IF(N15>=100000,100000,N15)+IF(O15>=200000,200000,O15) -> 300000
B16: 8 | C16: 유지안 | D16: 부장 | E16: 2100000 | N16: 200000 | O16: 200000 | P16: =SUM(E16:O16) -> 2500000 | Q16: =IFERROR(IF(P16-AC16<=10000000,VLOOKUP((P16-AC16)/1000,간이세액표,IF(11<Z16+AA16,13,2+Z16+AA16),TRUE),IF(P16-AC16>14000000,VLOOKUP((P16-AC16)/1000,간이세액표,IF(11<Z16+AA16,13,2+Z16+AA16),TRUE)+1372000+ROUNDDOWN(((P16-AC16-14000000)*98%)*38%,-1),VLOOKUP((P16-AC16)/1000,간이세액표,IF(11<Z16+AA16,13,2+Z16+AA16),TRUE)+ROUNDDOWN(((P16-AC16-10000000)*98%)*35%,-1))),) -> 25950 | R16: =ROUNDDOWN(Q16*10%,-1) -> 2590 | S16: =IFERROR(IF(AND(P16-AC16>=월액최저,P16-AC16<=월액최고),ROUNDDOWN((P16-AC16)*국민연금,-1),IF(P16-AC16>=월액최고,최고연금,IF(AND(P16-AC16<=월액최저,P16-AC16>=1),최저연금,))),) -> 99000 | T16: =IFERROR(ROUNDDOWN((P16-AC16)*3.43%,-1),) -> 75460 | U16: =ROUNDDOWN(T16*11.52%,-1) -> 8690 | V16: =IFERROR(IF(D16<>"대표이사",ROUNDDOWN((P16-AC16)*고용보험율,-1),0),) -> 17600 | W16: =SUM(Q16:V16) -> 229290 | X16: =P16-W16 -> 2270710 | Z16: 1 | AC16: =IF(N16>=100000,100000,N16)+IF(O16>=200000,200000,O16) -> 300000
B17: 9 | Z17: 1 | AC17: =IF(N17>=100000,100000,N17)+IF(O17>=200000,200000,O17) -> 0
B18: 10 | Z18: 1 | AC18: =IF(N18>=100000,100000,N18)+IF(O18>=200000,200000,O18) -> 0
B19: 11 | Z19: 1 | AC19: =IF(N19>=100000,100000,N19)+IF(O19>=200000,200000,O19) -> 0
B20: 12 | P20: =SUM(E20:O20) -> 0 | Q20: =IFERROR(IF(P20-AC20<=10000000,VLOOKUP((P20-AC20)/1000,간이세액표,IF(11<Z20+AA20,13,2+Z20+AA20),TRUE),IF(P20-AC20>14000000,VLOOKUP((P20-AC20)/1000,간이세액표,IF(11<Z20+AA20,13,2+Z20+AA20),TRUE)+1372000+ROUNDDOWN(((P20-AC20-14000000)*98%)*38%,-1),VLOOKUP((P20-AC20)/1000,간이세액표,IF(11<Z20+AA20,13,2+Z20+AA20),TRUE)+ROUNDDOWN(((P20-AC20-10000000)*98%)*35%,-1))),) -> 0 | R20: =ROUNDDOWN(Q20*10%,-1) -> 0 | S20: =IFERROR(IF(AND(P20-AC20>=월액최저,P20-AC20<=월액최고),ROUNDDOWN((P20-AC20)*국민연금,-1),IF(P20-AC20>=월액최고,최고연금,IF(AND(P20-AC20<=월액최저,P20-AC20>=1),최저연금,))),) -> 0 | T20: =IFERROR(ROUNDDOWN((P20-AC20)*건강보험율,-1),) -> 0 | U20: =ROUNDDOWN(T20*요양보험율,-1) -> 0 | V20: =IFERROR(IF(D20<>"대표이사",ROUNDDOWN((P20-AC20)*고용보험율,-1),0),) -> 0 | W20: =SUM(Q20:V20) -> 0 | X20: =P20-W20 -> 0 | Z20: 1 | AC20: =IF(N20>=100000,100000,N20)+IF(O20>=200000,200000,O20) -> 0
B21: 13 | P21: =SUM(E21:O21) -> 0 | Q21: =IFERROR(IF(P21-AC21<=10000000,VLOOKUP((P21-AC21)/1000,간이세액표,IF(11<Z21+AA21,13,2+Z21+AA21),TRUE),IF(P21-AC21>14000000,VLOOKUP((P21-AC21)/1000,간이세액표,IF(11<Z21+AA21,13,2+Z21+AA21),TRUE)+1372000+ROUNDDOWN(((P21-AC21-14000000)*98%)*38%,-1),VLOOKUP((P21-AC21)/1000,간이세액표,IF(11<Z21+AA21,13,2+Z21+AA21),TRUE)+ROUNDDOWN(((P21-AC21-10000000)*98%)*35%,-1))),) -> 0 | R21: =ROUNDDOWN(Q21*10%,-1) -> 0 | S21: =IFERROR(IF(AND(P21-AC21>=월액최저,P21-AC21<=월액최고),ROUNDDOWN((P21-AC21)*국민연금,-1),IF(P21-AC21>=월액최고,최고연금,IF(AND(P21-AC21<=월액최저,P21-AC21>=1),최저연금,))),) -> 0 | T21: =IFERROR(ROUNDDOWN((P21-AC21)*건강보험율,-1),) -> 0 | U21: =ROUNDDOWN(T21*요양보험율,-1) -> 0 | V21: =IFERROR(IF(D21<>"대표이사",ROUNDDOWN((P21-AC21)*고용보험율,-1),0),) -> 0 | W21: =SUM(Q21:V21) -> 0 | X21: =P21-W21 -> 0 | Z21: 1 | AC21: =IF(N21>=100000,100000,N21)+IF(O21>=200000,200000,O21) -> 0
B22: 합계 | E22: =SUM(E9:E21) -> 16800000 | F22: =SUM(F9:F21) -> 0 | G22: =SUM(G9:G21) -> 0 | H22: =SUM(H9:H21) -> 0 | I22: =SUM(I9:I21) -> 0 | J22: =SUM(J9:J21) -> 0 | K22: =SUM(K9:K21) -> 0 | L22: =SUM(L9:L21) -> 0 | ... X22: =SUM(X9:X21) -> 18363680
B23: *참고 : 대표자는 직책에 "대표이사"라고 입력해야만 고용보험 "0"으로 처리됨 / 부양가족수본인포함에 1인이상넣어야 소득세계산됨
H24: 주 소
B25: 입사자
B28: 퇴사자

Sheet 2월
B3: 건우건설주식회사 | L3: 2024년 ( 02 )월 급여대장
B5: 지급일자 : 2024년 02월 29일
B7: NO | C7: 성명 | D7: 직책 | E7: 지 급 내 역(과세) | N7: 지급내역(비과세) | P7: 지급액 | Q7: 공 제 내 역 | W7: 공제계 | X7: 지급총액 | Z7: 부양가족수 본인포함 | AA7: 20세이하 자녀수 | AC7: 비과세 합계액
E8: 기본급 | F8: 월차수당 | G8: 직책수당 | H8: 야근수당 | I8: 근속수당 | J8: 현장수당 | K8: 기술수당 | L8: 년차수당 | M8: 상여금 | N8: 식비 | O8: 차량유지비 | Q8: 소득세 | R8: 지방 소득세 | S8: 국민연금 | T8: 건강보험 | U8: 장기요양보험 | V8: 고용보험
B9: 1 | C9: =[1]직원인적급여카드!B2 -> 안경이 | D9: =[1]직원인적급여카드!C2 -> 대표 | E9: 2100000 | N9: 200000 | O9: 200000 | P9: =SUM(E9:O9) -> 2500000 | Q9: =IFERROR(IF(P9-AC9<=10000000,VLOOKUP((P9-AC9)/1000,간이세액표,IF(11<Z9+AA9,13,2+Z9+AA9),TRUE),IF(P9-AC9>14000000,VLOOKUP((P9-AC9)/1000,간이세액표,IF(11<Z9+AA9,13,2+Z9+AA9),TRUE)+1372000+ROUNDDOWN(((P9-AC9-14000000)*98%)*38%,-1),VLOOKUP((P9-AC9)/1000,간이세액표,IF(11<Z9+AA9,13,2+Z9+AA9),TRUE)+ROUNDDOWN(((P9-AC9-10000000)*98%)*35%,-1))),) -> 25950 | R9: =ROUNDDOWN(Q9*10%,-1) -> 2590 | S9: =IFERROR(IF(AND(P9-AC9>=월액최저,P9-AC9<=월액최고),ROUNDDOWN((P9-AC9)*국민연금,-1),IF(P9-AC9>=월액최고,최고연금,IF(AND(P9-AC9<=월액최저,P9-AC9>=1),최저연금,))),) -> 99000 | T9: =IFERROR(ROUNDDOWN((P9-AC9)*3.43%,-1),) -> 75460 | U9: =ROUNDDOWN(T9*11.52%,-1) -> 8690 | V9: =IFERROR(IF(D9<>"대표이사",ROUNDDOWN((P9-AC9)*고용보험율,-1),0),) -> 17600 | W9: =SUM(Q9:V9) -> 229290 | X9: =P9-W9 -> 2270710 | Z9: 1 | AC9: =IF(N9>=100000,100000,N9)+IF(O9>=200000,200000,O9) -> 300000
B10: 2 | C10: =[1]직원인적급여카드!B3 -> 김성헌 | D10: =[1]직원인적급여카드!C3 -> 부장 | E10: =[1]직원인적급여카드!M3 -> 2100000 | N10: 200000 | O10: 200000 | P10: =SUM(E10:O10) -> 2500000 | Q10: =IFERROR(IF(P10-AC10<=10000000,VLOOKUP((P10-AC10)/1000,간이세액표,IF(11<Z10+AA10,13,2+Z10+AA10),TRUE),IF(P10-AC10>14000000,VLOOKUP((P10-AC10)/1000,간이세액표,IF(11<Z10+AA10,13,2+Z10+AA10),TRUE)+1372000+ROUNDDOWN(((P10-AC10-14000000)*98%)*38%,-1),VLOOKUP((P10-AC10)/1000,간이세액표,IF(11<Z10+AA10,13,2+Z10+AA10),TRUE)+ROUNDDOWN(((P10-AC10-10000000)*98%)*35%,-1))),) -> 25950 | R10: =ROUNDDOWN(Q10*10%,-1) -> 2590 | S10: =IFERROR(IF(AND(P10-AC10>=월액최저,P10-AC10<=월액최고),ROUNDDOWN((P10-AC10)*국민연금,-1),IF(P10-AC10>=월액최고,최고연금,IF(AND(P10-AC10<=월액최저,P10-AC10>=1),최저연금,))),) -> 99000 | T10: =IFERROR(ROUNDDOWN((P10-AC10)*3.43%,-1),) -> 75460 | U10: =ROUNDDOWN(T10*11.52%,-1) -> 8690 | V10: =IFERROR(IF(D10<>"대표이사",ROUNDDOWN((P10-AC10)*고용보험율,-1),0),) -> 17600 | W10: =SUM(Q10:V10) -> 229290 | X10: =P10-W10 -> 2270710 | Z10: 1 | AC10: =IF(N10>=100000,100000,N10)+IF(O10>=200000,200000,O10) -> 300000
B11: 3 | C11: =[1]직원인적급여카드!B4 -> 최종식 | D11: =[1]직원인적급여카드!C4 -> 부장 | E11: =[1]직원인적급여카드!M4 -> 2100000 | N11: 200000 | O11: 200000 | P11: =SUM(E11:O11) -> 2500000 | Q11: =IFERROR(IF(P11-AC11<=10000000,VLOOKUP((P11-AC11)/1000,간이세액표,IF(11<Z11+AA11,13,2+Z11+AA11),TRUE),IF(P11-AC11>14000000,VLOOKUP((P11-AC11)/1000,간이세액표,IF(11<Z11+AA11,13,2+Z11+AA11),TRUE)+1372000+ROUNDDOWN(((P11-AC11-14000000)*98%)*38%,-1),VLOOKUP((P11-AC11)/1000,간이세액표,IF(11<Z11+AA11,13,2+Z11+AA11),TRUE)+ROUNDDOWN(((P11-AC11-10000000)*98%)*35%,-1))),) -> 25950 | R11: =ROUNDDOWN(Q11*10%,-1) -> 2590 | S11: =IFERROR(IF(AND(P11-AC11>=월액최저,P11-AC11<=월액최고),ROUNDDOWN((P11-AC11)*국민연금,-1),IF(P11-AC11>=월액최고,최고연금,IF(AND(P11-AC11<=월액최저,P11-AC11>=1),최저연금,))),) -> 99000 | T11: =IFERROR(ROUNDDOWN((P11-AC11)*3.43%,-1),) -> 75460 | U11: =ROUNDDOWN(T11*11.52%,-1) -> 8690 | V11: =IFERROR(IF(D11<>"대표이사",ROUNDDOWN((P11-AC11)*고용보험율,-1),0),) -> 17600 | W11: =SUM(Q11:V11) -> 229290 | X11: =P11-W11 -> 2270710 | Z11: 1 | AC11: =IF(N11>=100000,100000,N11)+IF(O11>=200000,200000,O11) -> 300000
B12: 4 | C12: =[1]직원인적급여카드!B5 -> 김태현 | D12: =[1]직원인적급여카드!C5 -> 과장 | E12: =[1]직원인적급여카드!M5 -> 2100000 | N12: 200000 | O12: 200000 | P12: =SUM(E12:O12) -> 2500000 | Q12: =IFERROR(IF(P12-AC12<=10000000,VLOOKUP((P12-AC12)/1000,간이세액표,IF(11<Z12+AA12,13,2+Z12+AA12),TRUE),IF(P12-AC12>14000000,VLOOKUP((P12-AC12)/1000,간이세액표,IF(11<Z12+AA12,13,2+Z12+AA12),TRUE)+1372000+ROUNDDOWN(((P12-AC12-14000000)*98%)*38%,-1),VLOOKUP((P12-AC12)/1000,간이세액표,IF(11<Z12+AA12,13,2+Z12+AA12),TRUE)+ROUNDDOWN(((P12-AC12-10000000)*98%)*35%,-1))),) -> 25950 | R12: =ROUNDDOWN(Q12*10%,-1) -> 2590 | S12: =IFERROR(IF(AND(P12-AC12>=월액최저,P12-AC12<=월액최고),ROUNDDOWN((P12-AC12)*국민연금,-1),IF(P12-AC12>=월액최고,최고연금,IF(AND(P12-AC12<=월액최저,P12-AC12>=1),최저연금,))),) -> 99000 | T12: =IFERROR(ROUNDDOWN((P12-AC12)*3.43%,-1),) -> 75460 | U12: =ROUNDDOWN(T12*11.52%,-1) -> 8690 | V12: =IFERROR(IF(D12<>"대표이사",ROUNDDOWN((P12-AC12)*고용보험율,-1),0),) -> 17600 | W12: =SUM(Q12:V12) -> 229290 | X12: =P12-W12 -> 2270710 | Z12: 1 | AC12: =IF(N12>=100000,100000,N12)+IF(O12>=200000,200000,O12) -> 300000
B13: 5 | C13: =[1]직원인적급여카드!B6 -> 박인식 | D13: 부장 | E13: 2100000 | N13: 200000 | O13: 200000 | P13: =SUM(E13:O13) -> 2500000 | Q13: =IFERROR(IF(P13-AC13<=10000000,VLOOKUP((P13-AC13)/1000,간이세액표,IF(11<Z13+AA13,13,2+Z13+AA13),TRUE),IF(P13-AC13>14000000,VLOOKUP((P13-AC13)/1000,간이세액표,IF(11<Z13+AA13,13,2+Z13+AA13),TRUE)+1372000+ROUNDDOWN(((P13-AC13-14000000)*98%)*38%,-1),VLOOKUP((P13-AC13)/1000,간이세액표,IF(11<Z13+AA13,13,2+Z13+AA13),TRUE)+ROUNDDOWN(((P13-AC13-10000000)*98%)*35%,-1))),) -> 25950 | R13: =ROUNDDOWN(Q13*10%,-1) -> 2590 | T13: =IFERROR(ROUNDDOWN((P13-AC13)*3.43%,-1),) -> 75460 | U13: =ROUNDDOWN(T13*11.52%,-1) -> 8690 | V13: =IFERROR(IF(D13<>"대표이사",ROUNDDOWN((P13-AC13)*고용보험율,-1),0),) -> 17600 | W13: =SUM(Q13:V13) -> 130290 | X13: =P13-W13 -> 2369710 | Z13: 1 | AC13: =IF(N13>=100000,100000,N13)+IF(O13>=200000,200000,O13) -> 300000
B14: 6 | C14: =[1]직원인적급여카드!B7 -> 이은애 | D14: =[1]직원인적급여카드!C7 -> 부장 | E14: =[1]직원인적급여카드!M7 -> 2100000 | N14: 200000 | O14: 200000 | P14: =SUM(E14:O14) -> 2500000 | Q14: =IFERROR(IF(P14-AC14<=10000000,VLOOKUP((P14-AC14)/1000,간이세액표,IF(11<Z14+AA14,13,2+Z14+AA14),TRUE),IF(P14-AC14>14000000,VLOOKUP((P14-AC14)/1000,간이세액표,IF(11<Z14+AA14,13,2+Z14+AA14),TRUE)+1372000+ROUNDDOWN(((P14-AC14-14000000)*98%)*38%,-1),VLOOKUP((P14-AC14)/1000,간이세액표,IF(11<Z14+AA14,13,2+Z14+AA14),TRUE)+ROUNDDOWN(((P14-AC14-10000000)*98%)*35%,-1))),) -> 25950 | R14: =ROUNDDOWN(Q14*10%,-1) -> 2590 | S14: =IFERROR(IF(AND(P14-AC14>=월액최저,P14-AC14<=월액최고),ROUNDDOWN((P14-AC14)*국민연금,-1),IF(P14-AC14>=월액최고,최고연금,IF(AND(P14-AC14<=월액최저,P14-AC14>=1),최저연금,))),) -> 99000 | T14: =IFERROR(ROUNDDOWN((P14-AC14)*3.43%,-1),) -> 75460 | U14: =ROUNDDOWN(T14*11.52%,-1) -> 8690 | V14: =IFERROR(IF(D14<>"대표이사",ROUNDDOWN((P14-AC14)*고용보험율,-1),0),) -> 17600 | W14: =SUM(Q14:V14) -> 229290 | X14: =P14-W14 -> 2270710 | Z14: 1 | AC14: =IF(N14>=100000,100000,N14)+IF(O14>=200000,200000,O14) -> 300000
B15: 7 | C15: =[1]직원인적급여카드!B8 -> 이일복 | D15: 과장 | E15: =[1]직원인적급여카드!M8 -> 2100000 | N15: 200000 | O15: 200000 | P15: =SUM(E15:O15) -> 2500000 | Q15: =IFERROR(IF(P15-AC15<=10000000,VLOOKUP((P15-AC15)/1000,간이세액표,IF(11<Z15+AA15,13,2+Z15+AA15),TRUE),IF(P15-AC15>14000000,VLOOKUP((P15-AC15)/1000,간이세액표,IF(11<Z15+AA15,13,2+Z15+AA15),TRUE)+1372000+ROUNDDOWN(((P15-AC15-14000000)*98%)*38%,-1),VLOOKUP((P15-AC15)/1000,간이세액표,IF(11<Z15+AA15,13,2+Z15+AA15),TRUE)+ROUNDDOWN(((P15-AC15-10000000)*98%)*35%,-1))),) -> 25950 | R15: =ROUNDDOWN(Q15*10%,-1) -> 2590 | T15: =IFERROR(ROUNDDOWN((P15-AC15)*3.43%,-1),) -> 75460 | U15: =ROUNDDOWN(T15*11.52%,-1) -> 8690 | V15: =IFERROR(IF(D15<>"대표이사",ROUNDDOWN((P15-AC15)*고용보험율,-1),0),) -> 17600 | W15: =SUM(Q15:V15) -> 130290 | X15: =P15-W15 -> 2369710 | Z15: 1 | AC15: =IF(N15>=100000,100000,N15)+IF(O15>=200000,200000,O15) -> 300000
B16: 8 | C16: 유지안 | D16: 부장 | E16: 2100000 | N16: 200000 | O16: 200000 | P16: =SUM(E16:O16) -> 2500000 | Q16: =IFERROR(IF(P16-AC16<=10000000,VLOOKUP((P16-AC16)/1000,간이세액표,IF(11<Z16+AA16,13,2+Z16+AA16),TRUE),IF(P16-AC16>14000000,VLOOKUP((P16-AC16)/1000,간이세액표,IF(11<Z16+AA16,13,2+Z16+AA16),TRUE)+1372000+ROUNDDOWN(((P16-AC16-14000000)*98%)*38%,-1),VLOOKUP((P16-AC16)/1000,간이세액표,IF(11<Z16+AA16,13,2+Z16+AA16),TRUE)+ROUNDDOWN(((P16-AC16-10000000)*98%)*35%,-1))),) -> 25950 | R16: =ROUNDDOWN(Q16*10%,-1) -> 2590 | S16: =IFERROR(IF(AND(P16-AC16>=월액최저,P16-AC16<=월액최고),ROUNDDOWN((P16-AC16)*국민연금,-1),IF(P16-AC16>=월액최고,최고연금,IF(AND(P16-AC16<=월액최저,P16-AC16>=1),최저연금,))),) -> 99000 | T16: =IFERROR(ROUNDDOWN((P16-AC16)*3.43%,-1),) -> 75460 | U16: =ROUNDDOWN(T16*11.52%,-1) -> 8690 | V16: =IFERROR(IF(D16<>"대표이사",ROUNDDOWN((P16-AC16)*고용보험율,-1),0),) -> 17600 | W16: =SUM(Q16:V16) -> 229290 | X16: =P16-W16 -> 2270710 | Z16: 1 | AC16: =IF(N16>=100000,100000,N16)+IF(O16>=200000,200000,O16) -> 300000
B17: 9 | C17: 조태현 | D17: 과장 | E17: 2100000 | N17: 200000 | O17: 200000 | P17: =SUM(E17:O17) -> 2500000 | Q17: =IFERROR(IF(P17-AC17<=10000000,VLOOKUP((P17-AC17)/1000,간이세액표,IF(11<Z17+AA17,13,2+Z17+AA17),TRUE),IF(P17-AC17>14000000,VLOOKUP((P17-AC17)/1000,간이세액표,IF(11<Z17+AA17,13,2+Z17+AA17),TRUE)+1372000+ROUNDDOWN(((P17-AC17-14000000)*98%)*38%,-1),VLOOKUP((P17-AC17)/1000,간이세액표,IF(11<Z17+AA17,13,2+Z17+AA17),TRUE)+ROUNDDOWN(((P17-AC17-10000000)*98%)*35%,-1))),) -> 25950 | R17: =ROUNDDOWN(Q17*10%,-1) -> 2590 | S17: =IFERROR(IF(AND(P17-AC17>=월액최저,P17-AC17<=월액최고),ROUNDDOWN((P17-AC17)*국민연금,-1),IF(P17-AC17>=월액최고,최고연금,IF(AND(P17-AC17<=월액최저,P17-AC17>=1),최저연금,))),) -> 99000 | T17: =IFERROR(ROUNDDOWN((P17-AC17)*건강보험율,-1),) -> 75460 | U17: =ROUNDDOWN(T17*11.52%,-1) -> 8690 | V17: =IFERROR(IF(D17<>"대표이사",ROUNDDOWN((P17-AC17)*고용보험율,-1),0),) -> 17600 | W17: =SUM(Q17:V17) -> 229290 | X17: =P17-W17 -> 2270710 | Z17: 1 | AC17: =IF(N17>=100000,100000,N17)+IF(O17>=200000,200000,O17) -> 300000
B18: 10 | C18: 홍혜경 | D18: 대리 | E18: 2100000 | N18: 200000 | O18: 200000 | P18: =SUM(E18:O18) -> 2500000 | Q18: =IFERROR(IF(P18-AC18<=10000000,VLOOKUP((P18-AC18)/1000,간이세액표,IF(11<Z18+AA18,13,2+Z18+AA18),TRUE),IF(P18-AC18>14000000,VLOOKUP((P18-AC18)/1000,간이세액표,IF(11<Z18+AA18,13,2+Z18+AA18),TRUE)+1372000+ROUNDDOWN(((P18-AC18-14000000)*98%)*38%,-1),VLOOKUP((P18-AC18)/1000,간이세액표,IF(11<Z18+AA18,13,2+Z18+AA18),TRUE)+ROUNDDOWN(((P18-AC18-10000000)*98%)*35%,-1))),) -> 25950 | R18: =ROUNDDOWN(Q18*10%,-1) -> 2590 | S18: =IFERROR(IF(AND(P18-AC18>=월액최저,P18-AC18<=월액최고),ROUNDDOWN((P18-AC18)*국민연금,-1),IF(P18-AC18>=월액최고,최고연금,IF(AND(P18-AC18<=월액최저,P18-AC18>=1),최저연금,))),) -> 99000 | T18: =IFERROR(ROUNDDOWN((P18-AC18)*건강보험율,-1),) -> 75460 | U18: =ROUNDDOWN(T18*11.52%,-1) -> 8690 | V18: =IFERROR(IF(D18<>"대표이사",ROUNDDOWN((P18-AC18)*고용보험율,-1),0),) -> 17600 | W18: =SUM(Q18:V18) -> 229290 | X18: =P18-W18 -> 2270710 | Z18: 1 | AC18: =IF(N18>=100000,100000,N18)+IF(O18>=200000,200000,O18) -> 300000
B19: 11 | C19: 박봉환 | D19: 과장 | E19: 2100000 | N19: 200000 | O19: 200000 | P19: =SUM(E19:O19) -> 2500000 | Q19: =IFERROR(IF(P19-AC19<=10000000,VLOOKUP((P19-AC19)/1000,간이세액표,IF(11<Z19+AA19,13,2+Z19+AA19),TRUE),IF(P19-AC19>14000000,VLOOKUP((P19-AC19)/1000,간이세액표,IF(11<Z19+AA19,13,2+Z19+AA19),TRUE)+1372000+ROUNDDOWN(((P19-AC19-14000000)*98%)*38%,-1),VLOOKUP((P19-AC19)/1000,간이세액표,IF(11<Z19+AA19,13,2+Z19+AA19),TRUE)+ROUNDDOWN(((P19-AC19-10000000)*98%)*35%,-1))),) -> 25950 | R19: =ROUNDDOWN(Q19*10%,-1) -> 2590 | T19: =IFERROR(ROUNDDOWN((P19-AC19)*건강보험율,-1),) -> 75460 | U19: =ROUNDDOWN(T19*11.52%,-1) -> 8690 | V19: =IFERROR(IF(D19<>"대표이사",ROUNDDOWN((P19-AC19)*고용보험율,-1),0),) -> 17600 | W19: =SUM(Q19:V19) -> 130290 | X19: =P19-W19 -> 2369710 | Z19: 1 | AC19: =IF(N19>=100000,100000,N19)+IF(O19>=200000,200000,O19) -> 300000
B20: 12 | P20: =SUM(E20:O20) -> 0 | Q20: =IFERROR(IF(P20-AC20<=10000000,VLOOKUP((P20-AC20)/1000,간이세액표,IF(11<Z20+AA20,13,2+Z20+AA20),TRUE),IF(P20-AC20>14000000,VLOOKUP((P20-AC20)/1000,간이세액표,IF(11<Z20+AA20,13,2+Z20+AA20),TRUE)+1372000+ROUNDDOWN(((P20-AC20-14000000)*98%)*38%,-1),VLOOKUP((P20-AC20)/1000,간이세액표,IF(11<Z20+AA20,13,2+Z20+AA20),TRUE)+ROUNDDOWN(((P20-AC20-10000000)*98%)*35%,-1))),) -> 0 | R20: =ROUNDDOWN(Q20*10%,-1) -> 0 | S20: =IFERROR(IF(AND(P20-AC20>=월액최저,P20-AC20<=월액최고),ROUNDDOWN((P20-AC20)*국민연금,-1),IF(P20-AC20>=월액최고,최고연금,IF(AND(P20-AC20<=월액최저,P20-AC20>=1),최저연금,))),) -> 0 | T20: =IFERROR(ROUNDDOWN((P20-AC20)*건강보험율,-1),) -> 0 | U20: =ROUNDDOWN(T20*요양보험율,-1) -> 0 | V20: =IFERROR(IF(D20<>"대표이사",ROUNDDOWN((P20-AC20)*고용보험율,-1),0),) -> 0 | W20: =SUM(Q20:V20) -> 0 | X20: =P20-W20 -> 0 | Z20: 1 | AC20: =IF(N20>=100000,100000,N20)+IF(O20>=200000,200000,O20) -> 0
B21: 13 | P21: =SUM(E21:O21) -> 0 | Q21: =IFERROR(IF(P21-AC21<=10000000,VLOOKUP((P21-AC21)/1000,간이세액표,IF(11<Z21+AA21,13,2+Z21+AA21),TRUE),IF(P21-AC21>14000000,VLOOKUP((P21-AC21)/1000,간이세액표,IF(11<Z21+AA21,13,2+Z21+AA21),TRUE)+1372000+ROUNDDOWN(((P21-AC21-14000000)*98%)*38%,-1),VLOOKUP((P21-AC21)/1000,간이세액표,IF(11<Z21+AA21,13,2+Z21+AA21),TRUE)+ROUNDDOWN(((P21-AC21-10000000)*98%)*35%,-1))),) -> 0 | R21: =ROUNDDOWN(Q21*10%,-1) -> 0 | S21: =IFERROR(IF(AND(P21-AC21>=월액최저,P21-AC21<=월액최고),ROUNDDOWN((P21-AC21)*국민연금,-1),IF(P21-AC21>=월액최고,최고연금,IF(AND(P21-AC21<=월액최저,P21-AC21>=1),최저연금,))),) -> 0 | T21: =IFERROR(ROUNDDOWN((P21-AC21)*건강보험율,-1),) -> 0 | U21: =ROUNDDOWN(T21*요양보험율,-1) -> 0 | V21: =IFERROR(IF(D21<>"대표이사",ROUNDDOWN((P21-AC21)*고용보험율,-1),0),) -> 0 | W21: =SUM(Q21:V21) -> 0 | X21: =P21-W21 -> 0
B22: 합계 | E22: =SUM(E9:E21) -> 23100000 | F22: =SUM(F9:F21) -> 0 | G22: =SUM(G9:G21) -> 0 | H22: =SUM(H9:H21) -> 0 | I22: =SUM(I9:I21) -> 0 | J22: =SUM(J9:J21) -> 0 | K22: =SUM(K9:K21) -> 0 | L22: =SUM(L9:L21) -> 0 | ... X22: =SUM(X9:X21) -> 25274810
B23: *참고 : 대표자는 직책에 "대표이사"라고 입력해야만 고용보험 "0"으로 처리됨 / 부양가족수본인포함에 1인이상넣어야 소득세계산됨
C24: 조태현 | D24: 660520-1386119 | F24: 2023.02.01 | H24: 주 소
B25: 입사자 | C25: 홍혜경 | D25: 790915-2813026 | F25: 2023.02.01
C26: 박봉환 | D26: 600713-1182814 | F26: 2023.02.01
B28: 퇴사자 | C28: 유지안 | D28: 760101-1384121 | F28: 2023.02.29

Sheet 3월
B3: 건우건설주식회사 | L3: 2024년 ( 03 )월 급여대장
B5: 지급일자 : 2024년 03월 31일
B7: NO | C7: 성명 | D7: 직책 | E7: 지 급 내 역(과세) | N7: 지급내역(비과세) | P7: 지급액 | Q7: 공 제 내 역 | W7: 공제계 | X7: 지급총액 | Z7: 부양가족수 본인포함 | AA7: 20세이하 자녀수 | AC7: 비과세 합계액
E8: 기본급 | F8: 월차수당 | G8: 직책수당 | H8: 야근수당 | I8: 근속수당 | J8: 현장수당 | K8: 기술수당 | L8: 년차수당 | M8: 상여금 | N8: 식비 | O8: 차량유지비 | Q8: 소득세 | R8: 지방 소득세 | S8: 국민연금 | T8: 건강보험 | U8: 장기요양보험 | V8: 고용보험
B9: 1 | C9: =[1]직원인적급여카드!B2 -> 안경이 | D9: =[1]직원인적급여카드!C2 -> 대표 | E9: 2100000 | N9: 200000 | O9: 200000 | P9: =SUM(E9:O9) -> 2500000 | Q9: =IFERROR(IF(P9-AC9<=10000000,VLOOKUP((P9-AC9)/1000,간이세액표,IF(11<Z9+AA9,13,2+Z9+AA9),TRUE),IF(P9-AC9>14000000,VLOOKUP((P9-AC9)/1000,간이세액표,IF(11<Z9+AA9,13,2+Z9+AA9),TRUE)+1372000+ROUNDDOWN(((P9-AC9-14000000)*98%)*38%,-1),VLOOKUP((P9-AC9)/1000,간이세액표,IF(11<Z9+AA9,13,2+Z9+AA9),TRUE)+ROUNDDOWN(((P9-AC9-10000000)*98%)*35%,-1))),) -> 25950 | R9: =ROUNDDOWN(Q9*10%,-1) -> 2590 | S9: =IFERROR(IF(AND(P9-AC9>=월액최저,P9-AC9<=월액최고),ROUNDDOWN((P9-AC9)*국민연금,-1),IF(P9-AC9>=월액최고,최고연금,IF(AND(P9-AC9<=월액최저,P9-AC9>=1),최저연금,))),) -> 99000 | T9: =IFERROR(ROUNDDOWN((P9-AC9)*3.43%,-1),) -> 75460 | U9: =ROUNDDOWN(T9*11.52%,-1) -> 8690 | V9: =IFERROR(IF(D9<>"대표이사",ROUNDDOWN((P9-AC9)*고용보험율,-1),0),) -> 17600 | W9: =SUM(Q9:V9) -> 229290 | X9: =P9-W9 -> 2270710 | Z9: 1 | AC9: =IF(N9>=100000,100000,N9)+IF(O9>=200000,200000,O9) -> 300000
B10: 2 | C10: =[1]직원인적급여카드!B3 -> 김성헌 | D10: =[1]직원인적급여카드!C3 -> 부장 | E10: =[1]직원인적급여카드!M3 -> 2100000 | N10: 200000 | O10: 200000 | P10: =SUM(E10:O10) -> 2500000 | Q10: =IFERROR(IF(P10-AC10<=10000000,VLOOKUP((P10-AC10)/1000,간이세액표,IF(11<Z10+AA10,13,2+Z10+AA10),TRUE),IF(P10-AC10>14000000,VLOOKUP((P10-AC10)/1000,간이세액표,IF(11<Z10+AA10,13,2+Z10+AA10),TRUE)+1372000+ROUNDDOWN(((P10-AC10-14000000)*98%)*38%,-1),VLOOKUP((P10-AC10)/1000,간이세액표,IF(11<Z10+AA10,13,2+Z10+AA10),TRUE)+ROUNDDOWN(((P10-AC10-10000000)*98%)*35%,-1))),) -> 25950 | R10: =ROUNDDOWN(Q10*10%,-1) -> 2590 | S10: =IFERROR(IF(AND(P10-AC10>=월액최저,P10-AC10<=월액최고),ROUNDDOWN((P10-AC10)*국민연금,-1),IF(P10-AC10>=월액최고,최고연금,IF(AND(P10-AC10<=월액최저,P10-AC10>=1),최저연금,))),) -> 99000 | T10: =IFERROR(ROUNDDOWN((P10-AC10)*3.43%,-1),) -> 75460 | U10: =ROUNDDOWN(T10*11.52%,-1) -> 8690 | V10: =IFERROR(IF(D10<>"대표이사",ROUNDDOWN((P10-AC10)*고용보험율,-1),0),) -> 17600 | W10: =SUM(Q10:V10) -> 229290 | X10: =P10-W10 -> 2270710 | Z10: 1 | AC10: =IF(N10>=100000,100000,N10)+IF(O10>=200000,200000,O10) -> 300000
B11: 3 | C11: =[1]직원인적급여카드!B4 -> 최종식 | D11: =[1]직원인적급여카드!C4 -> 부장 | E11: =[1]직원인적급여카드!M4 -> 2100000 | N11: 200000 | O11: 200000 | P11: =SUM(E11:O11) -> 2500000 | Q11: =IFERROR(IF(P11-AC11<=10000000,VLOOKUP((P11-AC11)/1000,간이세액표,IF(11<Z11+AA11,13,2+Z11+AA11),TRUE),IF(P11-AC11>14000000,VLOOKUP((P11-AC11)/1000,간이세액표,IF(11<Z11+AA11,13,2+Z11+AA11),TRUE)+1372000+ROUNDDOWN(((P11-AC11-14000000)*98%)*38%,-1),VLOOKUP((P11-AC11)/1000,간이세액표,IF(11<Z11+AA11,13,2+Z11+AA11),TRUE)+ROUNDDOWN(((P11-AC11-10000000)*98%)*35%,-1))),) -> 25950 | R11: =ROUNDDOWN(Q11*10%,-1) -> 2590 | S11: =IFERROR(IF(AND(P11-AC11>=월액최저,P11-AC11<=월액최고),ROUNDDOWN((P11-AC11)*국민연금,-1),IF(P11-AC11>=월액최고,최고연금,IF(AND(P11-AC11<=월액최저,P11-AC11>=1),최저연금,))),) -> 99000 | T11: =IFERROR(ROUNDDOWN((P11-AC11)*3.43%,-1),) -> 75460 | U11: =ROUNDDOWN(T11*11.52%,-1) -> 8690 | V11: =IFERROR(IF(D11<>"대표이사",ROUNDDOWN((P11-AC11)*고용보험율,-1),0),) -> 17600 | W11: =SUM(Q11:V11) -> 229290 | X11: =P11-W11 -> 2270710 | Z11: 1 | AC11: =IF(N11>=100000,100000,N11)+IF(O11>=200000,200000,O11) -> 300000
B12: 4 | C12: =[1]직원인적급여카드!B5 -> 김태현 | D12: =[1]직원인적급여카드!C5 -> 과장 | E12: =[1]직원인적급여카드!M5 -> 2100000 | N12: 200000 | O12: 200000 | P12: =SUM(E12:O12) -> 2500000 | Q12: =IFERROR(IF(P12-AC12<=10000000,VLOOKUP((P12-AC12)/1000,간이세액표,IF(11<Z12+AA12,13,2+Z12+AA12),TRUE),IF(P12-AC12>14000000,VLOOKUP((P12-AC12)/1000,간이세액표,IF(11<Z12+AA12,13,2+Z12+AA12),TRUE)+1372000+ROUNDDOWN(((P12-AC12-14000000)*98%)*38%,-1),VLOOKUP((P12-AC12)/1000,간이세액표,IF(11<Z12+AA12,13,2+Z12+AA12),TRUE)+ROUNDDOWN(((P12-AC12-10000000)*98%)*35%,-1))),) -> 25950 | R12: =ROUNDDOWN(Q12*10%,-1) -> 2590 | S12: =IFERROR(IF(AND(P12-AC12>=월액최저,P12-AC12<=월액최고),ROUNDDOWN((P12-AC12)*국민연금,-1),IF(P12-AC12>=월액최고,최고연금,IF(AND(P12-AC12<=월액최저,P12-AC12>=1),최저연금,))),) -> 99000 | T12: =IFERROR(ROUNDDOWN((P12-AC12)*3.43%,-1),) -> 75460 | U12: =ROUNDDOWN(T12*11.52%,-1) -> 8690 | V12: =IFERROR(IF(D12<>"대표이사",ROUNDDOWN((P12-AC12)*고용보험율,-1),0),) -> 17600 | W12: =SUM(Q12:V12) -> 229290 | X12: =P12-W12 -> 2270710 | Z12: 1 | AC12: =IF(N12>=100000,100000,N12)+IF(O12>=200000,200000,O12) -> 300000
B13: 5 | C13: =[1]직원인적급여카드!B6 -> 박인식 | D13: 부장 | E13: 2100000 | N13: 200000 | O13: 200000 | P13: =SUM(E13:O13) -> 2500000 | Q13: =IFERROR(IF(P13-AC13<=10000000,VLOOKUP((P13-AC13)/1000,간이세액표,IF(11<Z13+AA13,13,2+Z13+AA13),TRUE),IF(P13-AC13>14000000,VLOOKUP((P13-AC13)/1000,간이세액표,IF(11<Z13+AA13,13,2+Z13+AA13),TRUE)+1372000+ROUNDDOWN(((P13-AC13-14000000)*98%)*38%,-1),VLOOKUP((P13-AC13)/1000,간이세액표,IF(11<Z13+AA13,13,2+Z13+AA13),TRUE)+ROUNDDOWN(((P13-AC13-10000000)*98%)*35%,-1))),) -> 25950 | R13: =ROUNDDOWN(Q13*10%,-1) -> 2590 | T13: =IFERROR(ROUNDDOWN((P13-AC13)*3.43%,-1),) -> 75460 | U13: =ROUNDDOWN(T13*11.52%,-1) -> 8690 | V13: =IFERROR(IF(D13<>"대표이사",ROUNDDOWN((P13-AC13)*고용보험율,-1),0),) -> 17600 | W13: =SUM(Q13:V13) -> 130290 | X13: =P13-W13 -> 2369710 | Z13: 1 | AC13: =IF(N13>=100000,100000,N13)+IF(O13>=200000,200000,O13) -> 300000
B14: 6 | C14: =[1]직원인적급여카드!B7 -> 이은애 | D14: =[1]직원인적급여카드!C7 -> 부장 | E14: =[1]직원인적급여카드!M7 -> 2100000 | N14: 200000 | O14: 200000 | P14: =SUM(E14:O14) -> 2500000 | Q14: =IFERROR(IF(P14-AC14<=10000000,VLOOKUP((P14-AC14)/1000,간이세액표,IF(11<Z14+AA14,13,2+Z14+AA14),TRUE),IF(P14-AC14>14000000,VLOOKUP((P14-AC14)/1000,간이세액표,IF(11<Z14+AA14,13,2+Z14+AA14),TRUE)+1372000+ROUNDDOWN(((P14-AC14-14000000)*98%)*38%,-1),VLOOKUP((P14-AC14)/1000,간이세액표,IF(11<Z14+AA14,13,2+Z14+AA14),TRUE)+ROUNDDOWN(((P14-AC14-10000000)*98%)*35%,-1))),) -> 25950 | R14: =ROUNDDOWN(Q14*10%,-1) -> 2590 | S14: =IFERROR(IF(AND(P14-AC14>=월액최저,P14-AC14<=월액최고),ROUNDDOWN((P14-AC14)*국민연금,-1),IF(P14-AC14>=월액최고,최고연금,IF(AND(P14-AC14<=월액최저,P14-AC14>=1),최저연금,))),) -> 99000 | T14: =IFERROR(ROUNDDOWN((P14-AC14)*3.43%,-1),) -> 75460 | U14: =ROUNDDOWN(T14*11.52%,-1) -> 8690 | V14: =IFERROR(IF(D15<>"대표이사",ROUNDDOWN((P14-AC14)*고용보험율,-1),0),) -> 17600 | W14: =SUM(Q14:V14) -> 229290 | X14: =P14-W14 -> 2270710 | Z14: 1 | AC14: =IF(N15>=100000,100000,N15)+IF(O14>=200000,200000,O14) -> 300000
B15: 7 | C15: =[1]직원인적급여카드!B8 -> 이일복 | D15: 과장 | E15: =[1]직원인적급여카드!M8 -> 2100000 | N15: 200000 | O15: 200000 | P15: =SUM(E15:O15) -> 2500000 | Q15: =IFERROR(IF(P15-AC15<=10000000,VLOOKUP((P15-AC15)/1000,간이세액표,IF(11<Z15+AA15,13,2+Z15+AA15),TRUE),IF(P15-AC15>14000000,VLOOKUP((P15-AC15)/1000,간이세액표,IF(11<Z15+AA15,13,2+Z15+AA15),TRUE)+1372000+ROUNDDOWN(((P15-AC15-14000000)*98%)*38%,-1),VLOOKUP((P15-AC15)/1000,간이세액표,IF(11<Z15+AA15,13,2+Z15+AA15),TRUE)+ROUNDDOWN(((P15-AC15-10000000)*98%)*35%,-1))),) -> 25950 | R15: =ROUNDDOWN(Q15*10%,-1) -> 2590 | T15: =IFERROR(ROUNDDOWN((P15-AC15)*3.43%,-1),) -> 75460 | U15: =ROUNDDOWN(T15*11.52%,-1) -> 8690 | V15: =IFERROR(IF(D15<>"대표이사",ROUNDDOWN((P15-AC15)*고용보험율,-1),0),) -> 17600 | W15: =SUM(Q15:V15) -> 130290 | X15: =P15-W15 -> 2369710 | Z15: 1 | AC15: =IF(N15>=100000,100000,N15)+IF(O15>=200000,200000,O15) -> 300000
B16: 8 | C16: 유지안 | D16: 부장 | Q16: =IFERROR(IF(P16-AC16<=10000000,VLOOKUP((P16-AC16)/1000,간이세액표,IF(11<Z16+AA16,13,2+Z16+AA16),TRUE),IF(P16-AC16>14000000,VLOOKUP((P16-AC16)/1000,간이세액표,IF(11<Z16+AA16,13,2+Z16+AA16),TRUE)+1372000+ROUNDDOWN(((P16-AC16-14000000)*98%)*38%,-1),VLOOKUP((P16-AC16)/1000,간이세액표,IF(11<Z16+AA16,13,2+Z16+AA16),TRUE)+ROUNDDOWN(((P16-AC16-10000000)*98%)*35%,-1))),) -> 0 | R16: =ROUNDDOWN(Q16*10%,-1) -> 0 | S16: =IFERROR(IF(AND(P16-AC16>=월액최저,P16-AC16<=월액최고),ROUNDDOWN((P16-AC16)*국민연금,-1),IF(P16-AC16>=월액최고,최고연금,IF(AND(P16-AC16<=월액최저,P16-AC16>=1),최저연금,))),) -> 0 | T16: =IFERROR(ROUNDDOWN((P16-AC16)*건강보험율,-1),) -> 0 | U16: =ROUNDDOWN(T16*요양보험율,-1) -> 0 | V16: =IFERROR(IF(D16<>"대표이사",ROUNDDOWN((P16-AC16)*고용보험율,-1),0),) -> 0 | W16: =SUM(Q16:V16) -> 0 | X16: =P16-W16 -> 0 | AC16: =IF(N16>=100000,100000,N16)+IF(O16>=200000,200000,O16) -> 0
B17: 9 | C17: 조태현 | D17: 과장 | E17: 2100000 | N17: 200000 | O17: 200000 | P17: =SUM(E17:O17) -> 2500000 | Q17: =IFERROR(IF(P17-AC17<=10000000,VLOOKUP((P17-AC17)/1000,간이세액표,IF(11<Z17+AA17,13,2+Z17+AA17),TRUE),IF(P17-AC17>14000000,VLOOKUP((P17-AC17)/1000,간이세액표,IF(11<Z17+AA17,13,2+Z17+AA17),TRUE)+1372000+ROUNDDOWN(((P17-AC17-14000000)*98%)*38%,-1),VLOOKUP((P17-AC17)/1000,간이세액표,IF(11<Z17+AA17,13,2+Z17+AA17),TRUE)+ROUNDDOWN(((P17-AC17-10000000)*98%)*35%,-1))),) -> 25950 | R17: =ROUNDDOWN(Q17*10%,-1) -> 2590 | S17: =IFERROR(IF(AND(P17-AC17>=월액최저,P17-AC17<=월액최고),ROUNDDOWN((P17-AC17)*국민연금,-1),IF(P17-AC17>=월액최고,최고연금,IF(AND(P17-AC17<=월액최저,P17-AC17>=1),최저연금,))),) -> 99000 | T17: =IFERROR(ROUNDDOWN((P17-AC17)*3.43%,-1),) -> 75460 | U17: =ROUNDDOWN(T17*11.52%,-1) -> 8690 | V17: =IFERROR(IF(D17<>"대표이사",ROUNDDOWN((P17-AC17)*고용보험율,-1),0),) -> 17600 | W17: =SUM(Q17:V17) -> 229290 | X17: =P17-W17 -> 2270710 | Z17: 1 | AC17: =IF(N17>=100000,100000,N17)+IF(O17>=200000,200000,O17) -> 300000
B18: 10 | C18: 홍혜경 | D18: 대리 | E18: 2100000 | N18: 200000 | O18: 200000 | P18: =SUM(E18:O18) -> 2500000 | Q18: =IFERROR(IF(P18-AC18<=10000000,VLOOKUP((P18-AC18)/1000,간이세액표,IF(11<Z18+AA18,13,2+Z18+AA18),TRUE),IF(P18-AC18>14000000,VLOOKUP((P18-AC18)/1000,간이세액표,IF(11<Z18+AA18,13,2+Z18+AA18),TRUE)+1372000+ROUNDDOWN(((P18-AC18-14000000)*98%)*38%,-1),VLOOKUP((P18-AC18)/1000,간이세액표,IF(11<Z18+AA18,13,2+Z18+AA18),TRUE)+ROUNDDOWN(((P18-AC18-10000000)*98%)*35%,-1))),) -> 25950 | R18: =ROUNDDOWN(Q18*10%,-1) -> 2590 | S18: =IFERROR(IF(AND(P18-AC18>=월액최저,P18-AC18<=월액최고),ROUNDDOWN((P18-AC18)*국민연금,-1),IF(P18-AC18>=월액최고,최고연금,IF(AND(P18-AC18<=월액최저,P18-AC18>=1),최저연금,))),) -> 99000 | T18: =IFERROR(ROUNDDOWN((P18-AC18)*3.43%,-1),) -> 75460 | U18: =ROUNDDOWN(T18*11.52%,-1) -> 8690 | V18: =IFERROR(IF(D18<>"대표이사",ROUNDDOWN((P18-AC18)*고용보험율,-1),0),) -> 17600 | W18: =SUM(Q18:V18) -> 229290 | X18: =P18-W18 -> 2270710 | Z18: 1 | AC18: =IF(N18>=100000,100000,N18)+IF(O18>=200000,200000,O18) -> 300000
B19: 11 | C19: 박봉환 | D19: 과장 | E19: 2100000 | N19: 200000 | O19: 200000 | P19: =SUM(E19:O19) -> 2500000 | Q19: =IFERROR(IF(P19-AC19<=10000000,VLOOKUP((P19-AC19)/1000,간이세액표,IF(11<Z19+AA19,13,2+Z19+AA19),TRUE),IF(P19-AC19>14000000,VLOOKUP((P19-AC19)/1000,간이세액표,IF(11<Z19+AA19,13,2+Z19+AA19),TRUE)+1372000+ROUNDDOWN(((P19-AC19-14000000)*98%)*38%,-1),VLOOKUP((P19-AC19)/1000,간이세액표,IF(11<Z19+AA19,13,2+Z19+AA19),TRUE)+ROUNDDOWN(((P19-AC19-10000000)*98%)*35%,-1))),) -> 25950 | R19: =ROUNDDOWN(Q19*10%,-1) -> 2590 | T19: =IFERROR(ROUNDDOWN((P19-AC19)*3.43%,-1),) -> 75460 | U19: =ROUNDDOWN(T19*11.52%,-1) -> 8690 | V19: =IFERROR(IF(D19<>"대표이사",ROUNDDOWN((P19-AC19)*고용보험율,-1),0),) -> 17600 | W19: =SUM(Q19:V19) -> 130290 | X19: =P19-W19 -> 2369710 | Z19: 1 | AC19: =IF(N19>=100000,100000,N19)+IF(O19>=200000,200000,O19) -> 300000
B20: 12 | P20: =SUM(E20:O20) -> 0 | Q20: =IFERROR(IF(P20-AC20<=10000000,VLOOKUP((P20-AC20)/1000,간이세액표,IF(11<Z20+AA20,13,2+Z20+AA20),TRUE),IF(P20-AC20>14000000,VLOOKUP((P20-AC20)/1000,간이세액표,IF(11<Z20+AA20,13,2+Z20+AA20),TRUE)+1372000+ROUNDDOWN(((P20-AC20-14000000)*98%)*38%,-1),VLOOKUP((P20-AC20)/1000,간이세액표,IF(11<Z20+AA20,13,2+Z20+AA20),TRUE)+ROUNDDOWN(((P20-AC20-10000000)*98%)*35%,-1))),) -> 0 | R20: =ROUNDDOWN(Q20*10%,-1) -> 0 | S20: =IFERROR(IF(AND(P20-AC20>=월액최저,P20-AC20<=월액최고),ROUNDDOWN((P20-AC20)*국민연금,-1),IF(P20-AC20>=월액최고,최고연금,IF(AND(P20-AC20<=월액최저,P20-AC20>=1),최저연금,))),) -> 0 | T20: =IFERROR(ROUNDDOWN((P20-AC20)*건강보험율,-1),) -> 0 | U20: =ROUNDDOWN(T20*요양보험율,-1) -> 0 | V20: =IFERROR(IF(D20<>"대표이사",ROUNDDOWN((P20-AC20)*고용보험율,-1),0),) -> 0 | W20: =SUM(Q20:V20) -> 0 | X20: =P20-W20 -> 0 | Z20: 1 | AC20: =IF(N20>=100000,100000,N20)+IF(O20>=200000,200000,O20) -> 0
B21: 합계 | E21: =SUM(E9:E20) -> 21000000 | F21: =SUM(F9:F20) -> 0 | G21: =SUM(G9:G20) -> 0 | H21: =SUM(H9:H20) -> 0 | I21: =SUM(I9:I20) -> 0 | J21: =SUM(J9:J20) -> 0 | K21: =SUM(K9:K20) -> 0 | L21: =SUM(L9:L20) -> 0 | ... X21: =SUM(X9:X20) -> 23004100
B22: *참고 : 대표자는 직책에 "대표이사"라고 입력해야만 고용보험 "0"으로 처리됨 / 부양가족수본인포함에 1인이상넣어야 소득세계산됨
C23: 이름 | D23: 주민등록번호 | F23: 입,퇴사일자 | H23: 주 소
B24: 입사자
B27: 퇴사자

Sheet 4월
B3: 건우건설주식회사 | L3: 2024년 ( 04 )월 급여대장
B5: 지급일자 : 2024년 04월 30일
B7: NO | C7: 성명 | D7: 직책 | E7: 지 급 내 역(과세) | N7: 지급내역(비과세) | P7: 지급액 | Q7: 공 제 내 역 | W7: 공제계 | X7: 지급총액 | Z7: 부양가족수 본인포함 | AA7: 20세이하 자녀수 | AC7: 비과세 합계액
E8: 기본급 | F8: 월차수당 | G8: 직책수당 | H8: 야근수당 | I8: 근속수당 | J8: 현장수당 | K8: 기술수당 | L8: 년차수당 | M8: 상여금 | N8: 식비 | O8: 차량유지비 | Q8: 소득세 | R8: 지방 소득세 | S8: 국민연금 | T8: 건강보험 | U8: 장기요양보험 | V8: 고용보험
B9: 1 | C9: =[1]직원인적급여카드!B2 -> 안경이 | D9: =[1]직원인적급여카드!C2 -> 대표 | E9: 2100000 | N9: 200000 | O9: 200000 | P9: =SUM(E9:O9) -> 2500000 | Q9: =IFERROR(IF(P9-AC9<=10000000,VLOOKUP((P9-AC9)/1000,간이세액표,IF(11<Z9+AA9,13,2+Z9+AA9),TRUE),IF(P9-AC9>14000000,VLOOKUP((P9-AC9)/1000,간이세액표,IF(11<Z9+AA9,13,2+Z9+AA9),TRUE)+1372000+ROUNDDOWN(((P9-AC9-14000000)*98%)*38%,-1),VLOOKUP((P9-AC9)/1000,간이세액표,IF(11<Z9+AA9,13,2+Z9+AA9),TRUE)+ROUNDDOWN(((P9-AC9-10000000)*98%)*35%,-1))),) -> 25950 | R9: =ROUNDDOWN(Q9*10%,-1) -> 2590 | S9: =IFERROR(IF(AND(P9-AC9>=월액최저,P9-AC9<=월액최고),ROUNDDOWN((P9-AC9)*국민연금,-1),IF(P9-AC9>=월액최고,최고연금,IF(AND(P9-AC9<=월액최저,P9-AC9>=1),최저연금,))),) -> 99000 | T9: =IFERROR(ROUNDDOWN((P9-AC9)*3.43%,-1),) -> 75460 | U9: =ROUNDDOWN(T9*11.52%,-1) -> 8690 | V9: =IFERROR(IF(D9<>"대표이사",ROUNDDOWN((P9-AC9)*고용보험율,-1),0),) -> 17600 | W9: =SUM(Q9:V9) -> 229290 | X9: =P9-W9 -> 2270710 | Z9: 1 | AC9: =IF(N9>=100000,100000,N9)+IF(O9>=200000,200000,O9) -> 300000
B10: 2 | C10: =[1]직원인적급여카드!B3 -> 김성헌 | D10: =[1]직원인적급여카드!C3 -> 부장 | E10: =[1]직원인적급여카드!M3 -> 2100000 | N10: 200000 | O10: 200000 | P10: =SUM(E10:O10) -> 2500000 | Q10: =IFERROR(IF(P10-AC10<=10000000,VLOOKUP((P10-AC10)/1000,간이세액표,IF(11<Z10+AA10,13,2+Z10+AA10),TRUE),IF(P10-AC10>14000000,VLOOKUP((P10-AC10)/1000,간이세액표,IF(11<Z10+AA10,13,2+Z10+AA10),TRUE)+1372000+ROUNDDOWN(((P10-AC10-14000000)*98%)*38%,-1),VLOOKUP((P10-AC10)/1000,간이세액표,IF(11<Z10+AA10,13,2+Z10+AA10),TRUE)+ROUNDDOWN(((P10-AC10-10000000)*98%)*35%,-1))),) -> 25950 | R10: =ROUNDDOWN(Q10*10%,-1) -> 2590 | S10: =IFERROR(IF(AND(P10-AC10>=월액최저,P10-AC10<=월액최고),ROUNDDOWN((P10-AC10)*국민연금,-1),IF(P10-AC10>=월액최고,최고연금,IF(AND(P10-AC10<=월액최저,P10-AC10>=1),최저연금,))),) -> 99000 | T10: =IFERROR(ROUNDDOWN((P10-AC10)*3.43%,-1),) -> 75460 | U10: =ROUNDDOWN(T10*11.52%,-1) -> 8690 | V10: =IFERROR(IF(D10<>"대표이사",ROUNDDOWN((P10-AC10)*고용보험율,-1),0),) -> 17600 | W10: =SUM(Q10:V10) -> 229290 | X10: =P10-W10 -> 2270710 | Z10: 1 | AC10: =IF(N10>=100000,100000,N10)+IF(O10>=200000,200000,O10) -> 300000
B11: 3 | C11: =[1]직원인적급여카드!B4 -> 최종식 | D11: =[1]직원인적급여카드!C4 -> 부장 | E11: =[1]직원인적급여카드!M4 -> 2100000 | N11: 200000 | O11: 200000 | P11: =SUM(E11:O11) -> 2500000 | Q11: =IFERROR(IF(P11-AC11<=10000000,VLOOKUP((P11-AC11)/1000,간이세액표,IF(11<Z11+AA11,13,2+Z11+AA11),TRUE),IF(P11-AC11>14000000,VLOOKUP((P11-AC11)/1000,간이세액표,IF(11<Z11+AA11,13,2+Z11+AA11),TRUE)+1372000+ROUNDDOWN(((P11-AC11-14000000)*98%)*38%,-1),VLOOKUP((P11-AC11)/1000,간이세액표,IF(11<Z11+AA11,13,2+Z11+AA11),TRUE)+ROUNDDOWN(((P11-AC11-10000000)*98%)*35%,-1))),) -> 25950 | R11: =ROUNDDOWN(Q11*10%,-1) -> 2590 | S11: =IFERROR(IF(AND(P11-AC11>=월액최저,P11-AC11<=월액최고),ROUNDDOWN((P11-AC11)*국민연금,-1),IF(P11-AC11>=월액최고,최고연금,IF(AND(P11-AC11<=월액최저,P11-AC11>=1),최저연금,))),) -> 99000 | T11: =IFERROR(ROUNDDOWN((P11-AC11)*3.43%,-1),) -> 75460 | U11: =ROUNDDOWN(T11*11.52%,-1) -> 8690 | V11: =IFERROR(IF(D11<>"대표이사",ROUNDDOWN((P11-AC11)*고용보험율,-1),0),) -> 17600 | W11: =SUM(Q11:V11) -> 229290 | X11: =P11-W11 -> 2270710 | Z11: 1 | AC11: =IF(N11>=100000,100000,N11)+IF(O11>=200000,200000,O11) -> 300000
B12: 4 | C12: =[1]직원인적급여카드!B5 -> 김태현 | D12: =[1]직원인적급여카드!C5 -> 과장 | E12: =[1]직원인적급여카드!M5 -> 2100000 | N12: 200000 | O12: 200000 | P12: =SUM(E12:O12) -> 2500000 | Q12: =IFERROR(IF(P12-AC12<=10000000,VLOOKUP((P12-AC12)/1000,간이세액표,IF(11<Z12+AA12,13,2+Z12+AA12),TRUE),IF(P12-AC12>14000000,VLOOKUP((P12-AC12)/1000,간이세액표,IF(11<Z12+AA12,13,2+Z12+AA12),TRUE)+1372000+ROUNDDOWN(((P12-AC12-14000000)*98%)*38%,-1),VLOOKUP((P12-AC12)/1000,간이세액표,IF(11<Z12+AA12,13,2+Z12+AA12),TRUE)+ROUNDDOWN(((P12-AC12-10000000)*98%)*35%,-1))),) -> 25950 | R12: =ROUNDDOWN(Q12*10%,-1) -> 2590 | S12: =IFERROR(IF(AND(P12-AC12>=월액최저,P12-AC12<=월액최고),ROUNDDOWN((P12-AC12)*국민연금,-1),IF(P12-AC12>=월액최고,최고연금,IF(AND(P12-AC12<=월액최저,P12-AC12>=1),최저연금,))),) -> 99000 | T12: =IFERROR(ROUNDDOWN((P12-AC12)*3.43%,-1),) -> 75460 | U12: =ROUNDDOWN(T12*11.52%,-1) -> 8690 | V12: =IFERROR(IF(D12<>"대표이사",ROUNDDOWN((P12-AC12)*고용보험율,-1),0),) -> 17600 | W12: =SUM(Q12:V12) -> 229290 | X12: =P12-W12 -> 2270710 | Z12: 1 | AC12: =IF(N12>=100000,100000,N12)+IF(O12>=200000,200000,O12) -> 300000
B13: 5 | C13: =[1]직원인적급여카드!B6 -> 박인식 | D13: 부장 | E13: 2100000 | N13: 200000 | O13: 200000 | P13: =SUM(E13:O13) -> 2500000 | Q13: =IFERROR(IF(P13-AC13<=10000000,VLOOKUP((P13-AC13)/1000,간이세액표,IF(11<Z13+AA13,13,2+Z13+AA13),TRUE),IF(P13-AC13>14000000,VLOOKUP((P13-AC13)/1000,간이세액표,IF(11<Z13+AA13,13,2+Z13+AA13),TRUE)+1372000+ROUNDDOWN(((P13-AC13-14000000)*98%)*38%,-1),VLOOKUP((P13-AC13)/1000,간이세액표,IF(11<Z13+AA13,13,2+Z13+AA13),TRUE)+ROUNDDOWN(((P13-AC13-10000000)*98%)*35%,-1))),) -> 25950 | R13: =ROUNDDOWN(Q13*10%,-1) -> 2590 | T13: =IFERROR(ROUNDDOWN((P13-AC13)*3.43%,-1),) -> 75460 | U13: =ROUNDDOWN(T13*11.52%,-1) -> 8690 | V13: =IFERROR(IF(D13<>"대표이사",ROUNDDOWN((P13-AC13)*고용보험율,-1),0),) -> 17600 | W13: =SUM(Q13:V13) -> 130290 | X13: =P13-W13 -> 2369710 | Z13: 1 | AC13: =IF(N13>=100000,100000,N13)+IF(O13>=200000,200000,O13) -> 300000
B14: 6 | C14: =[1]직원인적급여카드!B7 -> 이은애 | D14: =[1]직원인적급여카드!C7 -> 부장 | E14: =[1]직원인적급여카드!M7 -> 2100000 | N14: 200000 | O14: 200000 | P14: =SUM(E14:O14) -> 2500000 | Q14: =IFERROR(IF(P14-AC14<=10000000,VLOOKUP((P14-AC14)/1000,간이세액표,IF(11<Z14+AA14,13,2+Z14+AA14),TRUE),IF(P14-AC14>14000000,VLOOKUP((P14-AC14)/1000,간이세액표,IF(11<Z14+AA14,13,2+Z14+AA14),TRUE)+1372000+ROUNDDOWN(((P14-AC14-14000000)*98%)*38%,-1),VLOOKUP((P14-AC14)/1000,간이세액표,IF(11<Z14+AA14,13,2+Z14+AA14),TRUE)+ROUNDDOWN(((P14-AC14-10000000)*98%)*35%,-1))),) -> 25950 | R14: =ROUNDDOWN(Q14*10%,-1) -> 2590 | S14: =IFERROR(IF(AND(P14-AC14>=월액최저,P14-AC14<=월액최고),ROUNDDOWN((P14-AC14)*국민연금,-1),IF(P14-AC14>=월액최고,최고연금,IF(AND(P14-AC14<=월액최저,P14-AC14>=1),최저연금,))),) -> 99000 | T14: =IFERROR(ROUNDDOWN((P14-AC14)*3.43%,-1),) -> 75460 | U14: =ROUNDDOWN(T14*11.52%,-1) -> 8690 | V14: =IFERROR(IF(D15<>"대표이사",ROUNDDOWN((P14-AC14)*고용보험율,-1),0),) -> 17600 | W14: =SUM(Q14:V14) -> 229290 | X14: =P14-W14 -> 2270710 | Z14: 1 | AC14: =IF(N15>=100000,100000,N15)+IF(O14>=200000,200000,O14) -> 300000
B15: 7 | C15: =[1]직원인적급여카드!B8 -> 이일복 | D15: 과장 | E15: =[1]직원인적급여카드!M8 -> 2100000 | N15: 200000 | O15: 200000 | P15: =SUM(E15:O15) -> 2500000 | Q15: =IFERROR(IF(P15-AC15<=10000000,VLOOKUP((P15-AC15)/1000,간이세액표,IF(11<Z15+AA15,13,2+Z15+AA15),TRUE),IF(P15-AC15>14000000,VLOOKUP((P15-AC15)/1000,간이세액표,IF(11<Z15+AA15,13,2+Z15+AA15),TRUE)+1372000+ROUNDDOWN(((P15-AC15-14000000)*98%)*38%,-1),VLOOKUP((P15-AC15)/1000,간이세액표,IF(11<Z15+AA15,13,2+Z15+AA15),TRUE)+ROUNDDOWN(((P15-AC15-10000000)*98%)*35%,-1))),) -> 25950 | R15: =ROUNDDOWN(Q15*10%,-1) -> 2590 | T15: =IFERROR(ROUNDDOWN((P15-AC15)*3.43%,-1),) -> 75460 | U15: =ROUNDDOWN(T15*11.52%,-1) -> 8690 | V15: =IFERROR(IF(D15<>"대표이사",ROUNDDOWN((P15-AC15)*고용보험율,-1),0),) -> 17600 | W15: =SUM(Q15:V15) -> 130290 | X15: =P15-W15 -> 2369710 | Z15: 1 | AC15: =IF(N15>=100000,100000,N15)+IF(O15>=200000,200000,O15) -> 300000
C16: 유지안 | D16: 부장 | Q16: =IFERROR(IF(P16-AC16<=10000000,VLOOKUP((P16-AC16)/1000,간이세액표,IF(11<Z16+AA16,13,2+Z16+AA16),TRUE),IF(P16-AC16>14000000,VLOOKUP((P16-AC16)/1000,간이세액표,IF(11<Z16+AA16,13,2+Z16+AA16),TRUE)+1372000+ROUNDDOWN(((P16-AC16-14000000)*98%)*38%,-1),VLOOKUP((P16-AC16)/1000,간이세액표,IF(11<Z16+AA16,13,2+Z16+AA16),TRUE)+ROUNDDOWN(((P16-AC16-10000000)*98%)*35%,-1))),) -> 0 | R16: =ROUNDDOWN(Q16*10%,-1) -> 0 | S16: =IFERROR(IF(AND(P16-AC16>=월액최저,P16-AC16<=월액최고),ROUNDDOWN((P16-AC16)*국민연금,-1),IF(P16-AC16>=월액최고,최고연금,IF(AND(P16-AC16<=월액최저,P16-AC16>=1),최저연금,))),) -> 0 | T16: =IFERROR(ROUNDDOWN((P16-AC16)*건강보험율,-1),) -> 0 | U16: =ROUNDDOWN(T16*요양보험율,-1) -> 0 | V16: =IFERROR(IF(D16<>"대표이사",ROUNDDOWN((P16-AC16)*고용보험율,-1),0),) -> 0 | W16: =SUM(Q16:V16) -> 0 | X16: =P16-W16 -> 0 | AC16: =IF(N16>=100000,100000,N16)+IF(O16>=200000,200000,O16) -> 0
B17: 8 | C17: 조태현 | D17: 과장 | E17: 2100000 | N17: 200000 | O17: 200000 | P17: =SUM(E17:O17) -> 2500000 | Q17: =IFERROR(IF(P17-AC17<=10000000,VLOOKUP((P17-AC17)/1000,간이세액표,IF(11<Z17+AA17,13,2+Z17+AA17),TRUE),IF(P17-AC17>14000000,VLOOKUP((P17-AC17)/1000,간이세액표,IF(11<Z17+AA17,13,2+Z17+AA17),TRUE)+1372000+ROUNDDOWN(((P17-AC17-14000000)*98%)*38%,-1),VLOOKUP((P17-AC17)/1000,간이세액표,IF(11<Z17+AA17,13,2+Z17+AA17),TRUE)+ROUNDDOWN(((P17-AC17-10000000)*98%)*35%,-1))),) -> 25950 | R17: =ROUNDDOWN(Q17*10%,-1) -> 2590 | S17: =IFERROR(IF(AND(P17-AC17>=월액최저,P17-AC17<=월액최고),ROUNDDOWN((P17-AC17)*국민연금,-1),IF(P17-AC17>=월액최고,최고연금,IF(AND(P17-AC17<=월액최저,P17-AC17>=1),최저연금,))),) -> 99000 | T17: =IFERROR(ROUNDDOWN((P17-AC17)*3.43%,-1),) -> 75460 | U17: =ROUNDDOWN(T17*11.52%,-1) -> 8690 | V17: =IFERROR(IF(D17<>"대표이사",ROUNDDOWN((P17-AC17)*고용보험율,-1),0),) -> 17600 | W17: =SUM(Q17:V17) -> 229290 | X17: =P17-W17 -> 2270710 | Z17: 1 | AC17: =IF(N17>=100000,100000,N17)+IF(O17>=200000,200000,O17) -> 300000
B18: 9 | C18: 홍혜경 | D18: 대리 | E18: 2100000 | N18: 200000 | O18: 200000 | P18: =SUM(E18:O18) -> 2500000 | Q18: =IFERROR(IF(P18-AC18<=10000000,VLOOKUP((P18-AC18)/1000,간이세액표,IF(11<Z18+AA18,13,2+Z18+AA18),TRUE),IF(P18-AC18>14000000,VLOOKUP((P18-AC18)/1000,간이세액표,IF(11<Z18+AA18,13,2+Z18+AA18),TRUE)+1372000+ROUNDDOWN(((P18-AC18-14000000)*98%)*38%,-1),VLOOKUP((P18-AC18)/1000,간이세액표,IF(11<Z18+AA18,13,2+Z18+AA18),TRUE)+ROUNDDOWN(((P18-AC18-10000000)*98%)*35%,-1))),) -> 25950 | R18: =ROUNDDOWN(Q18*10%,-1) -> 2590 | S18: =IFERROR(IF(AND(P18-AC18>=월액최저,P18-AC18<=월액최고),ROUNDDOWN((P18-AC18)*국민연금,-1),IF(P18-AC18>=월액최고,최고연금,IF(AND(P18-AC18<=월액최저,P18-AC18>=1),최저연금,))),) -> 99000 | T18: =IFERROR(ROUNDDOWN((P18-AC18)*3.43%,-1),) -> 75460 | U18: =ROUNDDOWN(T18*11.52%,-1) -> 8690 | V18: =IFERROR(IF(D18<>"대표이사",ROUNDDOWN((P18-AC18)*고용보험율,-1),0),) -> 17600 | W18: =SUM(Q18:V18) -> 229290 | X18: =P18-W18 -> 2270710 | Z18: 1 | AC18: =IF(N18>=100000,100000,N18)+IF(O18>=200000,200000,O18) -> 300000
B19: 10 | C19: 박봉환 | D19: 과장 | E19: 2100000 | N19: 200000 | O19: 200000 | P19: =SUM(E19:O19) -> 2500000 | Q19: =IFERROR(IF(P19-AC19<=10000000,VLOOKUP((P19-AC19)/1000,간이세액표,IF(11<Z19+AA19,13,2+Z19+AA19),TRUE),IF(P19-AC19>14000000,VLOOKUP((P19-AC19)/1000,간이세액표,IF(11<Z19+AA19,13,2+Z19+AA19),TRUE)+1372000+ROUNDDOWN(((P19-AC19-14000000)*98%)*38%,-1),VLOOKUP((P19-AC19)/1000,간이세액표,IF(11<Z19+AA19,13,2+Z19+AA19),TRUE)+ROUNDDOWN(((P19-AC19-10000000)*98%)*35%,-1))),) -> 25950 | R19: =ROUNDDOWN(Q19*10%,-1) -> 2590 | T19: =IFERROR(ROUNDDOWN((P19-AC19)*3.43%,-1),) -> 75460 | U19: =ROUNDDOWN(T19*11.52%,-1) -> 8690 | V19: =IFERROR(IF(D19<>"대표이사",ROUNDDOWN((P19-AC19)*고용보험율,-1),0),) -> 17600 | W19: =SUM(Q19:V19) -> 130290 | X19: =P19-W19 -> 2369710 | Z19: 1 | AC19: =IF(N19>=100000,100000,N19)+IF(O19>=200000,200000,O19) -> 300000
B20: 11 | C20: 김지헌 | D20: 과장 | E20: 2100000 | N20: 200000 | O20: 200000 | P20: =SUM(E20:O20) -> 2500000 | Q20: =IFERROR(IF(P20-AC20<=10000000,VLOOKUP((P20-AC20)/1000,간이세액표,IF(11<Z20+AA20,13,2+Z20+AA20),TRUE),IF(P20-AC20>14000000,VLOOKUP((P20-AC20)/1000,간이세액표,IF(11<Z20+AA20,13,2+Z20+AA20),TRUE)+1372000+ROUNDDOWN(((P20-AC20-14000000)*98%)*38%,-1),VLOOKUP((P20-AC20)/1000,간이세액표,IF(11<Z20+AA20,13,2+Z20+AA20),TRUE)+ROUNDDOWN(((P20-AC20-10000000)*98%)*35%,-1))),) -> 25950 | R20: =ROUNDDOWN(Q20*10%,-1) -> 2590 | S20: =IFERROR(IF(AND(P20-AC20>=월액최저,P20-AC20<=월액최고),ROUNDDOWN((P20-AC20)*국민연금,-1),IF(P20-AC20>=월액최고,최고연금,IF(AND(P20-AC20<=월액최저,P20-AC20>=1),최저연금,))),) -> 99000 | T20: =IFERROR(ROUNDDOWN((P20-AC20)*3.43%,-1),) -> 75460 | U20: =ROUNDDOWN(T20*11.52%,-1) -> 8690 | V20: =IFERROR(IF(D20<>"대표이사",ROUNDDOWN((P20-AC20)*고용보험율,-1),0),) -> 17600 | W20: =SUM(Q20:V20) -> 229290 | X20: =P20-W20 -> 2270710 | Z20: 1 | AC20: =IF(N20>=100000,100000,N20)+IF(O20>=200000,200000,O20) -> 300000
B21: 합계 | E21: =SUM(E9:E20) -> 23100000 | F21: =SUM(F9:F20) -> 0 | G21: =SUM(G9:G20) -> 0 | H21: =SUM(H9:H20) -> 0 | I21: =SUM(I9:I20) -> 0 | J21: =SUM(J9:J20) -> 0 | K21: =SUM(K9:K20) -> 0 | L21: =SUM(L9:L20) -> 0 | ... X21: =SUM(X9:X20) -> 25274810
B22: *참고 : 대표자는 직책에 "대표이사"라고 입력해야만 고용보험 "0"으로 처리됨 / 부양가족수본인포함에 1인이상넣어야 소득세계산됨
C23: 이름 | D23: 주민등록번호 | F23: 입,퇴사일자 | H23: 주 소
B24: 입사자 | C24: 김지헌 | D24: 760607-1386119 | F24: 24.04.01
B27: 퇴사자

Sheet 5월
B3: 건우건설주식회사 | L3: 2024년 ( 05 )월 급여대장
B5: 지급일자 : 2024년 05월 31일
B7: NO | C7: 성명 | D7: 직책 | E7: 지 급 내 역(과세) | N7: 지급내역(비과세) | P7: 지급액 | Q7: 공 제 내 역 | W7: 공제계 | X7: 지급총액 | Z7: 부양가족수 본인포함 | AA7: 20세이하 자녀수 | AC7: 비과세 합계액
E8: 기본급 | F8: 월차수당 | G8: 직책수당 | H8: 야근수당 | I8: 근속수당 | J8: 현장수당 | K8: 기술수당 | L8: 년차수당 | M8: 상여금 | N8: 식비 | O8: 차량유지비 | Q8: 소득세 | R8: 지방 소득세 | S8: 국민연금 | T8: 건강보험 | U8: 장기요양보험 | V8: 고용보험
B9: 1 | C9: =[1]직원인적급여카드!B2 -> 안경이 | D9: =[1]직원인적급여카드!C2 -> 대표 | E9: 2100000 | N9: 200000 | O9: 200000 | P9: =SUM(E9:O9) -> 2500000 | Q9: =IFERROR(IF(P9-AC9<=10000000,VLOOKUP((P9-AC9)/1000,간이세액표,IF(11<Z9+AA9,13,2+Z9+AA9),TRUE),IF(P9-AC9>14000000,VLOOKUP((P9-AC9)/1000,간이세액표,IF(11<Z9+AA9,13,2+Z9+AA9),TRUE)+1372000+ROUNDDOWN(((P9-AC9-14000000)*98%)*38%,-1),VLOOKUP((P9-AC9)/1000,간이세액표,IF(11<Z9+AA9,13,2+Z9+AA9),TRUE)+ROUNDDOWN(((P9-AC9-10000000)*98%)*35%,-1))),) -> 25950 | R9: =ROUNDDOWN(Q9*10%,-1) -> 2590 | S9: =IFERROR(IF(AND(P9-AC9>=월액최저,P9-AC9<=월액최고),ROUNDDOWN((P9-AC9)*국민연금,-1),IF(P9-AC9>=월액최고,최고연금,IF(AND(P9-AC9<=월액최저,P9-AC9>=1),최저연금,))),) -> 99000 | T9: =IFERROR(ROUNDDOWN((P9-AC9)*3.43%,-1),) -> 75460 | U9: =ROUNDDOWN(T9*11.52%,-1) -> 8690 | V9: =IFERROR(IF(D9<>"대표이사",ROUNDDOWN((P9-AC9)*고용보험율,-1),0),) -> 17600 | W9: =SUM(Q9:V9) -> 229290 | X9: =P9-W9 -> 2270710 | Z9: 1 | AC9: =IF(N9>=100000,100000,N9)+IF(O9>=200000,200000,O9) -> 300000
B10: 2 | C10: =[1]직원인적급여카드!B3 -> 김성헌 | D10: =[1]직원인적급여카드!C3 -> 부장 | E10: =[1]직원인적급여카드!M3 -> 2100000 | N10: 200000 | O10: 200000 | P10: =SUM(E10:O10) -> 2500000 | Q10: =IFERROR(IF(P10-AC10<=10000000,VLOOKUP((P10-AC10)/1000,간이세액표,IF(11<Z10+AA10,13,2+Z10+AA10),TRUE),IF(P10-AC10>14000000,VLOOKUP((P10-AC10)/1000,간이세액표,IF(11<Z10+AA10,13,2+Z10+AA10),TRUE)+1372000+ROUNDDOWN(((P10-AC10-14000000)*98%)*38%,-1),VLOOKUP((P10-AC10)/1000,간이세액표,IF(11<Z10+AA10,13,2+Z10+AA10),TRUE)+ROUNDDOWN(((P10-AC10-10000000)*98%)*35%,-1))),) -> 25950 | R10: =ROUNDDOWN(Q10*10%,-1) -> 2590 | S10: =IFERROR(IF(AND(P10-AC10>=월액최저,P10-AC10<=월액최고),ROUNDDOWN((P10-AC10)*국민연금,-1),IF(P10-AC10>=월액최고,최고연금,IF(AND(P10-AC10<=월액최저,P10-AC10>=1),최저연금,))),) -> 99000 | T10: =IFERROR(ROUNDDOWN((P10-AC10)*3.43%,-1),) -> 75460 | U10: =ROUNDDOWN(T10*11.52%,-1) -> 8690 | V10: =IFERROR(IF(D10<>"대표이사",ROUNDDOWN((P10-AC10)*고용보험율,-1),0),) -> 17600 | W10: =SUM(Q10:V10) -> 229290 | X10: =P10-W10 -> 2270710 | Z10: 1 | AC10: =IF(N10>=100000,100000,N10)+IF(O10>=200000,200000,O10) -> 300000
B11: 3 | C11: =[1]직원인적급여카드!B4 -> 최종식 | D11: =[1]직원인적급여카드!C4 -> 부장 | E11: =[1]직원인적급여카드!M4 -> 2100000 | N11: 200000 | O11: 200000 | P11: =SUM(E11:O11) -> 2500000 | Q11: =IFERROR(IF(P11-AC11<=10000000,VLOOKUP((P11-AC11)/1000,간이세액표,IF(11<Z11+AA11,13,2+Z11+AA11),TRUE),IF(P11-AC11>14000000,VLOOKUP((P11-AC11)/1000,간이세액표,IF(11<Z11+AA11,13,2+Z11+AA11),TRUE)+1372000+ROUNDDOWN(((P11-AC11-14000000)*98%)*38%,-1),VLOOKUP((P11-AC11)/1000,간이세액표,IF(11<Z11+AA11,13,2+Z11+AA11),TRUE)+ROUNDDOWN(((P11-AC11-10000000)*98%)*35%,-1))),) -> 25950 | R11: =ROUNDDOWN(Q11*10%,-1) -> 2590 | S11: =IFERROR(IF(AND(P11-AC11>=월액최저,P11-AC11<=월액최고),ROUNDDOWN((P11-AC11)*국민연금,-1),IF(P11-AC11>=월액최고,최고연금,IF(AND(P11-AC11<=월액최저,P11-AC11>=1),최저연금,))),) -> 99000 | T11: =IFERROR(ROUNDDOWN((P11-AC11)*3.43%,-1),) -> 75460 | U11: =ROUNDDOWN(T11*11.52%,-1) -> 8690 | V11: =IFERROR(IF(D11<>"대표이사",ROUNDDOWN((P11-AC11)*고용보험율,-1),0),) -> 17600 | W11: =SUM(Q11:V11) -> 229290 | X11: =P11-W11 -> 2270710 | Z11: 1 | AC11: =IF(N11>=100000,100000,N11)+IF(O11>=200000,200000,O11) -> 300000
B12: 4 | C12: =[1]직원인적급여카드!B5 -> 김태현 | D12: =[1]직원인적급여카드!C5 -> 과장 | E12: =[1]직원인적급여카드!M5 -> 2100000 | N12: 200000 | O12: 200000 | P12: =SUM(E12:O12) -> 2500000 | Q12: =IFERROR(IF(P12-AC12<=10000000,VLOOKUP((P12-AC12)/1000,간이세액표,IF(11<Z12+AA12,13,2+Z12+AA12),TRUE),IF(P12-AC12>14000000,VLOOKUP((P12-AC12)/1000,간이세액표,IF(11<Z12+AA12,13,2+Z12+AA12),TRUE)+1372000+ROUNDDOWN(((P12-AC12-14000000)*98%)*38%,-1),VLOOKUP((P12-AC12)/1000,간이세액표,IF(11<Z12+AA12,13,2+Z12+AA12),TRUE)+ROUNDDOWN(((P12-AC12-10000000)*98%)*35%,-1))),) -> 25950 | R12: =ROUNDDOWN(Q12*10%,-1) -> 2590 | S12: =IFERROR(IF(AND(P12-AC12>=월액최저,P12-AC12<=월액최고),ROUNDDOWN((P12-AC12)*국민연금,-1),IF(P12-AC12>=월액최고,최고연금,IF(AND(P12-AC12<=월액최저,P12-AC12>=1),최저연금,))),) -> 99000 | T12: =IFERROR(ROUNDDOWN((P12-AC12)*3.43%,-1),) -> 75460 | U12: =ROUNDDOWN(T12*11.52%,-1) -> 8690 | V12: =IFERROR(IF(D12<>"대표이사",ROUNDDOWN((P12-AC12)*고용보험율,-1),0),) -> 17600 | W12: =SUM(Q12:V12) -> 229290 | X12: =P12-W12 -> 2270710 | Z12: 1 | AC12: =IF(N12>=100000,100000,N12)+IF(O12>=200000,200000,O12) -> 300000
B13: 5 | C13: =[1]직원인적급여카드!B6 -> 박인식 | D13: 부장 | E13: 2100000 | N13: 200000 | O13: 200000 | P13: =SUM(E13:O13) -> 2500000 | Q13: =IFERROR(IF(P13-AC13<=10000000,VLOOKUP((P13-AC13)/1000,간이세액표,IF(11<Z13+AA13,13,2+Z13+AA13),TRUE),IF(P13-AC13>14000000,VLOOKUP((P13-AC13)/1000,간이세액표,IF(11<Z13+AA13,13,2+Z13+AA13),TRUE)+1372000+ROUNDDOWN(((P13-AC13-14000000)*98%)*38%,-1),VLOOKUP((P13-AC13)/1000,간이세액표,IF(11<Z13+AA13,13,2+Z13+AA13),TRUE)+ROUNDDOWN(((P13-AC13-10000000)*98%)*35%,-1))),) -> 25950 | R13: =ROUNDDOWN(Q13*10%,-1) -> 2590 | T13: =IFERROR(ROUNDDOWN((P13-AC13)*3.43%,-1),) -> 75460 | U13: =ROUNDDOWN(T13*11.52%,-1) -> 8690 | V13: =IFERROR(IF(D13<>"대표이사",ROUNDDOWN((P13-AC13)*고용보험율,-1),0),) -> 17600 | W13: =SUM(Q13:V13) -> 130290 | X13: =P13-W13 -> 2369710 | Z13: 1 | AC13: =IF(N13>=100000,100000,N13)+IF(O13>=200000,200000,O13) -> 300000
B14: 6 | C14: =[1]직원인적급여카드!B7 -> 이은애 | D14: =[1]직원인적급여카드!C7 -> 부장 | E14: =[1]직원인적급여카드!M7 -> 2100000 | N14: 200000 | O14: 200000 | P14: =SUM(E14:O14) -> 2500000 | Q14: =IFERROR(IF(P14-AC14<=10000000,VLOOKUP((P14-AC14)/1000,간이세액표,IF(11<Z14+AA14,13,2+Z14+AA14),TRUE),IF(P14-AC14>14000000,VLOOKUP((P14-AC14)/1000,간이세액표,IF(11<Z14+AA14,13,2+Z14+AA14),TRUE)+1372000+ROUNDDOWN(((P14-AC14-14000000)*98%)*38%,-1),VLOOKUP((P14-AC14)/1000,간이세액표,IF(11<Z14+AA14,13,2+Z14+AA14),TRUE)+ROUNDDOWN(((P14-AC14-10000000)*98%)*35%,-1))),) -> 25950 | R14: =ROUNDDOWN(Q14*10%,-1) -> 2590 | S14: =IFERROR(IF(AND(P14-AC14>=월액최저,P14-AC14<=월액최고),ROUNDDOWN((P14-AC14)*국민연금,-1),IF(P14-AC14>=월액최고,최고연금,IF(AND(P14-AC14<=월액최저,P14-AC14>=1),최저연금,))),) -> 99000 | T14: =IFERROR(ROUNDDOWN((P14-AC14)*3.43%,-1),) -> 75460 | U14: =ROUNDDOWN(T14*11.52%,-1) -> 8690 | V14: =IFERROR(IF(D15<>"대표이사",ROUNDDOWN((P14-AC14)*고용보험율,-1),0),) -> 17600 | W14: =SUM(Q14:V14) -> 229290 | X14: =P14-W14 -> 2270710 | Z14: 1 | AC14: =IF(N15>=100000,100000,N15)+IF(O14>=200000,200000,O14) -> 300000
B15: 7 | C15: =[1]직원인적급여카드!B8 -> 이일복 | D15: 과장 | E15: =[1]직원인적급여카드!M8 -> 2100000 | N15: 200000 | O15: 200000 | P15: =SUM(E15:O15) -> 2500000 | Q15: =IFERROR(IF(P15-AC15<=10000000,VLOOKUP((P15-AC15)/1000,간이세액표,IF(11<Z15+AA15,13,2+Z15+AA15),TRUE),IF(P15-AC15>14000000,VLOOKUP((P15-AC15)/1000,간이세액표,IF(11<Z15+AA15,13,2+Z15+AA15),TRUE)+1372000+ROUNDDOWN(((P15-AC15-14000000)*98%)*38%,-1),VLOOKUP((P15-AC15)/1000,간이세액표,IF(11<Z15+AA15,13,2+Z15+AA15),TRUE)+ROUNDDOWN(((P15-AC15-10000000)*98%)*35%,-1))),) -> 25950 | R15: =ROUNDDOWN(Q15*10%,-1) -> 2590 | T15: =IFERROR(ROUNDDOWN((P15-AC15)*3.43%,-1),) -> 75460 | U15: =ROUNDDOWN(T15*11.52%,-1) -> 8690 | V15: =IFERROR(IF(D15<>"대표이사",ROUNDDOWN((P15-AC15)*고용보험율,-1),0),) -> 17600 | W15: =SUM(Q15:V15) -> 130290 | X15: =P15-W15 -> 2369710 | Z15: 1 | AC15: =IF(N15>=100000,100000,N15)+IF(O15>=200000,200000,O15) -> 300000
C16: 유지안 | D16: 부장 | Q16: =IFERROR(IF(P16-AC16<=10000000,VLOOKUP((P16-AC16)/1000,간이세액표,IF(11<Z16+AA16,13,2+Z16+AA16),TRUE),IF(P16-AC16>14000000,VLOOKUP((P16-AC16)/1000,간이세액표,IF(11<Z16+AA16,13,2+Z16+AA16),TRUE)+1372000+ROUNDDOWN(((P16-AC16-14000000)*98%)*38%,-1),VLOOKUP((P16-AC16)/1000,간이세액표,IF(11<Z16+AA16,13,2+Z16+AA16),TRUE)+ROUNDDOWN(((P16-AC16-10000000)*98%)*35%,-1))),) -> 0 | R16: =ROUNDDOWN(Q16*10%,-1) -> 0 | S16: =IFERROR(IF(AND(P16-AC16>=월액최저,P16-AC16<=월액최고),ROUNDDOWN((P16-AC16)*국민연금,-1),IF(P16-AC16>=월액최고,최고연금,IF(AND(P16-AC16<=월액최저,P16-AC16>=1),최저연금,))),) -> 0 | T16: =IFERROR(ROUNDDOWN((P16-AC16)*건강보험율,-1),) -> 0 | U16: =ROUNDDOWN(T16*요양보험율,-1) -> 0 | V16: =IFERROR(IF(D16<>"대표이사",ROUNDDOWN((P16-AC16)*고용보험율,-1),0),) -> 0 | W16: =SUM(Q16:V16) -> 0 | X16: =P16-W16 -> 0 | AC16: =IF(N16>=100000,100000,N16)+IF(O16>=200000,200000,O16) -> 0
B17: 8 | C17: 조태현 | D17: 과장 | E17: 1050000 | N17: 100000 | O17: 100000 | P17: =SUM(E17:O17) -> 1250000 | Q17: =IFERROR(IF(P17-AC17<=10000000,VLOOKUP((P17-AC17)/1000,간이세액표,IF(11<Z17+AA17,13,2+Z17+AA17),TRUE),IF(P17-AC17>14000000,VLOOKUP((P17-AC17)/1000,간이세액표,IF(11<Z17+AA17,13,2+Z17+AA17),TRUE)+1372000+ROUNDDOWN(((P17-AC17-14000000)*98%)*38%,-1),VLOOKUP((P17-AC17)/1000,간이세액표,IF(11<Z17+AA17,13,2+Z17+AA17),TRUE)+ROUNDDOWN(((P17-AC17-10000000)*98%)*35%,-1))),) -> 0 | R17: =ROUNDDOWN(Q17*10%,-1) -> 0 | S17: =IFERROR(IF(AND(P17-AC17>=월액최저,P17-AC17<=월액최고),ROUNDDOWN((P17-AC17)*국민연금,-1),IF(P17-AC17>=월액최고,최고연금,IF(AND(P17-AC17<=월액최저,P17-AC17>=1),최저연금,))),) -> 47250 | T17: =IFERROR(ROUNDDOWN((P17-AC17)*건강보험율,-1),) -> 36010 | U17: =ROUNDDOWN(T17*11.52%,-1) -> 4140 | V17: =IFERROR(IF(D17<>"대표이사",ROUNDDOWN((P17-AC17)*고용보험율,-1),0),) -> 8400 | W17: =SUM(Q17:V17) -> 95800 | X17: =P17-W17 -> 1154200 | Z17: 1 | AC17: =IF(N17>=100000,100000,N17)+IF(O17>=200000,200000,O17) -> 200000
B18: 9 | C18: 홍혜경 | D18: 대리 | E18: 2100000 | N18: 200000 | O18: 200000 | P18: =SUM(E18:O18) -> 2500000 | Q18: =IFERROR(IF(P18-AC18<=10000000,VLOOKUP((P18-AC18)/1000,간이세액표,IF(11<Z18+AA18,13,2+Z18+AA18),TRUE),IF(P18-AC18>14000000,VLOOKUP((P18-AC18)/1000,간이세액표,IF(11<Z18+AA18,13,2+Z18+AA18),TRUE)+1372000+ROUNDDOWN(((P18-AC18-14000000)*98%)*38%,-1),VLOOKUP((P18-AC18)/1000,간이세액표,IF(11<Z18+AA18,13,2+Z18+AA18),TRUE)+ROUNDDOWN(((P18-AC18-10000000)*98%)*35%,-1))),) -> 25950 | R18: =ROUNDDOWN(Q18*10%,-1) -> 2590 | S18: =IFERROR(IF(AND(P18-AC18>=월액최저,P18-AC18<=월액최고),ROUNDDOWN((P18-AC18)*국민연금,-1),IF(P18-AC18>=월액최고,최고연금,IF(AND(P18-AC18<=월액최저,P18-AC18>=1),최저연금,))),) -> 99000 | T18: =IFERROR(ROUNDDOWN((P18-AC18)*3.43%,-1),) -> 75460 | U18: =ROUNDDOWN(T18*11.52%,-1) -> 8690 | V18: =IFERROR(IF(D18<>"대표이사",ROUNDDOWN((P18-AC18)*고용보험율,-1),0),) -> 17600 | W18: =SUM(Q18:V18) -> 229290 | X18: =P18-W18 -> 2270710 | Z18: 1 | AC18: =IF(N18>=100000,100000,N18)+IF(O18>=200000,200000,O18) -> 300000
